Workbook

Sheet 绩效整理表
A1: 2026-05 销售绩效溯源工作簿（精简整理表 + Hub输入）
A2: 第3行=整理表字段（合并）；第4行=源表叶子字段/匹配方式/公式；第5行起填数据。 同工作簿另含 18 张源表（Hub/岗位 + 发薪边表；版式来自 uploads/主账套，公式保留、数值留空）。
A3: 指标汇总部门 | D3: 渠道 | E3: 库存天数 | I3: 订单号 | K3: 车种 | M3: 销售渠道 | O3: 台数 | P3: 订单合计(含税) | R3: VIN码 | T3: 销售顾问 | V3: 部门 | X3: 精品最低价金额 | Z3: 不提成精品 | AB3: 整车节约 | AD3: 经理权限 | AE3: 整车实际节约 | AH3: 盈利性产品按揭权限扣除 | AJ3: 实际整车节约权限 | AK3: 保险返利收入 | AO3: 按揭收入 | AQ3: 爱车宝收入 | AS3: 上户收入 | AU3: 延保收入 | AW3: 单台绩效 | AZ3: 整车超额 | BA3: 加装绩效 | BC3: 保险提成 | BG3: 按揭提成 | BI3: 盈利产品 | BM3: 爱车宝 | BR3: 上户绩效 | BX3: 座位险绩效 | CA3: 玻璃险绩效 | CD3: 特殊车型追加绩效（追加+质损车） | CH3: 二手车置换 | CQ3: 置换服务 | CT3: 延保提成 | CU3: 超期追加 | CV3: 出厂指导价/扣除降价补差 | CX3: 提车现返 | CZ3: 合同履约 | DB3: 项目金额附加费 | DD3: 广告返利 | DF3: 提车奖励当月返 | DH3: 当月返利 | DK3: 促销奖 | DL3: 代交车佣金 | DN3: 裸车毛利 | DO3: 装饰成本 | DQ3: 装饰毛利 | DT3: 主营业务毛利 | DW3: 上户代收代付部分 | DX3: 安心保 | DY3: 爱车保 | DZ3: 上户量
A4: 系统销售毛利-部门（BL列） | B4: 比对表-系统部门（A列）→指标汇总部门（B列） | C4: 通过Vin码匹配 | D4: 表内派生：指标汇总部门+销售渠道→渠道规则 | E4: 系统销售毛利-结算日期（BA列） | F4: 整车成本-结算日期（B列） | G4: 通过Vin码匹配 | H4: 表内派生：INT(订单结算日−成本结算日) | I4: 系统销售毛利-订单号（B列） | J4: 通过Vin码匹配 | K4: 系统销售毛利-车种（D列） | L4: 通过Vin码匹配 | M4: 系统销售毛利-销售渠道（E列） | N4: 通过Vin码匹配 | O4: 表内派生：默认1; supplement_rows可空 | P4: 系统销售毛利-订单合计(含税)（AO列） | Q4: 通过Vin码匹配 | R4: 系统销售毛利-VIN码（BD列） | S4: 通过Vin码匹配 | T4: 系统销售毛利-销售顾问（BJ列） | U4: 通过Vin码匹配 | V4: 系统销售毛利-部门（BL列） | W4: 通过Vin码匹配 | X4: 系统销售毛利-精品最低价金额（BQ列） | Y4: 通过Vin码匹配 | Z4: 装饰台账-最低价含税金额（AR列） | AA4: 按订单号汇总 | AB4: 系统超额-合计超卖金额（P列） | AC4: 通过Vin码匹配 | AD4: 配置：manager_permission_by_vin | AE4: 整车节约 | AF4: 经理权限 | AG4: 整车节约+经理权限 | AH4: 按揭原表-整车超权限（AN列） | AI4: 通过Vin码匹配 | AJ4: 表内派生：盈利性产品按揭权限扣除≠0→0 else 整车实际节约−盈利性产品按揭权限扣除 | AK4: 保险明细-应结算服务费-合计（AN列） | AL4: 保险明细-返利金额（BP列） | AM4: 通过Vin码匹配 | AN4: BP=SUMIF(VIN,AN) | AO4: 按揭明细-服务费合计（Z列） | AP4: 通过Vin码匹配 | AQ4: 爱车保-产品名称（K列） | AR4: 通过Vin码匹配 | AS4: 上户提成-手续费（C列） | AT4: 通过Vin码匹配 | AU4: 延保提成-延保收入（BE列） | AV4: 通过Vin码匹配 | AW4: 提成标准-单台绩效（F列） | AX4: 台数 | AY4: 提成标准F×台数 | AZ4: 表内派生：实际整车节约权限×比例分支 | BA4: 表内派生：台数=0→订单合计×12% | BB4: 表内派生：else (精品最低价金额−不提成精品)×12% | BC4: 保险明细-购买险种-商业险保费（AE列） | BD4: 保险明细-直营店保险额外提成-保险额外提成（BT列） | BE4: 通过Vin码匹配 | BF4: AE*0.03+BT | BG4: 按揭明细-基础绩效（BO列） | BH4: 通过Vin码匹配 | BI4: 按揭原表-盈利性奖励（AF列） | BJ4: 按揭明细-吉致额外追加奖励（BR列） | BK4: 通过Vin码匹配 | BL4: AF+BR | BM4: 爱车保-VIN（F列） | BN4: 爱车保-产品名称（K列） | BO4: 爱车保-实际金额（Z列） | BP4: 通过Vin码匹配 | BQ4: 分段规则(熊猫/畅行保C/置换无忧/悦行保A/金额档) | BR4: 上户提成-手续费（C列） | BS4: 上户提成-福袋（D列） | BT4: 上户提成-VIN码（B列） | BU4: 上户提成-车型（M列） | BV4: 通过Vin码匹配 | BW4: IF(G=0,0,IF(G>=330,G*0.14+53.8,(G-330)*0.14)) | BX4: 保险明细-15/单-座位险提成（BU列） | BY4: 通过Vin码匹配 | BZ4: IF(BF>0,15,0) | CA4: 保险明细-玻璃险-BG（BG列） | CB4: 通过Vin码匹配 | CC4: BG*0.08 | CD4: 重功超期+活动-奖励明细（N列） | CE4: 提成标准-政策追加2月（H列） | CF4: 通过Vin码匹配 | CG4: N+提成标准H×台数 | CH4: 二手置换-公司留存补贴（Y列） | CI4: 二手置换-结余提成（AC列） | CJ4: Y*0.14 | CK4: 二手置换-毛利（O列） | CL4: 二手置换-置换提成（AD列） | CM4: IF(O>=1000,O*0.14,IF(O>=500,100,0)) | CN4: 大客户-销售提成（R列） | CO4: 通过Vin码匹配 | CP4: AC+AD+大客户R | CQ4: 置换服务-服务费金额（AH列） | CR4: 通过Vin码匹配 | CS4: AH*0.14 | CT4: 表内派生：延保收入分段(-200/0/200) | CU4: 表内派生：超期政策×库存天数 | CV4: 整车成本-出厂指导价（R列） | CW4: 通过Vin码匹配 | CX4: 整车成本-提车现返（S列） | CY4: 通过Vin码匹配 | CZ4: 整车成本-合同履约奖（T列） | DA4: 通过Vin码匹配 | DB4: 整车成本-项目金额附加费（U列） | DC4: 通过Vin码匹配 | DD4: 整车成本-广告返利（V列） | DE4: 通过Vin码匹配 | DF4: 整车成本-提车奖励当月返（W列） | DG4: 通过Vin码匹配 | DH4: 终端明细表-金额（P列） | DI4: 通过Vin码匹配 | DJ4: 表内派生：台数≠0时取负SUMIFS | DK4: 需手工填入 | DL4: 系统二手车降价-佣金（去税）（BE列） | DM4: 通过Vin码匹配 | DN4: 表内派生：订单合计(含税)−SUM(出厂指导价:代交车佣金) | DO4: 装饰台账-含税成本价（AK列） | DP4: 按订单号汇总 | DQ4: 精品最低价金额 | DR4: 装饰成本 | DS4: 精品最低价金额−装饰成本 | DT4: 裸车毛利 | DU4: 装饰毛利 | DV4: 裸车毛利+装饰毛利 | DW4: 需手工填入 | DX4: 需手工填入 | DY4: 需手工填入 | DZ4: 需手工填入

Sheet 销售任务及完成率
A1: 西物汽车2016年8月销售任务计划执行计划统计表
A2: 编制部门：2026年05月整理数据 | M2: 拟定时间：
A3: 店名 | B3: 小组 | C3: 姓名 | D3: 西物、超市（合） | G3: 西物、超市（新品）（L网） | J3: 西物、超市（老品）（G网） | M3: 熊猫 | P3: 西物、超市（合） | S3: 西物、超市（合） | V3: 西物、超市（合） | Y3: 西物、超市（总完成率）
D4: 集客(台） | G4: 销量（台） | J4: 销量（台） | P4: *月博越L\博越cool考核 | S4: 武侯店-ICON | V4: 超期/重攻质损 | Y4: 总考核（台）
D5: 考核 | E5: 实际 | F5: 完成率 | G5: 考核 | H5: 实际 | I5: 完成率 | J5: 考核 | K5: 实际 | L5: 完成率 | M5: 考核 | N5: 实际 | O5: 完成率 | P5: 考核 | Q5: 实际 | R5: 完成率 | S5: 考核 | T5: 实际 | U5: 完成率 | V5: 考核 | W5: 实际 | X5: 提成金额 | Y5: 考核 | Z5: 实际 | AA5: 完成率
A6: 总计 | D6: =D7+D40+D55+D78 -> 0 | E6: =E7+E40+E55+E78 -> 0 | F6: =F7+F40+F55+F78 -> 5 | G6: =G7+G40+G55+G78 -> 0 | H6: =H7+H40+H55+H78 -> 0 | I6: =I7+I40+I55+I78 -> 15 | J6: =J7+J40+J55+J78 -> 0 | K6: =K7+K40+K55+K78 -> 0 | ... AA6: =AA7+AA40+AA55+AA78 -> 5 | AB6: 公告车销售量
A7: 武侯店 | B7: 合计 | D7: =D8+D27 -> 0 | E7: =E8+E27 -> 0 | F7: =IF(D7=0,1,E7/D7) -> 1 | G7: =G8+G16+G28 -> 0 | H7: =H8+H16+H28 -> 0 | I7: =I8+I16+I28 -> 12 | J7: =J8+J16+J28 -> 0 | K7: =K8+K16+K28 -> 0 | L7: =L8+L16+L28 -> 13 | M7: =M8+M16+M28 -> 0 | N7: =N8+N16+N28 -> 0 | ... AA7: =AA8+AA16+AA28 -> 2
C8: A组 | D8: =SUM(D9:D15) -> 0 | E8: =SUM(E9:E15) -> 0 | F8: =IF(D8=0,1,E8/D8) -> 1 | G8: =SUM(G9:G15) -> 0 | H8: =SUM(H9:H15) -> 0 | I8: =IF(G8=0,1,H8/G8) -> 1 | J8: =SUM(J9:J15) -> 0 | K8: =SUM(K9:K15) -> 0 | L8: =IF(J8=0,1,K8/J8) -> 1 | M8: =SUM(M9:M15) -> 0 | N8: =SUM(N9:N15) -> 0 | O8: =IF(M8=0,1,N8/M8) -> 1 | P8: =SUM(P9:P15) -> 0 | Q8: =SUM(Q9:Q15) -> 0 | R8: =IF(P8=0,1,Q8/P8) -> 1 | S8: =SUM(S9:S15) -> 0 | T8: =SUM(T9:T15) -> 0 | U8: =IF(S8=0,1,T8/S8) -> 1 | V8: =SUM(V9:V15) -> 0 | W8: =SUM(W9:W15) -> 0 | X8: =IF(V8=0,1,W8/V8) -> 1 | Y8: =SUM(Y9:Y15) -> 0 | Z8: =SUM(Z9:Z15) -> 0 | AA8: =IF(Y8=0,1,Z8/Y8) -> 1
F9: =IF(D9=0,1,E9/D9) -> 1 | I9: =IF(J9=0,1,H9/J9) -> 1 | L9: =IF(J9=0,1,K9/J9) -> 1 | O9: =IF(M9=0,1,N9/M9) -> 1 | R9: =IF(P9=0,1,Q9/P9) -> 1 | Y9: =J9+G9+M9 -> 0 | AA9: =IF(IF(Y9=0,1,Z9/Y9)>1,1,IF(Y9=0,1,Z9/Y9)) -> 1
F10: =IF(D10=0,1,E10/D10) -> 1 | I10: =IF(J10=0,1,H10/J10) -> 1 | L10: =IF(J10=0,1,K10/J10) -> 1 | O10: =IF(M10=0,1,N10/M10) -> 1 | R10: =IF(P10=0,1,Q10/P10) -> 1 | Y10: =J10+G10+M10 -> 0 | AA10: =IF(IF(Y10=0,1,Z10/Y10)>1,1,IF(Y10=0,1,Z10/Y10)) -> 1
F11: =IF(D11=0,1,E11/D11) -> 1 | I11: =IF(J11=0,1,H11/J11) -> 1 | L11: =IF(J11=0,1,K11/J11) -> 1 | O11: =IF(M11=0,1,N11/M11) -> 1 | R11: =IF(P11=0,1,Q11/P11) -> 1 | Y11: =J11+G11+M11 -> 0 | AA11: =IF(IF(Y11=0,1,Z11/Y11)>1,1,IF(Y11=0,1,Z11/Y11)) -> 1
F12: =IF(D12=0,1,E12/D12) -> 1 | I12: =IF(J12=0,1,H12/J12) -> 1 | L12: =IF(J12=0,1,K12/J12) -> 1 | O12: =IF(M12=0,1,N12/M12) -> 1 | R12: =IF(P12=0,1,Q12/P12) -> 1 | Y12: =J12+G12+M12 -> 0 | AA12: =IF(IF(Y12=0,1,Z12/Y12)>1,1,IF(Y12=0,1,Z12/Y12)) -> 1
F13: =IF(D13=0,1,E13/D13) -> 1 | I13: =IF(J13=0,1,H13/J13) -> 1 | L13: =IF(J13=0,1,K13/J13) -> 1 | O13: =IF(M13=0,1,N13/M13) -> 1 | R13: =IF(P13=0,1,Q13/P13) -> 1 | Y13: =J13+G13+M13 -> 0 | AA13: =IF(IF(Y13=0,1,Z13/Y13)>1,1,IF(Y13=0,1,Z13/Y13)) -> 1
F14: =IF(D14=0,1,E14/D14) -> 1 | I14: =IF(J14=0,1,H14/J14) -> 1 | L14: =IF(J14=0,1,K14/J14) -> 1 | O14: =IF(M14=0,1,N14/M14) -> 1 | R14: =IF(P14=0,1,Q14/P14) -> 1 | Y14: =J14+G14+M14 -> 0 | AA14: =IF(IF(Y14=0,1,Z14/Y14)>1,1,IF(Y14=0,1,Z14/Y14)) -> 1
F15: =IF(D15=0,1,E15/D15) -> 1 | I15: =IF(G15=0,1,H15/G15) -> 1 | L15: =IF(J15=0,1,K15/J15) -> 1 | O15: =IF(M15=0,1,N15/M15) -> 1 | R15: =IF(P15=0,1,Q15/P15) -> 1 | Y15: =J15+G15+M15 -> 0 | AA15: =IF(Y15=0,1,Z15/Y15) -> 1
C16: B组 | D16: =SUM(D17:D26) -> 0 | E16: =SUM(E17:E26) -> 0 | F16: =IF(D16=0,1,E16/D16) -> 1 | G16: =SUM(G17:G26) -> 0 | H16: =SUM(H17:H26) -> 0 | J16: =SUM(J17:J26) -> 0 | K16: =SUM(K17:K26) -> 0 | L16: =IF(J16=0,1,K16/J16) -> 1 | M16: =J16*1500 -> 0 | N16: =SUM(N17:N26) -> 0 | O16: =IF(M16=0,1,N16/M16) -> 1 | P16: =SUM(P17:P26) -> 0 | Q16: =SUM(Q17:Q26) -> 0 | R16: =IF(P16=0,1,Q16/P16) -> 1 | S16: =SUM(S17:S26) -> 0 | T16: =SUM(T17:T26) -> 0 | U16: =IF(S16=0,1,T16/S16) -> 1 | V16: =SUM(V17:V26) -> 0 | W16: =SUM(W17:W26) -> 0 | X16: =IF(V16=0,1,W16/V16) -> 1 | Y16: =SUM(Y17:Y26) -> 0 | Z16: =SUM(Z17:Z26) -> 0 | AA16: =IF(Y16=0,1,Z16/Y16) -> 1
B17: 武侯展厅 | C17: 熊杰文 | F17: =IF(D17=0,1,E17/D17) -> 1 | I17: =IF(G17=0,1,H17/G17) -> 1 | L17: =IF(J17=0,1,K17/J17) -> 1 | O17: =IF(M17=0,1,N17/M17) -> 1 | R17: =IF(Q17<P17,-(P17-Q17)*200,0) -> 0 | U17: =IF(T17<S17,-(S17-T17)*200,0) -> 0 | X17: =IF(W17<V17,-(V17-W17)*300,0) -> 0 | Y17: =J17+G17+M17 -> 0 | AA17: =IF(IF(Y17=0,1,Z17/Y17)>1,1,IF(Y17=0,1,Z17/Y17)) -> 1
C18: 易花贞子 | F18: =IF(D18=0,1,E18/D18) -> 1 | I18: =IF(G18=0,1,H18/G18) -> 1 | L18: =IF(J18=0,1,K18/J18) -> 1 | O18: =IF(M18=0,1,N18/M18) -> 1 | R18: =IF(Q18<P18,-(P18-Q18)*200,0) -> 0 | U18: =IF(T18<S18,-(S18-T18)*200,0) -> 0 | X18: =IF(W18<V18,-(V18-W18)*300,0) -> 0 | Y18: =J18+G18+M18 -> 0 | AA18: =IF(IF(Y18=0,1,Z18/Y18)>1,1,IF(Y18=0,1,Z18/Y18)) -> 1
C19: 马攀 | F19: =IF(D19=0,1,E19/D19) -> 1 | I19: =IF(G19=0,1,H19/G19) -> 1 | L19: =IF(J19=0,1,K19/J19) -> 1 | O19: =IF(M19=0,1,N19/M19) -> 1 | R19: =IF(Q19<P19,-(P19-Q19)*200,0) -> 0 | U19: =IF(T19<S19,-(S19-T19)*200,0) -> 0 | X19: =IF(W19<V19,-(V19-W19)*300,0) -> 0 | Y19: =J19+G19+M19 -> 0 | AA19: =IF(IF(Y19=0,1,Z19/Y19)>1,1,IF(Y19=0,1,Z19/Y19)) -> 1
C20: 毛春秀 | F20: =IF(D20=0,1,E20/D20) -> 1 | I20: =IF(G20=0,1,H20/G20) -> 1 | L20: =IF(J20=0,1,K20/J20) -> 1 | O20: =IF(M20=0,1,N20/M20) -> 1 | R20: =IF(Q20<P20,-(P20-Q20)*200,0) -> 0 | U20: =IF(T20<S20,-(S20-T20)*200,0) -> 0 | X20: =IF(W20<V20,-(V20-W20)*300,0) -> 0 | Y20: =J20+G20+M20 -> 0 | AA20: =IF(IF(Y20=0,1,Z20/Y20)>1,1,IF(Y20=0,1,Z20/Y20)) -> 1
C21: 廖晓军 | F21: =IF(D21=0,1,E21/D21) -> 1 | I21: =IF(G21=0,1,H21/G21) -> 1 | L21: =IF(J21=0,1,K21/J21) -> 1 | O21: =IF(M21=0,1,N21/M21) -> 1 | R21: =IF(Q21<P21,-(P21-Q21)*200,0) -> 0 | U21: =IF(T21<S21,-(S21-T21)*200,0) -> 0 | X21: =IF(W21<V21,-(V21-W21)*300,0) -> 0 | Y21: =J21+G21+M21 -> 0 | AA21: =IF(IF(Y21=0,1,Z21/Y21)>1,1,IF(Y21=0,1,Z21/Y21)) -> 1
C22: 康鳞波 | F22: =IF(D22=0,1,E22/D22) -> 1 | O22: =IF(M22=0,1,N22/M22) -> 1 | R22: =IF(Q22<P22,-(P22-Q22)*200,0) -> 0 | U22: =IF(T22<S22,-(S22-T22)*200,0) -> 0 | X22: =IF(W22<V22,-(V22-W22)*300,0) -> 0 | Y22: =J22+G22+M22 -> 0 | AA22: =IF(IF(Y22=0,1,Z22/Y22)>1,1,IF(Y22=0,1,Z22/Y22)) -> 1
C23: 黄利君 | F23: =IF(D23=0,1,E23/D23) -> 1 | I23: =IF(G23=0,1,H23/G23) -> 1 | L23: =IF(J23=0,1,K23/J23) -> 1 | O23: =IF(M23=0,1,N23/M23) -> 1 | R23: =IF(Q23<P23,-(P23-Q23)*200,0) -> 0 | U23: =IF(T23<S23,-(S23-T23)*200,0) -> 0 | X23: =IF(W23<V23,-(V23-W23)*300,0) -> 0 | Y23: =J23+G23+M23 -> 0 | AA23: =IF(IF(Y23=0,1,Z23/Y23)>1,1,IF(Y23=0,1,Z23/Y23)) -> 1
C24: 代力 | F24: =IF(D24=0,1,E24/D24) -> 1 | R24: =IF(Q24<P24,-(P24-Q24)*200,0) -> 0 | U24: =IF(T24<S24,-(S24-T24)*200,0) -> 0 | X24: =IF(W24<V24,-(V24-W24)*300,0) -> 0 | Y24: =J24+G24+M24 -> 0 | AA24: =IF(IF(Y24=0,1,Z24/Y24)>1,1,IF(Y24=0,1,Z24/Y24)) -> 1
R25: =IF(Q25<P25,-(P25-Q25)*200,0) -> 0 | X25: =IF(W25<V25,-(V25-W25)*500,0) -> 0 | Y25: =J25+G25+M25 -> 0 | AA25: =IF(IF(Y25=0,1,Z25/Y25)>1,1,IF(Y25=0,1,Z25/Y25)) -> 1
R26: =IF(Q26<P26,-(P26-Q26)*200,0) -> 0 | X26: =IF(W26<V26,-(V26-W26)*500,0) -> 0 | Y26: =J26+G26+M26 -> 0 | AA26: =IF(IF(Y26=0,1,Z26/Y26)>1,1,IF(Y26=0,1,Z26/Y26)) -> 1
B27: 武侯DCC | D27: =SUM(D29:D39) -> 0 | E27: =SUM(E29:E39) -> 0 | F27: =IF(D27=0,1,E27/D27) -> 1 | G27: =G28 -> 0 | H27: =H28 -> 0 | I27: =I28 -> 11 | J27: =J28 -> 0 | K27: =K28 -> 0 | L27: =L28 -> 11 | Y27: =Y28 -> 0 | Z27: =SUM(Z29:Z39) -> 0 | AA27: =IF(Y27=0,1,Z27/Y27) -> 1
C28: DCCA组 | G28: =SUM(G29:G39) -> 0 | H28: =SUM(H29:H39) -> 0 | I28: =SUM(I29:I39) -> 11 | J28: =SUM(J29:J39) -> 0 | K28: =SUM(K29:K39) -> 0 | L28: =SUM(L29:L39) -> 11 | M28: =SUM(M29:M39) -> 0 | N28: =SUM(N29:N39) -> 0 | ... W28: =SUM(W29:W39) -> 0 | Y28: =SUM(Y29:Y39) -> 0 | Z28: =SUM(Z29:Z39) -> 0
C29: 蒲喜 | F29: =IF(D29=0,1,E29/D29) -> 1 | I29: =IF(G29=0,1,H29/G29) -> 1 | L29: =IF(J29=0,1,K29/J29) -> 1 | O29: =IF(M29=0,1,N29/M29) -> 1 | R29: =IF(Q29<P29,-(P29-Q29)*200,0) -> 0 | U29: =IF(T29<S29,-(S29-T29)*200,0) -> 0 | X29: =IF(W29<V29,-(V29-W29)*300,0) -> 0 | Y29: =J29+G29+M29 -> 0 | AA29: =IF(IF(Y29=0,1,Z29/Y29)>1,1,IF(Y29=0,1,Z29/Y29)) -> 1
C30: 何宇 | F30: =IF(D30=0,1,E30/D30) -> 1 | I30: =IF(G30=0,1,H30/G30) -> 1 | L30: =IF(J30=0,1,K30/J30) -> 1 | O30: =IF(M30=0,1,N30/M30) -> 1 | R30: =IF(Q30<P30,-(P30-Q30)*200,0) -> 0 | U30: =IF(T30<S30,-(S30-T30)*200,0) -> 0 | X30: =IF(W30<V30,-(V30-W30)*300,0) -> 0 | Y30: =J30+G30+M30 -> 0 | AA30: =IF(IF(Y30=0,1,Z30/Y30)>1,1,IF(Y30=0,1,Z30/Y30)) -> 1
C31: 何伟 | F31: =IF(D31=0,1,E31/D31) -> 1 | I31: =IF(G31=0,1,H31/G31) -> 1 | L31: =IF(J31=0,1,K31/J31) -> 1 | O31: =IF(M31=0,1,N31/M31) -> 1 | R31: =IF(Q31<P31,-(P31-Q31)*200,0) -> 0 | U31: =IF(T31<S31,-(S31-T31)*200,0) -> 0 | X31: =IF(W31<V31,-(V31-W31)*300,0) -> 0 | Y31: =J31+G31+M31 -> 0 | AA31: =IF(IF(Y31=0,1,Z31/Y31)>1,1,IF(Y31=0,1,Z31/Y31)) -> 1
C32: 唐操 | F32: =IF(D32=0,1,E32/D32) -> 1 | I32: =IF(G32=0,1,H32/G32) -> 1 | L32: =IF(J32=0,1,K32/J32) -> 1 | O32: =IF(M32=0,1,N32/M32) -> 1 | R32: =IF(Q32<P32,-(P32-Q32)*200,0) -> 0 | U32: =IF(T32<S32,-(S32-T32)*200,0) -> 0 | X32: =IF(W32<V32,-(V32-W32)*300,0) -> 0 | Y32: =J32+G32+M32 -> 0 | AA32: =IF(IF(Y32=0,1,Z32/Y32)>1,1,IF(Y32=0,1,Z32/Y32)) -> 1
C33: 母勇 | F33: =IF(D33=0,1,E33/D33) -> 1 | I33: =IF(G33=0,1,H33/G33) -> 1 | L33: =IF(J33=0,1,K33/J33) -> 1 | O33: =IF(M33=0,1,N33/M33) -> 1 | R33: =IF(Q33<P33,-(P33-Q33)*200,0) -> 0 | U33: =IF(T33<S33,-(S33-T33)*200,0) -> 0 | X33: =IF(W33<V33,-(V33-W33)*300,0) -> 0 | Y33: =J33+G33+M33 -> 0 | AA33: =IF(IF(Y33=0,1,Z33/Y33)>1,1,IF(Y33=0,1,Z33/Y33)) -> 1
C34: 刘飞 | F34: =IF(D34=0,1,E34/D34) -> 1 | I34: =IF(G34=0,1,H34/G34) -> 1 | L34: =IF(J34=0,1,K34/J34) -> 1 | O34: =IF(M34=0,1,N34/M34) -> 1 | R34: =IF(Q34<P34,-(P34-Q34)*200,0) -> 0 | U34: =IF(T34<S34,-(S34-T34)*200,0) -> 0 | X34: =IF(W34<V34,-(V34-W34)*300,0) -> 0 | Y34: =J34+G34+M34 -> 0 | AA34: =IF(IF(Y34=0,1,Z34/Y34)>1,1,IF(Y34=0,1,Z34/Y34)) -> 1
C35: 何剑 | F35: =IF(D35=0,1,E35/D35) -> 1 | I35: =IF(G35=0,1,H35/G35) -> 1 | L35: =IF(J35=0,1,K35/J35) -> 1 | O35: =IF(M35=0,1,N35/M35) -> 1 | R35: =IF(Q35<P35,-(P35-Q35)*200,0) -> 0 | U35: =IF(T35<S35,-(S35-T35)*200,0) -> 0 | X35: =IF(W35<V35,-(V35-W35)*300,0) -> 0 | Y35: =J35+G35+M35 -> 0 | AA35: =IF(IF(Y35=0,1,Z35/Y35)>1,1,IF(Y35=0,1,Z35/Y35)) -> 1
C36: 雷卓远 | F36: =IF(D36=0,1,E36/D36) -> 1 | I36: =IF(G36=0,1,H36/G36) -> 1 | L36: =IF(J36=0,1,K36/J36) -> 1 | O36: =IF(M36=0,1,N36/M36) -> 1 | R36: =IF(Q36<P36,-(P36-Q36)*200,0) -> 0 | X36: =IF(W36<V36,-(V36-W36)*300,0) -> 0 | Y36: =J36+G36+M36 -> 0 | AA36: =IF(IF(Y36=0,1,Z36/Y36)>1,1,IF(Y36=0,1,Z36/Y36)) -> 1
C37: 王泳文 | F37: =IF(D37=0,1,E37/D37) -> 1 | I37: =IF(G37=0,1,H37/G37) -> 1 | L37: =IF(J37=0,1,K37/J37) -> 1 | O37: =IF(M37=0,1,N37/M37) -> 1 | R37: =IF(Q37<P37,-(P37-Q37)*200,0) -> 0 | U37: =IF(T37<S37,-(S37-T37)*200,0) -> 0 | X37: =IF(W37<V37,-(V37-W37)*300,0) -> 0 | Y37: =J37+G37+M37 -> 0 | AA37: =IF(IF(Y37=0,1,Z37/Y37)>1,1,IF(Y37=0,1,Z37/Y37)) -> 1
F38: =IF(D38=0,1,E38/D38) -> 1 | I38: =IF(G38=0,1,H38/G38) -> 1 | L38: =IF(J38=0,1,K38/J38) -> 1 | O38: =IF(M38=0,1,N38/M38) -> 1 | R38: =IF(Q38<P38,-(P38-Q38)*200,0) -> 0 | U38: =IF(T38<S38,-(S38-T38)*200,0) -> 0 | X38: =IF(W38<V38,-(V38-W38)*300,0) -> 0 | Y38: =J38+G38+M38 -> 0 | AA38: =IF(IF(Y38=0,1,Z38/Y38)>1,1,IF(Y38=0,1,Z38/Y38)) -> 1
F39: =IF(D39=0,1,E39/D39) -> 1 | I39: =IF(G39=0,1,H39/G39) -> 1 | L39: =IF(J39=0,1,K39/J39) -> 1 | O39: =IF(M39=0,1,N39/M39) -> 1 | R39: =IF(Q39<P39,-(P39-Q39)*200,0) -> 0 | U39: =IF(T39<S39,-(S39-T39)*200,0) -> 0 | X39: =IF(W39<V39,-(V39-W39)*300,0) -> 0 | Y39: =J39+G39+M39 -> 0 | AA39: =IF(IF(Y39=0,1,Z39/Y39)>1,1,IF(Y39=0,1,Z39/Y39)) -> 1
A40: 机场店 | B40: 展厅 | C40: 合计 | D40: =SUM(D41:D54) -> 0 | E40: =SUM(E41:E54) -> 0 | F40: =IF(D40=0,1,E40/D40) -> 1 | H40: =H54 -> 0 | I40: =I54 -> 0 | K40: =K54 -> 0 | L40: =L54 -> 0 | M40: =SUM(M29:M39) -> 0 | N40: =N54 -> 0 | O40: =O54 -> 1 | P40: =SUM(P41:P53) -> 0 | Q40: =SUM(Q41:Q53) -> 0 | R40: =R54 -> 0 | S40: =S54 -> 0 | T40: =T54 -> 0 | U40: =U54 -> 0 | V40: =V54 -> 0 | W40: =W54 -> 0 | X40: =SUM(X17:X39) -> 0 | Y40: =Y54 -> 0 | Z40: =Z54 -> 0 | AA40: =AA54 -> 0
...

Sheet 新媒体
B1: 2026年 5月新媒体薪资明细
B2: 岗位 | C2: 项目 | D2: 直播场次 | E2: 直播线索 （仅限 小风车线索、直播复盘数据做参考） | F2: 直播粉丝关注量 （仅限 对应账户） | G2: 视频创作发布量 | H2: 岗位绩效KPI | I2: 岗位绩效 | J2: 终端量提成（仅限 对应公司账户端量） | L2: 线索超额完成奖励 | N2: 直播场次超额奖励 | P2: 基本薪资 | Q2: 绩效薪资 | R2: 合计薪资
J3: 以月度目标制定 | K3: 终端完成 | L3: 超额部分10元/条 （上限1000元） | M3: 当月超额线索数 | N3: 超额部分100元/场 （上限500元） | O3: 直播超额 完成场次 | T3: 新媒体部门人力归属及分配（5月）
T4: 序号 | U4: 网属 | V4: 公司归属 | W4: 执行岗位 | X4: 岗位要求 | Y4: 姓名 | Z4: 负责店面 | AA4: 人力数量 | AB4: 绩效薪资 | AC4: 备注
B5: 直播运维专员 | C5: 月度目标量 | I5: =H9*H5% -> #DIV/0! | J5: 未完成50元/台 完成100元/台 | U5: G网 | V5: 吉星-西物 | W5: 新媒体经理/运营 | X5: 专职 | Y5: 肖廷忠 | Z5: 吉星 | AB5: =Q54 -> #DIV/0!
C6: 实际达成量 | M6: =E6-E5 -> 0 | Q6: =SUM(I5,J8,L8,N8) -> #DIV/0! | R6: =SUM(I5,J8,L8,N8,P6) -> #DIV/0! | U6: G网 | V6: 吉星-西物 | W6: 视频运营专员 | X6: 专职 | Y6: 黄凤 | Z6: 吉星 | AB6: =Q46 -> #DIV/0!
B7: 吉星G-西物 | C7: 实际达成率 | D7: =D6/D5 -> #DIV/0! | E7: =E6/E5 -> #DIV/0! | F7: =F6/F5 -> #DIV/0! | G7: =G6/G5 -> #DIV/0! | U7: G网 | V7: 吉星-西物 | W7: 新媒体主播 | X7: 专职 | Y7: 曾子乂 | Z7: 西物 | AB7: =Q6 -> #DIV/0!
C8: 考核分值数 | H8: =SUM(D8:G8) -> 0 | J8: =J6*K6 -> 0 | L8: =_xlfn.IFS(M6>=100,1000,M6<=100,M6*L6) -> 0 | N8: =_xlfn.IFS(O6>=5,500,O6<=5,O6*N6) -> 0 | U8: L网 | V8: 吉星-超市 | W8: 新媒体主播 | X8: 专职 | Y8: 王芝婕 | Z8: 超市 | AB8: =Q25 -> #DIV/0!
B9: 曾子乂 | C9: 考核得分数 | D9: =IF(D7>=100%,D8*1,D8*D7) -> #DIV/0! | E9: =IF(E7>=100%,E8*1,E8*E7) -> #DIV/0! | F9: =IF(F7>=100%,F8*1,F8*F7) -> #DIV/0! | G9: =IF(G7>=100%,G8*1,G8*G7) -> #DIV/0! | H9: =SUM(D9:G9) -> #DIV/0! | U9: L网 | V9: 吉星-超市 | W9: 新媒体主播 | X9: 专职 | Y9: 蓝仁楷 | Z9: 超市 | AB9: =Q34 -> #DIV/0!
U10: G网 | V10: 吉星-西物 | W10: 新媒体主播 | X10: 专职 | Y10: 何玉 | Z10: 西物G | AB10: =Q15 -> #DIV/0!
B11: 岗位 | C11: 项目 | D11: 直播场次 | E11: 直播线索 （仅限 小风车线索、直播复盘数据做参考） | F11: 直播粉丝关注量 （仅限 对应账户） | G11: 视频创作发布量 视频：40 小红书：20 | H11: 岗位绩效KPI | I11: 岗位绩效 | J11: 终端量提成（仅限 对应公司账户端量） | L11: 线索超额完成奖励 | N11: 直播场次超额奖励 | P11: 基本薪资 | Q11: 绩效薪资 | R11: 合计薪资 | U11: G网 | W11: 新媒体运营 | X11: 兼职 | Y11: 赵金秀 | Z11: 吉星
J12: 以月度目标制定 | K12: 终端完成 | L12: 超额部分10元/条 （上限1000元） | M12: 当月超额线索数 | N12: 超额部分100元/场 （上限500元） | O12: 直播超额 完成场次
B14: 直播运维专员 | C14: 月度目标量 | I14: =H18*H14% -> #DIV/0! | J14: 完成100元/台； 未完成50元/台
C15: 实际达成量 | M15: =E15-E14 -> 0 | Q15: =SUM(I14,J17,L17,N17) -> #DIV/0! | R15: =SUM(I14,J17,L17,N17,P15) -> #DIV/0!
B16: 吉星G-西物 | C16: 实际达成率 | D16: =D15/D14 -> #DIV/0! | E16: =E15/E14 -> #DIV/0! | F16: =F15/F14 -> #DIV/0! | G16: =G15/G14 -> #DIV/0!
C17: 考核分值数 | H17: =SUM(D17:G17) -> 0 | J17: =J15*K15 -> 0 | L17: =_xlfn.IFS(M15>=100,1000,M15<=100,M15*L15) -> 0 | N17: =_xlfn.IFS(O15>=5,500,O15<=5,O15*N15) -> 0
B18: 何玉 | C18: 考核得分数 | D18: =IF(D16>=100%,D17*1,D17*D16) -> #DIV/0! | E18: =IF(E16>=100%,E17*1,E17*E16) -> #DIV/0! | F18: =IF(F16>=100%,F17*1,F17*F16) -> #DIV/0! | G18: =IF(G16>=100%,G17*1,G17*G16) -> #DIV/0! | H18: =SUM(D18:G18) -> #DIV/0!
B21: 岗位 | C21: 项目 | D21: 直播场次 | E21: 直播线索 （仅限 小风车线索、直播复盘数据做参考） | F21: 直播粉丝关注量 （仅限 对应账户） | G21: 视频创作发布量 | H21: 岗位绩效KPI | I21: 岗位绩效 | J21: 终端量提成（仅限 对应公司账户端量） | L21: 线索超额完成奖励 | N21: 直播场次超额奖励 | P21: 基本薪资 | Q21: 绩效薪资 | R21: 合计薪资
J22: 以月度目标制定 | K22: 终端完成 | L22: 超额部分10元/条 （上限1000元） | M22: 当月超额线索数 | N22: 超额部分100元/场 （上限500元） | O22: 直播超额 完成场次
B24: 直播运维专员 | C24: 月度目标量 | I24: =H28*H24% -> #DIV/0! | J24: 未完成50元/台 完成100元/台
C25: 实际达成量 | M25: =E25-E24 -> 0 | O25: =D25-D24 -> 0 | Q25: =SUM(I24,J27,L27,N27) -> #DIV/0! | R25: =SUM(I24,J27,L27,N27,P25) -> #DIV/0!
B26: 吉星L-超市 | C26: 实际达成率 | D26: =D25/D24 -> #DIV/0! | E26: =E25/E24 -> #DIV/0! | F26: =F25/F24 -> #DIV/0! | G26: =G25/G24 -> #DIV/0!
C27: 考核分值数 | H27: =SUM(D27:G27) -> 0 | J27: =J25*K25 -> 0 | L27: =_xlfn.IFS(M25>=100,1000,M25<=100,M25*L25) -> 0 | N27: =_xlfn.IFS(O25>=5,500,O25<=5,O25*N25) -> 0
B28: 王芝婕 | C28: 考核得分数 | D28: =IF(D26>=100%,D27*1,D27*D26) -> #DIV/0! | E28: =IF(E26>=100%,E27*1,E27*E26) -> #DIV/0! | F28: =IF(F26>=100%,F27*1,F27*F26) -> #DIV/0! | G28: =IF(G26>=100%,G27*1,G27*G26) -> #DIV/0! | H28: =SUM(D28:G28) -> #DIV/0!
B30: 岗位 | C30: 项目 | D30: 直播场次 | E30: 直播线索 （仅限 小风车线索、直播复盘数据做参考） | F30: 直播粉丝关注量 （仅限 对应账户） | G30: 视频创作发布量 | H30: 岗位绩效KPI | I30: 岗位绩效 | J30: 终端量提成（仅限 对应公司账户端量） | L30: 线索超额完成奖励 | N30: 直播场次超额奖励 | P30: 基本薪资 | Q30: 绩效薪资 | R30: 合计薪资
J31: 以月度目标制定 | K31: 终端完成 | L31: 超额部分10元/条 （上限1000元） | M31: 当月超额线索数 | N31: 超额部分100元/场 （上限500元） | O31: 直播超额 完成场次
B33: 直播运维专员 | C33: 月度目标量 | I33: =H37*H33% -> #DIV/0! | J33: 未完成50元/台 完成100元/台
C34: 实际达成量 | O34: =D34-D33 -> 0 | Q34: =SUM(I33,J36,L36,N36) -> #DIV/0! | R34: =SUM(I33,J36,L36,N36,P34) -> #DIV/0!
B35: 吉星L—超市 | C35: 实际达成率 | D35: =D34/D33 -> #DIV/0! | E35: =E34/E33 -> #DIV/0! | F35: =F34/F33 -> #DIV/0! | G35: =G34/G33 -> #DIV/0!
C36: 考核分值数 | H36: =SUM(D36:G36) -> 0 | J36: =J34*K34 -> 0 | L36: =_xlfn.IFS(M34>=100,1000,M34<=100,M34*L34) -> 0 | N36: =_xlfn.IFS(O34>=5,500,O34<=5,O34*N34) -> 0
B37: 蓝仁楷 | C37: 考核得分数 | D37: =IF(D35>=100%,D36*1,D36*D35) -> #DIV/0! | E37: =IF(E35>=100%,E36*1,E36*E35) -> #DIV/0! | F37: =IF(F35>=100%,F36*1,F36*F35) -> #DIV/0! | G37: =IF(G35>=100%,G36*1,G36*G35) -> #DIV/0! | H37: =SUM(D37:G37) -> #DIV/0!
B42: 岗位 | C42: 项目 | D42: 视频创作发布数 | E42: 播放量 | F42: 短视频粉丝关注量 | G42: 小红书笔记发布 | H42: 岗位绩效KPI | I42: 岗位绩效 | J42: 终端量提成（双账户合计量） | L42: 优质视频视频奖励≥30000播放量 | N42: 视频创作超额完成奖励 | P42: 基本薪资 | Q42: 绩效薪资 | R42: 合计薪资
J43: 以月度目标制定 | K43: 终端完成 | L43: 优质视频50元/条 （上限500元） | M43: 优质视频数量 | N43: 超额部分50元/条 (上限500元) | O43: 视频超额完成数
E44: 播放量≥3000
B45: 视频运维专员 超市+西物视频 | C45: 月度目标量 | I45: =H49*H45% -> #DIV/0! | J45: 未完成20元/台； 完成30元/台
C46: 实际达成量 | O46: =D46-D45 -> 0 | Q46: =SUM(I45,J48,L48,N48) -> #DIV/0! | R46: =SUM(I45,J48,L48,N48,P46) -> #DIV/0!
B47: 吉星G-西物 | C47: 实际达成率 | D47: =D46/D45 -> #DIV/0! | E47: =E46/E45 -> #DIV/0! | F47: =F46/F45 -> #DIV/0! | G47: =G46/G45 -> #DIV/0!
C48: 考核分值数 | H48: =SUM(D48:G48) -> 0 | J48: =J46*K46 -> 0 | L48: =L46*M46 -> 0
B49: 黄凤 | C49: 考核得分数 | D49: =IF(D47>=100%,D48*1,D48*D47) -> #DIV/0! | E49: =IF(E47>=100%,E48*1,E48*E47) -> #DIV/0! | F49: =IF(F47>=100%,F48*1,F48*F47) -> #DIV/0! | G49: =IF(G47>=100%,G48*1,G48*G47) -> #DIV/0! | H49: =SUM(D49:G49) -> #DIV/0!
B52: 岗位 | C52: 项目 | D52: 直播场次数 | E52: 视频创作数 | F52: 线索量 （月度目标制定） | G52: 邀约到店数 （月度目标制定） | H52: 岗位绩效KPI | I52: 岗位绩效 | J52: 终端量提成 | L52: 底薪薪资 | M52: 无 | N52: 无 | O52: 无 | P52: 无 | Q52: 绩效薪资 | R52: 合计薪资
...

Sheet 邀约专员提成
B1: 05月 | C1: 人员 | D1: 人员 | AE1: 总绩效 | AF1: 发放金额
E2: 标准 | F2: 是否达成 | G2: 考核 | H2: 标准 | I2: 实际得分 | J2: 绩效 | K2: 单台绩效 | L2: 到店量 | M2: 绩效 | N2: 单台绩效 | O2: 成交台次 | P2: 绩效 | Q2: 计划线索分配量 | R2: 线索分配量 | S2: 邀约率 | T2: 单组追加 | U2: 奖励提成 | V2: 成交率 | W2: 单台追加 | X2: 奖励提成 | Y2: 单组追加 | Z2: 重攻台次 | AA2: 奖励 | AB2: 邀约任务 | AC2: 完成率
B3: 西物 | C3: 金玉梅 | G3: 六项标准均达成 | L3: =K3*J3 -> 0 | O3: =M3*N3 -> 0 | R3: =IFERROR(K3/Q3,"") | T3: =S3*K3 -> 0 | U3: =IFERROR(N3/K3,"") | W3: =N3*V3 -> 0 | Z3: =X3*Y3 -> 0 | AB3: =IFERROR(K3/AA3,"") | AD3: =I3+L3+O3+T3+W3+Z3+AC3+F3 -> 0 | AE3: 金玉梅 | AF3: =AD3 -> 0
B4: 西物 | C4: 周思雨 | L4: =K4*J4 -> 0 | O4: =M4*N4 -> 0 | R4: =IFERROR(K4/Q4,"") | T4: =S4*K4 -> 0 | U4: =IFERROR(N4/K4,"") | W4: =N4*V4 -> 0 | Z4: =X4*Y4 -> 0 | AB4: =IFERROR(K4/AA4,"") | AD4: =I4+L4+O4+T4+W4+Z4+AC4+F4 -> 0 | AE4: 周思雨 | AF4: =AD4 -> 0
B5: 西物 | C5: 陈文霜 | L5: =K5*J5 -> 0 | O5: =M5*N5 -> 0 | R5: =IFERROR(K5/Q5,"") | T5: =S5*K5 -> 0 | U5: =IFERROR(N5/K5,"") | W5: =N5*V5 -> 0 | Z5: =X5*Y5 -> 0 | AB5: =IFERROR(K5/AA5,"") | AD5: =I5+L5+O5+T5+W5+Z5+AC5+F5 -> 0 | AE5: 陈文霜 | AF5: =AD5 -> 0
B6: 西物 | C6: 杜小红 | L6: =K6*J6 -> 0 | O6: =M6*N6 -> 0 | R6: =IFERROR(K6/Q6,"") | T6: =S6*K6 -> 0 | U6: =IFERROR(N6/K6,"") | W6: =N6*V6 -> 0 | Z6: =X6*Y6 -> 0 | AB6: =IFERROR(K6/AA6,"") | AD6: =I6+L6+O6+T6+W6+Z6+AC6+F6 -> 0 | AE6: 杜小红 | AF6: =AD6 -> 0
B7: 西物 | C7: 周梅 | L7: =K7*J7 -> 0 | O7: =M7*N7 -> 0 | R7: =IFERROR(K7/Q7,"") | T7: =S7*K7 -> 0 | U7: =IFERROR(N7/K7,"") | W7: =N7*V7 -> 0 | Z7: =X7*Y7 -> 0 | AB7: =IFERROR(K7/AA7,"") | AD7: =I7+L7+O7+T7+W7+Z7+AC7+F7 -> 0 | AE7: 周梅 | AF7: =AD7 -> 0
B9: 05月 | C9: 人员 | D9: 400接起率 | G9: DMS指标六维度 | J9: 邀约绩效60元/组 | M9: 成交绩效40元/台 | P9: 缤越COOL、博越COOL、缤瑞COOL | S9: 成交率奖励 | V9: 任务考核 | Y9: 总绩效
D10: 标准 | E10: 是否达成 | F10: 考核 | G10: 标准 | H10: 实际得分 | I10: 绩效 | J10: 单台绩效 | K10: 到店量 | L10: 绩效 | M10: 单台绩效 | O10: 绩效 | P10: 达成邀约量 | Q10: 单组到店追加 | R10: 奖励提成 | S10: 成交率 | T10: 单台追加 | U10: 奖励提成 | V10: 邀约任务 | W10: 完成率 | X10: 考核金额
B11: 超市 | C11: 李春梅 | G11: 六项标准均达成 | AE11: =C11 -> 李春梅 | AF11: =Y11 -> 0
B12: 超市 | C12: 魏艳 | AE12: =C12 -> 魏艳 | AF12: =Y12 -> 0
B13: 超市 | C13: 谷雨 | AE13: =C13 -> 谷雨 | AF13: =Y13 -> 0
B15: 05月 | C15: 人员 | D15: 400接起率 | G15: DMS指标六维度 | J15: 邀约绩效60元/组 | M15: 成交绩效40元/台 | P15: 过程KPI奖励 | X15: 重攻奖励： | AA15: 任务考核 | AD15: 总绩效 | AE15: 杨婷 | AF15: =AD17 -> 0
D16: 标准 | E16: 是否达成 | F16: 考核 | G16: 标准 | H16: 实际得分 | I16: 绩效 | J16: 单台绩效 | K16: 到店量 | L16: 绩效 | M16: 单台绩效 | N16: 成交台次 | O16: 绩效 | P16: 计划线索分配量 | Q16: 线索分配量 | R16: 邀约率 | S16: 单组追加 | T16: 奖励提成 | U16: 成交率 | V16: 单台追加 | W16: 奖励提成 | X16: 单组追加 | Y16: 重攻台次 | Z16: 奖励 | AA16: 邀约任务 | AB16: 完成率 | AC16: 考核金额 | AE16: 陈子逸 | AF16: =W32 -> 0
B17: 崇州 | C17: 杨婷 | G17: 六项标准均达成 | L17: =K17*J17 -> 0 | O17: =M17*N17 -> 0 | R17: =IFERROR(K17/Q17,"") | T17: =S17*K17 -> 0 | U17: =IFERROR(N17/K17,"") | W17: =N17*V17 -> 0 | Z17: =X17*Y17 -> 0 | AB17: =IFERROR(K17/AA17,"") | AD17: =I17+L17+O17+T17+W17+Z17-AC17-F17 -> 0
B18: 1.400接起率出现未接起考核500元
B19: 2.DMS六维度指标：1.线索有效率70% 2.响应及时率100% 3.及时跟进率100% 4.邀约到店率15% 5.到店成交率35% 6.线索成交率4% 7.战败率90%以下，每项达成按100元计提，7项指标均达成追加100元。
B20: 3.邀约基础绩效：基础绩效60元一组
B21: 4.邀约到店率≥15%追加10元一组，未达标不奖励
B22: 5.成交基础绩效：基础绩效40元/台
B23: 6.成交率30-＜35%，追加20元/台成交；成交率≥35%，追加30元/台成交
B24: 7.有重攻车型时可设立重攻车型，重攻车型客户到店额外追加10元/组
B25: 8.任务考核：设立当月邀约到店目标量，未达成按照比例进行计提邀约绩效，上限100%
B26: 9.薪资方案由网销经理填报，销售总监/副总审核，总经理签字确认，承报财务/行政纳入当月绩效。
B27: 备注：1.到店率及成交率随市场变化，合理设定及上浮邀约专员追加指标。 2.店内过程指标需真实有效，DMS指标可手段提升
L30: 任务达成
C31: 员工 | D31: 店面 | E31: 基本工资 | F31: 岗位工资 | G31: DMS指标绩效/70元/项 | H31: 自媒体绩效(含内部员工转发率） | I31: 线索提成标准 | J31: 终端提成标准（月计算完成率） | K31: 线索任务 | L31: 销售任务 | M31: 线索数 | N31: 线索达成率 | O31: 终端达成 | P31: 终端达成率 | Q31: 线索绩效 | R31: 终端绩效 | S31: 新车上市4月内线索激励减半量 | T31: 线索减半金额 | U31: 考核 | V31: 绩效提成 | W31: 实际发放 | X31: 薪酬总额
C32: 陈子逸 | D32: 机场网销

Sheet 客户部提成
A1: 05月客户关系部 | AO1: A | AP1: B | AQ1: C=B-A | AR1: D | AS1: E | AT1: F=D*E
A2: 值 | B2: 项 | C2: 达成率 | D2: 系数 | E2: 邓芳 | G2: 张保珍 | I2: 备注 | K2: 05月 | L2: 潜客回访 | M2: 5天新车回访 | N2: 30天新车回访 | O2: 潜客战败回访 | P2: 新车回访绩效 | Q2: 面访量 | R2: 面访（6元/个） | S2: 多对一群聊建立量 | T2: 多对一群聊建立及维护（5元） | U2: 生日关怀接通量 | V2: 生日关怀绩效提成（2元/个） | W2: 口碑/发帖量 | X2: 口碑发帖绩效（X/个） | Y2: 投诉处理 | Z2: 销售满意度得分 | AA2: 销售满意度绩效 | AB2: 保客营销 | AD2: 合计薪资 | AE2: 备注 | AH2: 保客营销挖掘与转化绩效 | AN2: 店面——中国星武侯 | AO2: 1-3月数据情况 | AP2: 5月达成情况 | AQ2: 达成提升目标(%) | AR2: 台次(交付数) | AS2: 享受单台 | AT2: 金额
E3: 数量 | F3: 小计 | G3: 数量 | H3: 小计 | K3: 周舟 | P3: =SUM(L3:O3)*2 -> 0 | R3: =Q3*6 -> 0 | T3: =S3*5 -> 0 | V3: =U3*2 -> 0 | X3: =W3*50 -> 0 | AD3: =SUM(P3,R3,T3,V3,X3,Y3,AA3,AB3) -> 0 | AH3: 基盘客户 转介绍 | AI3: 绩效(元/台) | AN3: 电话回访 | AP3: =727+847 -> 1574
A4: 必做 | B4: 3DC一网 | F4: =D4*E4 -> 0 | H4: =G4*D4 -> 0 | K4: 合计 | AI4: 提升目标（%） | AJ4: 提升＜1% | AK4: 1%≤提升＜3% | AL4: 提升≥3% | AN4: 基盘客户转介绍 | AQ4: =+AP4-AO4 -> 0 | AS4: =+IF(AQ4<1%,20,IF(AQ4<3%,30,40)) -> 20 | AT4: =AR4*AS4 -> 0
A5: 必做 | B5: 3DC二网 | F5: =D5*E5 -> 0 | H5: =G5*D5 -> 0 | K5: 1.潜客回访、3天新车回访、30天新车回访、战败客户回访、生日关怀、售后3DC标准提成按电话接通2元/组 2.新车面访6元/个 3.口碑/发帖：＜5篇，30元/帖；≥5帖＜10帖，40元/帖；≥10帖，50元/帖；最高1000元 4.生日关怀，接通1元/个; 5.投诉处理：2小时未响应考核200元/单 3天未闭环考核500元/单，投诉单申述未通过考核200元/单，无异常奖励200元， 6.销售满意度：400得分90分及以下，考核200元；≥93分，奖励300元；≥95分，奖励500元 | AH5: 保客挖掘 置换/增购 | AI5: 绩效(元/台) | AN5: 保客挖掘置换/增购 | AS5: =+IF(AQ5>=3%,50,IF(AQ5>=1%,40,30)) -> 30 | AT5: =AR5*AS5 -> 0
A6: 必做 | B6: 新车5DC回访 | F6: =D6*E6 -> 0 | H6: =G6*D6 -> 0 | AI6: 提升目标（%） | AJ6: 提升＜1% | AK6: 1%≤提升＜3% | AL6: 提升≥3% | AN6: 全员营销 | AQ6: =+AP6-AO6 -> 0 | AS6: =+IF(AQ6<1%,10,IF(AQ6<3%,20,30)) -> 10 | AT6: =AR6*AS6 -> 0
A7: 必做 | B7: 新车30DC回访 | F7: =D7*E7 -> 0 | H7: =G7*D7 -> 0 | AH7: 全员营销 | AI7: 绩效(元/台) | AN7: 绩效合计 | AO7: 邓芳 | AT7: =SUM(AT3:AT6) -> 0
A8: 必做 | B8: 战败回访 | F8: =D8*E8 -> 0 | H8: =G8*D8 -> 0 | AI8: 提升目标（%） | AJ8: 提升＜1% | AK8: 1%≤提升＜3% | AL8: 提升≥3%
A9: 必做 | B9: 潜客回访 | F9: =D9*E9 -> 0 | H9: =G9*D9 -> 0 | AH9: 基本数据要求： | AN9: 店面——银河B武侯 | AO9: 1-3月数据情况 | AP9: 5月达成情况 | AQ9: 达成提升目标(%) | AR9: 台次(交付数) | AS9: 享受单台 | AT9: 金额
A10: 机动 | B10: 其他回访 | F10: =D10*E10 -> 0 | H10: =G10*D10 -> 0 | I10: 其他回访，是指核实老带新，核实债权转让，活动参加等临时事项 | AH10: 1、增加500元固定绩效，要求每日对基盘客户有效回访数＞30批次，单人每月有效回访批次＞900批 2、以上三类别计算基数分母为：当月销量 3、此方案试运行时间为：4月-6月，后续另行调整 | AN10: 电话回访
A11: 必做 | B11: 新车面访 | F11: =D11*E11 -> 0 | H11: =G11*D11 -> 0 | AN11: 基盘客户转介绍 | AQ11: =+AP11-AO11 -> 0 | AS11: =+IF(AQ11<1%,20,IF(AQ11<3%,30,40)) -> 20 | AT11: =AR11*AS11 -> 0
A12: 必做 | B12: 微信维系 | F12: =D12*E12 -> 0 | H12: =G12*D12 -> 0 | AN12: 保客挖掘置换/增购 | AO12: 4月新增项目 | AS12: =+IF(AQ12>=3%,50,IF(AQ12>=1%,40,30)) -> 30 | AT12: =AR12*AS12 -> 0
A13: 必做 | B13: 投诉处理 | F13: =D13*E13 -> 0 | H13: =G13*D13 -> 0 | AN13: 全员营销 | AQ13: =+AP13-AO13 -> 0 | AS13: =+IF(AQ13<1%,10,IF(AQ13<3%,20,30)) -> 10 | AT13: =AR13*AS13 -> 0
A14: 必做 | B14: 微信添加 | F14: =D14*E14 -> 0 | H14: =G14*D14 -> 0 | AN14: 绩效合计 | AO14: 李璐秀 | AT14: =SUM(AT10:AT13) -> 0
A15: 机动 | B15: 满意度 | F15: =D15*E15 -> 0 | H15: =G15*D15 -> 0 | I15: 4月400销售满意度：西物95.65分
A16: 增值 | B16: 口碑 | F16: =D16*E16 -> 0 | H16: =G16*D16 -> 0
A17: 增值 | B17: 发帖 | F17: =D17*E17 -> 0 | H17: =G17*D17 -> 0 | AN17: 店面——银河A武侯 | AO17: 1-3月数据情况 | AP17: 5月达成情况 | AQ17: 达成提升目标(%) | AR17: 台次(交付数) | AS17: 享受单台 | AT17: 金额
A18: 增值 | B18: N-3首保 | F18: =D18*E18 -> 0 | H18: =G18*D18 -> 0 | AN18: 电话回访
A19: 增值 | B19: N-4首保 | F19: =D19*E19 -> 0 | H19: =G19*D19 -> 0 | AN19: 基盘客户转介绍 | AQ19: =+AP19-AO19 -> 0 | AS19: =+IF(AQ19<1%,20,IF(AQ19<3%,30,40)) -> 20 | AT19: =AR19*AS19 -> 0
A20: 增值 | B20: N-5首保 | F20: =D20*E20 -> 0 | H20: =G20*D20 -> 0 | AN20: 保客挖掘置换/增购 | AO20: 4月新增项目 | AS20: =+IF(AQ20>=3%,50,IF(AQ20>=1%,40,30)) -> 30 | AT20: =AR20*AS20 -> 0
A21: 增值 | B21: N-6二保 | F21: =D21*E21 -> 0 | H21: =G21*D21 -> 0 | AN21: 全员营销 | AQ21: =+AP21-AO21 -> 0 | AS21: =+IF(AQ21<1%,10,IF(AQ21<3%,20,30)) -> 10 | AT21: =AR21*AS21 -> 0
A22: 增值 | B22: N-9二保 | F22: =D22*E22 -> 0 | H22: =G22*D22 -> 0 | AN22: 绩效合计 | AO22: 郭静 | AT22: =SUM(AT18:AT21) -> 0
A23: 增值 | B23: N-12二保 | F23: =D23*E23 -> 0 | H23: =G23*D23 -> 0
A24: 增值 | B24: N-6定保 | F24: =D24*E24 -> 0 | H24: =G24*D24 -> 0
A25: 增值 | B25: N-9定保 | F25: =D25*E25 -> 0 | H25: =G25*D25 -> 0 | AN25: 店面——银河B机场 | AO25: 1-3月数据情况 | AP25: 5月达成情况 | AQ25: 达成提升目标(%) | AR25: 台次(交付数) | AS25: 享受单台 | AT25: 金额
A26: 增值 | B26: N-12定保 | F26: =D26*E26 -> 0 | H26: =G26*D26 -> 0 | AN26: 电话回访
A27: 增值 | B27: 外拓 | F27: =D27*E27 -> 0 | H27: =G27*D27 -> 0 | AN27: 基盘客户转介绍 | AQ27: =+AP27-AO27 -> 0 | AS27: =+IF(AQ27<1%,20,IF(AQ27<3%,30,40)) -> 20 | AT27: =AR27*AS27 -> 0
A28: 增值 | B28: N-6其他 | F28: =D28*E28 -> 0 | H28: =G28*D28 -> 0 | AN28: 保客挖掘置换/增购 | AO28: 4月新增项目 | AS28: =+IF(AQ28>=3%,50,IF(AQ28>=1%,40,30)) -> 30 | AT28: =AR28*AS28 -> 0
A29: 增值 | B29: N-9其他 | F29: =D29*E29 -> 0 | H29: =G29*D29 -> 0 | AN29: 全员营销 | AQ29: =+AP29-AO29 -> 0 | AS29: =+IF(AQ29<1%,10,IF(AQ29<3%,20,30)) -> 10 | AT29: =AR29*AS29 -> 0
A30: 增值 | B30: N-12其他 | F30: =D30*E30 -> 0 | H30: =G30*D30 -> 0 | AN30: 绩效合计 | AO30: 古瑞婷 | AT30: =SUM(AT26:AT29) -> 0
A31: 增值 | B31: 无福袋 | F31: =D31*E31 -> 0 | H31: =G31*D31 -> 0
A32: 增值 | B32: 纯电回站 | F32: =D32*E32 -> 0 | H32: =G32*D32 -> 0 | I32: 2023年4月1号起，纯电车型预约回站，按8元/个计算
A33: 增值 | B33: 车机 | F33: =D33*E33 -> 0 | H33: =G33*D33 -> 0 | AN33: 店面——中国星机场 | AO33: 1-3月数据情况 | AP33: 5月达成情况 | AQ33: 达成提升目标(%) | AR33: 台次(交付数) | AS33: 享受单台 | AT33: 金额
A34: 增值 | B34: 福袋 | F34: =D34*E34 -> 0 | H34: =G34*D34 -> 0 | AN34: 电话回访
A35: 增值 | B35: 质保 | F35: =D35*E35 -> 0 | H35: =G35*D35 -> 0 | AN35: 基盘客户转介绍 | AQ35: =+AP35-AO35 -> 0 | AS35: =+IF(AQ35<1%,20,IF(AQ35<3%,30,40)) -> 20 | AT35: =AR35*AS35 -> 0
A36: 增值 | B36: 流失 | F36: =D36*E36 -> 0 | H36: =G36*D36 -> 0 | AN36: 保客挖掘置换/增购 | AO36: 4月新增项目 | AS36: =+IF(AQ36>=3%,50,IF(AQ36>=1%,40,30)) -> 30 | AT36: =AR36*AS36 -> 0
A37: 增值 | B37: 续保 | F37: =D37*E37 -> 0 | H37: =G37*D37 -> 0 | AN37: 全员营销 | AQ37: =+AP37-AO37 -> 0 | AS37: =+IF(AQ37<1%,10,IF(AQ37<3%,20,30)) -> 10 | AT37: =AR37*AS37 -> 0
A38: 增值 | B38: 轮胎 | F38: =D38*E38 -> 0 | H38: =G38*D38 -> 0 | AN38: 绩效合计 | AO38: 周舟 | AT38: =SUM(AT34:AT37) -> 0
A39: 增值 | B39: LED | F39: =D39*E39 -> 0 | H39: =G39*D39 -> 0
A40: 增值 | B40: 盲区 | F40: =D40*E40 -> 0 | H40: =G40*D40 -> 0
...

Sheet 直营店经理提成 (财务)
D1: 直营店店面 | J1: 直营店二网
B2: 店别 | C2: 展厅任务销售台次 | D2: 展厅实际销售台次 | E2: 新能源展厅实际销售台次 | F2: 完成率 | G2: 单台提成标准 | H2: 单台提成金额 | I2: 渠道任务销售台次 | J2: 渠道实际销售台次 | K2: 新能源渠道任务销售台次 | L2: 完成率 | M2: 单台提成标准 | N2: 单台提成金额 | O2: 台次提成合计 | P2: 附加收入提成合计 | Q2: 固定绩效 | R2: 提成合计 | S2: 指定车型考核 | T2: 考核金额 | AN2: 序号 | AO2: 出库日期 | AP2: 客户姓名 | AQ2: 电话 | AR2: 按揭信息 | BA2: 贴息信息 | BF2: 上户地 | BG2: 销售部门 | BH2: 直营店经理 | BI2: 车架号 | BJ2: 直营店经理 奖励金额
B3: 崇州直营店 | F3: =IF(C3<>0,IF(D3/C3>110%,110%,D3/C3),0) -> 0 | H3: =D3*F3*G3+E3*G3 -> 0 | L3: =IF(I3<>0,IF(J3/I3>110%,110%,J3/I3),0) -> 0 | N3: =L3*M3*J3+K3*M3 -> 0 | O3: =H3+N3 -> 0 | P3: =V13 -> 0 | Q3: =2500 -> 2500 | R3: =SUM(O3:Q3)+V3 -> 2500 | AR3: 总车价 | AS3: 期数 | AT3: 产品 | AU3: 贷款金额 | AV3: 附加贷 | AW3: 首付金额 | AX3: 首付比例 | AY3: 车型 | AZ3: 金融公司 | BA3: 贴息 | BB3: 工厂贴息 | BC3: 金融公司 贴息 | BD3: 客户补息 | BE3: 我司贴息
B4: 大邑直营店 | F4: =IF(C4<>0,IF(D4/C4>110%,110%,D4/C4),0) -> 0 | H4: =D4*F4*G4+E4*G4 -> 0 | L4: =IF(I4<>0,IF(J4/I4>110%,110%,J4/I4),0) -> 0 | N4: =L4*M4*J4+K4*M4 -> 0 | O4: =H4+N4 -> 0 | P4: =V14 -> 0 | Q4: =2500 -> 2500 | R4: =SUM(O4:Q4)+V4 -> 2500 | AP4: 隆波 | AT4: 60建行三支行(普通) | AY4: 星越L | AZ4: 建行三支行 | BA4: 是 | BF4: A成都 | BG4: 彭州直营店 | BH4: 黎明朗 | BI4: LB37852Z0TS027357
B5: 华阳直营店 | F5: =IF(C5<>0,IF(D5/C5>110%,110%,D5/C5),0) -> 0 | H5: =D5*F5*G5+E5*G5 -> 0 | L5: =IF(I5<>0,IF(J5/I5>110%,110%,J5/I5),0) -> 0 | N5: =L5*M5*J5+K5*M5 -> 0 | O5: =H5+N5 -> 0 | P5: =V15 -> 0 | Q5: =2500 -> 2500 | R5: =SUM(O5:Q5)+V5 -> 2500 | AP5: 刘倩言 | AT5: 60吉致(9.58%标贷) | AY5: 新博越 | AZ5: 吉致 | BA5: 否 | BF5: A成都 | BG5: 邛崃直营店 | BH5: 吴思超 | BI5: LB37722Z6TX316067
B6: 华阳领克 | F6: =IF(C6<>0,IF(D6/C6>110%,110%,D6/C6),0) -> 0 | H6: =D6*F6*G6+E6*G6 -> 0 | L6: =IF(I6<>0,IF(J6/I6>110%,110%,J6/I6),0) -> 0 | N6: =L6*M6*J6+K6*M6 -> 0 | O6: =H6+N6 -> 0 | P6: =V16 -> 0 | R6: =SUM(O6:Q6)+V6 -> 0 | AP6: 肖杨 | AT6: 60吉致(安心宝) | AY6: 第5代帝豪 | AZ6: 吉致 | BA6: 是 | BF6: A成都 | BG6: 崇州直营店 | BH6: 朱剑波 | BI6: LB37824Z1TG026166
B7: 彭州直营店 | F7: =IF(C7<>0,IF(D7/C7>110%,110%,D7/C7),0) -> 0 | H7: =D7*F7*G7+E7*G7 -> 0 | L7: =IF(I7<>0,IF(J7/I7>110%,110%,J7/I7),0) -> 0 | N7: =L7*M7*J7+K7*M7 -> 0 | O7: =H7+N7 -> 0 | P7: =V17 -> 0 | Q7: =2500+750 -> 3250 | R7: =SUM(O7:Q7)+V7 -> 3250 | AP7: 罗利华 | AT7: 60吉致(安心宝) | AY7: 第四代博越L | AZ7: 吉致 | BA7: 是 | BF7: A成都 | BG7: 华阳直营店 | BH7: 钟涛 | BI7: LB37822Z7TB041979
B8: 邛崃直营店 | F8: =IF(C8<>0,IF(D8/C8>110%,110%,D8/C8),0) -> 0 | H8: =D8*F8*G8+E8*G8 -> 0 | L8: =IF(I8<>0,IF(J8/I8>110%,110%,J8/I8),0) -> 0 | N8: =L8*M8*J8+K8*M8 -> 0 | O8: =H8+N8 -> 0 | P8: =V18 -> 0 | Q8: =2500 -> 2500 | R8: =SUM(O8:Q8)+V8 -> 2500 | AP8: 濮寿邦 | AT8: 60吉致(安心宝) | AY8: 星越L | AZ8: 吉致 | BA8: 是 | BF8: A成都 | BG8: 崇州直营店 | BH8: 朱剑波 | BI8: LB37852ZXTS027950
B9: 合计 | C9: =SUM(C3:C8) -> 0 | D9: =SUM(D3:D8) -> 0 | E9: =SUM(E3:E8) -> 0 | I9: =SUM(I3:I8) -> 0 | J9: =SUM(J3:J8) -> 0 | O9: =SUM(O3:O8) -> 0 | P9: =SUM(P3:P8) -> 0 | Q9: =SUM(Q3:Q8) -> 13250 | R9: =SUM(R3:R8) -> 13250 | AP9: 何冉 | AT9: 60吉致(安心宝) | AY9: 豪越L | AZ9: 吉致 | BA9: 是 | BF9: A成都 | BG9: 崇州直营店 | BH9: 朱剑波 | BI9: L6T7922Z0TY871239
AP10: 唐庆 | AT10: 60吉致(安心宝) | AY10: 星越L | AZ10: 吉致 | BA10: 是 | BF10: A成都 | BG10: 华阳直营店 | BH10: 钟涛 | BI10: LB37852Z4TS040239
AP11: 黎智全 | AT11: 60吉致(9.58%标贷) | AY11: 豪越L | AZ11: 吉致 | BA11: 否 | BF11: A成都 | BG11: 彭州直营店 | BH11: 黎明朗 | BI11: L6T7922Z3SY852750
B12: 店别 | C12: 展厅按提台次 | D12: 展厅实际销售台次 | E12: 渠道按提台次 | F12: 渠道实际销售台次 | G12: 展厅手续费实际金额 | H12: 展厅手续费标准金额（考核标准） | I12: 渠道手续费实际金额 | J12: 渠道手续费标准金额（考核标准） | K12: 爱车保毛利 | L12: 爱车保毛利标准 | M12: 上户费合计（扣出库）实际 | N12: 上户费合计（扣出库）标准 | O12: 整车超权限 | P12: 实际附加收入 | Q12: 标准附加收入 | R12: 差异 | S12: 盈利性渗透率 | T12: 盈利性渗透率 | U12: 盈利性提成金额 | V12: 新工资标准 | AP12: 罗新华 | AT12: 60吉致(安心宝) | AY12: 第四代博越L | AZ12: 吉致 | BA12: 是 | BF12: A成都 | BG12: 华阳直营店 | BH12: 钟涛 | BI12: LB37822Z4TB044774
A13: 朱剑波 | B13: 崇州直营店 | D13: =D3 -> 0 | F13: =J3 -> 0 | H13: =D13*0.55*283 -> 0 | J13: =F13*0.3*170 -> 0 | L13: =D13*0.3*1085 -> 0 | N13: =D13*552*1.06 -> 0 | P13: =G13+I13+K13+M13+O13 -> 0 | Q13: =H13+J13+L13+N13 -> 0 | R13: =P13-Q13 -> 0 | U13: =IF(D13>0,ROUND((IF(T13/S13>110%,SUMIF(BH:BH,A13,BJ:BJ)*110%,SUMIF(BH:BH,A13,BJ:BJ)*(T13/S13))),2),0) -> 0 | V13: =IF(R13<=0,(P13+R13)*0.05,P13*0.05)+U13 -> 0 | W13: =P13-Q13 -> 0 | AP13: 张志友 | AT13: 60吉致(安心宝) | AY13: 星瑞(1.5T) | AZ13: 吉致 | BA13: 是 | BF13: A成都 | BG13: 彭州直营店 | BH13: 黎明朗 | BI13: L6T7924Z9TD052802
A14: 孙伟 | B14: 大邑直营店 | D14: =D4 -> 0 | F14: =J4 -> 0 | H14: =D14*0.55*283 -> 0 | J14: =F14*0.3*170 -> 0 | L14: =D14*0.3*1085 -> 0 | N14: =D14*552*1.06 -> 0 | P14: =G14+I14+K14+M14+O14 -> 0 | Q14: =H14+J14+L14+N14 -> 0 | R14: =P14-Q14 -> 0 | U14: =IF(D14>0,ROUND((IF(T14/S14>110%,SUMIF(BH:BH,A14,BJ:BJ)*110%,SUMIF(BH:BH,A14,BJ:BJ)*(T14/S14))),2),0) -> 0 | V14: =IF(R14<=0,(P14+R14)*0.05,P14*0.05)+U14 -> 0 | W14: =P14-Q14 -> 0 | AP14: 陈静 | AT14: 60吉致(安心宝) | AY14: 星瑞(1.5T) | AZ14: 吉致 | BA14: 是 | BF14: A成都 | BG14: 邛崃直营店 | BH14: 吴思超 | BI14: L6T7924Z3TD056019
A15: 钟涛 | B15: 华阳直营店 | D15: =D5 -> 0 | F15: =J5 -> 0 | H15: =D15*0.55*283 -> 0 | J15: =F15*0.3*170 -> 0 | L15: =D15*0.3*1085 -> 0 | N15: =D15*552*1.06 -> 0 | P15: =G15+I15+K15+M15+O15 -> 0 | Q15: =H15+J15+L15+N15 -> 0 | R15: =P15-Q15 -> 0 | U15: =IF(D15>0,ROUND((IF(T15/S15>110%,SUMIF(BH:BH,A15,BJ:BJ)*110%,SUMIF(BH:BH,A15,BJ:BJ)*(T15/S15))),2),0) -> 0 | V15: =IF(R15<=0,(P15+R15)*0.05,P15*0.05)+U15 -> 0 | W15: =P15-Q15 -> 0
B16: 华阳领克 | D16: =D6 -> 0 | F16: =J6 -> 0 | H16: =D16*0.55*283 -> 0 | J16: =F16*0.3*170 -> 0 | L16: =D16*0.3*1085 -> 0 | N16: =D16*552*1.06 -> 0 | P16: =G16+I16+K16+M16+O16 -> 0 | Q16: =H16+J16+L16+N16 -> 0 | U16: =IF(D16>0,ROUND((IF(T16/S16>110%,SUMIF(BH:BH,A16,BJ:BJ)*110%,SUMIF(BH:BH,A16,BJ:BJ)*(T16/S16))),2),0) -> 0 | V16: =IF(R16<=0,(P16+R16)*0.05,P16*0.05)+U16 -> 0 | W16: =P16-Q16 -> 0
A17: 黎明朗 | B17: 彭州直营店 | D17: =D7 -> 0 | F17: =J7 -> 0 | H17: =D17*0.55*283 -> 0 | J17: =F17*0.3*170 -> 0 | L17: =D17*0.3*1085 -> 0 | N17: =D17*552*1.06 -> 0 | P17: =G17+I17+K17+M17+O17 -> 0 | Q17: =H17+J17+L17+N17 -> 0 | R17: =P17-Q17 -> 0 | U17: =IF(D17>0,ROUND((IF(T17/S17>110%,SUMIF(BH:BH,A17,BJ:BJ)*110%,SUMIF(BH:BH,A17,BJ:BJ)*(T17/S17))),2),0) -> 0 | V17: =IF(R17<=0,(P17+R17)*0.05,P17*0.05)+U17 -> 0 | W17: =P17-Q17 -> 0
A18: 吴思超 | B18: 邛崃直营店 | D18: =D8 -> 0 | F18: =J8 -> 0 | H18: =D18*0.55*283 -> 0 | J18: =F18*0.3*170 -> 0 | L18: =D18*0.3*1085 -> 0 | N18: =D18*552*1.06 -> 0 | P18: =G18+I18+K18+M18+O18 -> 0 | Q18: =H18+J18+L18+N18 -> 0 | R18: =P18-Q18 -> 0 | U18: =IF(D18>0,ROUND((IF(T18/S18>110%,SUMIF(BH:BH,A18,BJ:BJ)*110%,SUMIF(BH:BH,A18,BJ:BJ)*(T18/S18))),2),0) -> 0 | V18: =IF(R18<=0,(P18+R18)*0.05,P18*0.05)+U18 -> 0 | W18: =P18-Q18 -> 0
B19: 合计 | C19: =SUM(C13:C18) -> 0 | D19: =SUM(D13:D18) -> 0 | E19: =SUM(E13:E18) -> 0 | F19: =SUM(F13:F18) -> 0 | G19: =SUM(G13:G18) -> 0 | H19: =SUM(H13:H18) -> 0 | I19: =SUM(I13:I18) -> 0 | J19: =SUM(J13:J18) -> 0 | ... O19: =SUM(O13:O18) -> 0 | P19: =G19+I19+K19+M19+O19 -> 0 | Q19: =H19+J19+L19+N19 -> 0 | R19: =SUM(R13:R18) -> 0 | U19: =SUM(U13:U18) -> 0 | V19: =SUM(V13:V18) -> 0 | W19: =SUM(W13:W18) -> 0 | X19: =SUM(X13:X18) -> 0
X20: =IF(V20<=0,(R20+V20)*0.05,R20*0.05) -> 0

Sheet 招聘
A2: 2026年05月招聘报表
A3: 序号 | B3: 日期 | C3: 公司 | D3: 邀约岗位 | E3: 面试者姓名 | F3: 电话 | G3: 部门面试官 | H3: 面试结果 | I3: 预计到岗时间 | J3: 实际到岗时间 | K3: 人数 | L3: 稳岗情况（在岗） | M3: 稳岗情况（离职） | N3: 备注 | O3: 备注 | Q3: 姓名 | R3: 5月岗位需求 | S3: 5月招聘到岗数 | T3: 招聘提成 | U3: 提成金额 | V3: 分配 | W3: 提成金额
B4: 2026.5.10 | C4: 吉利超市 | D4: 续保专员 | E4: 刘尧梅 | G4: 黄意轩 | H4: 建议试用 | Q4: 周小红 | U4: =S4*T4 -> 0 | W4: =$U$4*V4 -> 0
B5: 2026.5.10 | C5: 吉利超市 | D5: 续保专员 | E5: 冯桢 | G5: 黄意轩 | H5: 建议试用 | Q5: 何婷婷 | W5: =$U$4*V5 -> 0
B6: 2026.4.26 | C6: 西物星瑞 | D6: 展厅顾问 | E6: 梁泽煦 | G6: 安洋 | H6: 建议试用 | Q6: 李玲 | W6: =$U$4*V6 -> 0
B7: 2026.5.19 | C7: 成都健行 | D7: 会计助理 | E7: 刘文清 | G7: 刘靖 | H7: 建议试用 | Q7: 刘晓琴 | W7: =$U$4*V7 -> 0
B8: 2026.5.10 | C8: 成都极客 | D8: 机电技师 | E8: 张健涛 | G8: 徐炳涛 | H8: 建议试用 | Q8: 岗位需求 | R8: 需求 | S8: 到岗 | T8: 离职
B9: 2026.5.6 | C9: 成都极客 | D9: 机电技师 | E9: 易佳乐 | F9: 15328215121 | G9: 徐炳涛 | H9: 建议试用 | P9: 武侯售后 | Q9: 续保 | U9: 现有岗位转郫都店补编
B10: 2026.4.30 | C10: 西物精锐 | D10: 展厅顾问 | E10: 张京川 | G10: 刘虹呈 | H10: 建议试用 | P10: 武侯售后 | Q10: 事故接待
B11: 2026.5.1 | C11: 成都健行 | D11: 会计助理 | E11: 淳厚舒 | G11: 刘靖 | H11: 建议试用 | P11: 武侯售后 | Q11: 机电技师
B12: 2026.4.30 | C12: 吉利超市 | D12: 续保专员 | E12: 孙茂梅 | G12: 黄意轩 | H12: 建议试用 | P12: 武侯售后 | Q12: PDI
B13: 2026.5.1 | C13: 吉利超市 | D13: 续保专员 | E13: 王丹 | G13: 黄意轩 | H13: 建议试用 | P13: 超市银河 | Q13: 销售顾问
B14: 2026.5.1 | C14: 成都极客 | D14: 机电技师 | E14: 魏世玉 | G14: 徐炳涛 | H14: 建议试用 | P14: 西物汽车 | Q14: 销售顾问
P15: 西物银河 | Q15: 汽车销售
P16: 西物精锐 | Q16: 汽车销售
P17: 西物精锐 | Q17: 邀约专员
P18: 市场中心 | Q18: 企划
P19: 机场售后 | Q19: 机电技工
P20: 机场售后 | Q20: 服务顾问
P21: 极客 | Q21: 维修技师
P22: 新媒体 | Q22: 主播
P23: 超市 | Q23: 邀约专员
P24: 直营店 | Q24: 销售顾问 | T24: =SUM(T9:T23) -> 0 | U24: =SUM(U9:U23) -> 0 | V24: =SUM(V9:V23) -> 0 | W24: =SUM(W9:W23) -> 0
P25: 西物银河 | Q25: 邀约专员 | T25: =SUM(T9:T24) -> 0
P26: 机场售后 | Q26: 事故接待
P27: 超市吉星 | Q27: 销售顾问 | T27: =SUM(T9:T26) -> 0 | U27: =SUM(U9:U26) -> 0 | V27: =SUM(V9:V26) -> 0 | W27: =SUM(W9:W26) -> 0
P28: 超市吉星 | Q28: 客户专员
P29: 西物星瑞 | Q29: 客户专员
P30: 西物星瑞 | Q30: 销售顾问
P31: 西物星瑞 | Q31: 会计
P32: 西物星瑞 | Q32: 试驾专员
P33: 西物精锐 | Q33: 试驾专员
K34: =SUM(K4:K33) -> 0 | L34: =SUM(L4:L33) -> 0 | M34: =SUM(M4:M33) -> 0 | P34: 健行 | Q34: 会计
M35: =SUM(M4:M34) -> 0 | P35: 西物极客 | Q35: 服务顾问
P36: 西物极客 | Q36: 机电
P37: 健行 | Q37: 销售顾问
R38: =SUM(R9:R37) -> 0 | S38: =SUBTOTAL(9,S9:S37) -> 0

Sheet 综合表
AG1: 武侯店 | AH1: 销售顾问 | AI1: 盈利性产品 | AL1: 渗透率考核 | AO1: 培训考核 | AQ1: 备注
AI2: 任务目标 | AJ2: 完成情况 | AK2: 考核 | AL2: 渗透率 | AM2: 盈利性占比 | AN2: 盈利性产品考核 | AO2: 考试成绩 | AP2: 绩效标准 | AQ2: 实习员工不作考核
A3: 04月 | AG3: 展厅 | AH3: 马攀 | AK3: =IF((AJ3-AI3)>=0,0,IF(AJ3=1,-200,-400)) -> 0 | AN3: =IF(AL3>=0.67,1.1,IF(AL3>=0.6,1,IF(AL3>=0.45,0.9,0.8))) -> 0.8 | AR3: =INDEX(B:B,MATCH(AH3,B:B,0)) -> #N/A
A4: 序号 | B4: 姓名 | C4: 保险及实习员工 | D4: 考核 | E4: 吉致长期考核+培训考核 | F4: 管理考核及特殊车型考核 | G4: 直营店店总盈利性产品考核 | H4: 其它 | I4: 其它 | J4: 安心保(已发并税）+重功+订单+上门服务+转介绍 | L4: 绩效考核进入工资 | AH4: 易花贞子 | AK4: =IF((AJ4-AI4)>=0,0,IF(AJ4=1,-200,-400)) -> 0 | AN4: =IF(AL4>=0.67,1.1,IF(AL4>=0.6,1,IF(AL4>=0.45,0.9,0.8))) -> 0.8 | AR4: =INDEX(B:B,MATCH(AH4,B:B,0)) -> #N/A | BG4: 张永强绩效
E5: =SUMIF(AH:AH,B5,AK:AK) -> 0 | L5: =SUM(C5:K5)-SUM(J5:K5) -> 0 | N5: =INDEX(AK:AK,MATCH(B5,AH:AH,0))-E5 -> #N/A | AH5: 毛春秀 | AK5: =IF((AJ5-AI5)>=0,0,IF(AJ5=1,-200,-400)) -> 0 | AN5: =IF(AL5>=0.67,1.1,IF(AL5>=0.6,1,IF(AL5>=0.45,0.9,0.8))) -> 0.8 | AR5: =INDEX(B:B,MATCH(AH5,B:B,0)) -> #N/A | BH5: 燃油车销量 | BI5: 新能源销量
E6: =SUMIF(AH:AH,B6,AK:AK) -> 0 | L6: =SUM(C6:K6)-SUM(J6:K6) -> 0 | N6: =INDEX(AK:AK,MATCH(B6,AH:AH,0))-E6 -> #N/A | AH6: 廖晓军 | AK6: =IF((AJ6-AI6)>=0,0,IF(AJ6=1,-200,-400)) -> 0 | AN6: =IF(AL6>=0.67,1.1,IF(AL6>=0.6,1,IF(AL6>=0.45,0.9,0.8))) -> 0.8 | AR6: =INDEX(B:B,MATCH(AH6,B:B,0)) -> #N/A | BG6: 大邑直营店
E7: =SUMIF(AH:AH,B7,AK:AK) -> 0 | L7: =SUM(C7:K7)-SUM(J7:K7) -> 0 | N7: =INDEX(AK:AK,MATCH(B7,AH:AH,0))-E7 -> #N/A | AH7: 康鳞波 | AK7: =IF((AJ7-AI7)>=0,0,IF(AJ7=1,-200,-400)) -> 0 | AN7: =IF(AL7>=0.67,1.1,IF(AL7>=0.6,1,IF(AL7>=0.45,0.9,0.8))) -> 0.8 | AR7: =INDEX(B:B,MATCH(AH7,B:B,0)) -> #N/A | BG7: 华阳直营店
E8: =SUMIF(AH:AH,B8,AK:AK) -> 0 | L8: =SUM(C8:K8)-SUM(J8:K8) -> 0 | N8: =INDEX(AK:AK,MATCH(B8,AH:AH,0))-E8 -> #N/A | AH8: 代力 | AK8: =IF((AJ8-AI8)>=0,0,IF(AJ8=1,-200,-400)) -> 0 | AN8: =IF(AL8>=0.67,1.1,IF(AL8>=0.6,1,IF(AL8>=0.45,0.9,0.8))) -> 0.8 | AR8: =INDEX(B:B,MATCH(AH8,B:B,0)) -> #N/A | BG8: 崇州直营店
E9: =SUMIF(AH:AH,B9,AK:AK) -> 0 | L9: =SUM(C9:K9)-SUM(J9:K9) -> 0 | N9: =INDEX(AK:AK,MATCH(B9,AH:AH,0))-E9 -> #N/A | AH9: 熊杰文 | AK9: =IF((AJ9-AI9)>=0,0,IF(AJ9=1,-200,-400)) -> 0 | AN9: =IF(AL9>=0.67,1.1,IF(AL9>=0.6,1,IF(AL9>=0.45,0.9,0.8))) -> 0.8 | AR9: =INDEX(B:B,MATCH(AH9,B:B,0)) -> #N/A | AT9: 2026年04吉利超市售后吧台提成工资明细表 | BG9: 邛崃直营店
E10: =SUMIF(AH:AH,B10,AK:AK) -> 0 | L10: =SUM(C10:K10)-SUM(J10:K10) -> 0 | N10: =INDEX(AK:AK,MATCH(B10,AH:AH,0))-E10 -> #N/A | R10: 2021年4月起市场部薪酬 | V10: 05月绩效核算 | AH10: 黄利君 | AK10: =IF((AJ10-AI10)>=0,0,IF(AJ10=1,-200,-400)) -> 0 | AN10: =IF(AL10>=0.67,1.1,IF(AL10>=0.6,1,IF(AL10>=0.45,0.9,0.8))) -> 0.8 | AR10: =INDEX(B:B,MATCH(AH10,B:B,0)) -> #N/A | AS10: 人数 | AT10: 04月吧台月均营业额 | AU10: 系数 | AV10: 提成金额 | AW10: 2026年04月售后台次 | AX10: 单台比例 | AY10: 提成金额 | AZ10: 固定绩效 | BA10: 考核+其它 | BB10: 分配比例 | BC10: 浮动绩效分配金额 | BD10: 月度薪资合计 | BE10: 出勤天数 | BG10: 彭州直营店
E11: =SUMIF(AH:AH,B11,AK:AK) -> 0 | L11: =SUM(C11:K11)-SUM(J11:K11) -> 0 | N11: =INDEX(AK:AK,MATCH(B11,AH:AH,0))-E11 -> #N/A | P11: 员工 | Q11: 岗位 | R11: 基本工资 | S11: 加班工资 | T11: 考核绩效 | U11: 单台标准 | V11: 提成金额 | W11: 考核绩效 | X11: 销量绩效 | Y11: 其它 | Z11: 绩效总额 | AA11: 当月薪酬总额 | AB11: 人力归属 | AC11: 备注 | AR11: =INDEX(B:B,MATCH(AH11,B:B,0)) -> #N/A | AS11: 白影 | AV11: =AU11*AT11 -> 0 | AY11: =AW11*AX11 -> 0 | BC11: =($AV$11+$AY$11)*BB11 -> 0 | BG11: 新都直营店
E12: =SUMIF(AH:AH,B12,AK:AK) -> 0 | L12: =SUM(C12:K12)-SUM(J12:K12) -> 0 | N12: =INDEX(AK:AK,MATCH(B12,AH:AH,0))-E12 -> #N/A | P12: 谭艳 | Q12: 企划经理 | Z12: =SUM(W12:Y12) -> 0 | AA12: =Z12+R12+S12 -> 0 | AB12: 西物 | AR12: =INDEX(B:B,MATCH(AH12,B:B,0)) -> #N/A | AS12: 曹青 | BC12: =($AV$11+$AY$11)*BB12 -> 0 | BG12: 金堂直营店
E13: =SUMIF(AH:AH,B13,AK:AK) -> 0 | L13: =SUM(C13:K13)-SUM(J13:K13) -> 0 | N13: =INDEX(AK:AK,MATCH(B13,AH:AH,0))-E13 -> #N/A | P13: 孙舒琪 | Q13: 设计专员 | X13: =V13*U13 -> 0 | Z13: =SUM(W13:Y13) -> 0 | AA13: =Z13+R13+S13 -> 0 | AB13: 明睿 | AR13: =INDEX(B:B,MATCH(AH13,B:B,0)) -> #N/A | AS13: 朱开莲 | BC13: =($AV$11+$AY$11)*BB13 -> 0 | BG13: 合计 | BH13: =SUM(BH6:BH12) -> 0 | BI13: =SUM(BI6:BI12) -> 0
E14: =SUMIF(AH:AH,B14,AK:AK) -> 0 | L14: =SUM(C14:K14)-SUM(J14:K14) -> 0 | N14: =INDEX(AK:AK,MATCH(B14,AH:AH,0))-E14 -> #N/A | AR14: =INDEX(B:B,MATCH(AH14,B:B,0)) -> #N/A | AS14: 谢槟羽 | BC14: =($AV$11+$AY$11)*BB14 -> 0
E15: =SUMIF(AH:AH,B15,AK:AK) -> 0 | L15: =SUM(C15:K15)-SUM(J15:K15) -> 0 | N15: =INDEX(AK:AK,MATCH(B15,AH:AH,0))-E15 -> #N/A | P15: 黄思露 | Q15: 核销专员 | X15: =V15*U15 -> 0 | Z15: =SUM(W15:Y15) -> 0 | AA15: =Z15+R15+S15 -> 0 | AB15: 豪明 | AH15: 小计 | AI15: =SUM(AI3:AI14) -> 0 | AJ15: =SUM(AJ3:AJ14) -> 0 | AK15: =SUM(AK3:AK14) -> 0 | AN15: - | AO15: =SUM(AO3:AO14)/13 -> 0 | AP15: - | AR15: =INDEX(B:B,MATCH(AH15,B:B,0)) -> #N/A | AS15: 陶纯玲 | BC15: =($AV$11+$AY$11)*BB15 -> 0
E16: =SUMIF(AH:AH,B16,AK:AK) -> 0 | L16: =SUM(C16:K16)-SUM(J16:K16) -> 0 | N16: =INDEX(AK:AK,MATCH(B16,AH:AH,0))-E16 -> #N/A | P16: 赵若贝 | Q16: 设计专员 | X16: =V16*U16 -> 0 | Z16: =SUM(W16:Y16) -> 0 | AA16: =Z16+R16+S16 -> 0 | AB16: 超市 | AG16: 网销 | AH16: 母勇 | AK16: =IF((AJ16-AI16)>=0,0,IF(AJ16=1,-200,-400)) -> 0 | AN16: =IF(AL16>=0.67,1.1,IF(AL16>=0.6,1,IF(AL16>=0.45,0.9,0.8))) -> 0.8 | AR16: =INDEX(B:B,MATCH(AH16,B:B,0)) -> #N/A
E17: =SUMIF(AH:AH,B17,AK:AK) -> 0 | L17: =SUM(C17:K17)-SUM(J17:K17) -> 0 | N17: =INDEX(AK:AK,MATCH(B17,AH:AH,0))-E17 -> #N/A | P17: 杨兰 | Q17: 企划专员 | X17: =V17*U17 -> 0 | Z17: =SUM(W17:Y17) -> 0 | AA17: =Z17+R17+S17 -> 0 | AB17: 超市 | AH17: 蒲喜 | AK17: =IF((AJ17-AI17)>=0,0,IF(AJ17=1,-200,-400)) -> 0 | AN17: =IF(AL17>=0.67,1.1,IF(AL17>=0.6,1,IF(AL17>=0.45,0.9,0.8))) -> 0.8 | AR17: =INDEX(B:B,MATCH(AH17,B:B,0)) -> #N/A | AS17: 合计 | AT17: =SUM(AT11:AT16) -> 0 | AU17: =SUM(AU11:AU16) -> 0 | AV17: =SUM(AV11:AV16) -> 0 | AW17: =SUM(AW11:AW16) -> 0 | AX17: =SUM(AX11:AX16) -> 0 | AY17: =SUM(AY11:AY16) -> 0 | AZ17: =SUM(AZ11:AZ16) -> 0 | BA17: =SUM(BA11:BA16) -> 0 | ... BE17: =SUM(BE11:BE16) -> 0 | BJ17: =BH17/BI17 -> #DIV/0!
E18: =SUMIF(AH:AH,B18,AK:AK) -> 0 | L18: =SUM(C18:K18)-SUM(J18:K18) -> 0 | N18: =INDEX(AK:AK,MATCH(B18,AH:AH,0))-E18 -> #N/A | P18: 史浩栋 | Q18: 设计专员 | X18: =V18*U18 -> 0 | Z18: =SUM(W18:Y18) -> 0 | AA18: =Z18+R18+S18 -> 0 | AB18: 豪明 | AC18: 9月晋升主管 | AH18: 何伟 | AK18: =IF((AJ18-AI18)>=0,0,IF(AJ18=1,-200,-400)) -> 0 | AN18: =IF(AL18>=0.67,1.1,IF(AL18>=0.6,1,IF(AL18>=0.45,0.9,0.8))) -> 0.8 | AR18: =INDEX(B:B,MATCH(AH18,B:B,0)) -> #N/A | BJ18: =BH18/BI18 -> #DIV/0!
E19: =SUMIF(AH:AH,B19,AK:AK) -> 0 | L19: =SUM(C19:K19)-SUM(J19:K19) -> 0 | N19: =INDEX(AK:AK,MATCH(B19,AH:AH,0))-E19 -> #N/A | P19: 孙小慧 | Q19: 核销专员 | X19: =V19*U19 -> 0 | Z19: =SUM(W19:Y19) -> 0 | AA19: =Z19+R19+S19 -> 0 | AB19: 明睿 | AC19: 9月晋升主管 | AH19: 何宇 | AK19: =IF((AJ19-AI19)>=0,0,IF(AJ19=1,-200,-400)) -> 0 | AN19: =IF(AL19>=0.67,1.1,IF(AL19>=0.6,1,IF(AL19>=0.45,0.9,0.8))) -> 0.8 | AR19: =INDEX(B:B,MATCH(AH19,B:B,0)) -> #N/A | BH19: 基础工资 | BI19: 加班工资 | BJ19: 考核绩效 | BK19: 业绩绩效 | BL19: 月均 | BM19: 单台奖
E20: =SUMIF(AH:AH,B20,AK:AK) -> 0 | L20: =SUM(C20:K20)-SUM(J20:K20) -> 0 | N20: =INDEX(AK:AK,MATCH(B20,AH:AH,0))-E20 -> #N/A | P20: 陈子茜 | Q20: 核销专员 | Z20: =SUM(W20:Y20) -> 0 | AA20: =Z20+R20+S20 -> 0 | AB20: 星瑞 | AH20: 唐操 | AK20: =IF((AJ20-AI20)>=0,0,IF(AJ20=1,-200,-400)) -> 0 | AN20: =IF(AL20>=0.67,1.1,IF(AL20>=0.6,1,IF(AL20>=0.45,0.9,0.8))) -> 0.8 | AR20: =INDEX(B:B,MATCH(AH20,B:B,0)) -> #N/A | BN20: =BK20/BL20 -> #DIV/0!
E21: =SUMIF(AH:AH,B21,AK:AK) -> 0 | L21: =SUM(C21:K21)-SUM(J21:K21) -> 0 | N21: =INDEX(AK:AK,MATCH(B21,AH:AH,0))-E21 -> #N/A | P21: 李中婷 | Q21: 设计专员 | Z21: =SUM(W21:Y21) -> 0 | AA21: =Z21+R21+S21 -> 0 | AB21: 明睿银河 | AH21: 刘飞 | AK21: =IF((AJ21-AI21)>=0,0,IF(AJ21=1,-200,-400)) -> 0 | AN21: =IF(AL21>=0.67,1.1,IF(AL21>=0.6,1,IF(AL21>=0.45,0.9,0.8))) -> 0.8 | AR21: =INDEX(B:B,MATCH(AH21,B:B,0)) -> #N/A | BK21: =BJ18-BJ21-BI21-BH21 -> #DIV/0! | BN21: =BK21/BL21 -> #DIV/0!
E22: =SUMIF(AH:AH,B22,AK:AK) -> 0 | L22: =SUM(C22:K22)-SUM(J22:K22) -> 0 | N22: =INDEX(AK:AK,MATCH(B22,AH:AH,0))-E22 -> #N/A | Q22: 设计专员 | AB22: 西物银河 | AH22: 王泳文 | AK22: =IF((AJ22-AI22)>=0,0,IF(AJ22=1,-200,-400)) -> 0 | AN22: =IF(AL22>=0.67,1.1,IF(AL22>=0.6,1,IF(AL22>=0.45,0.9,0.8))) -> 0.8 | AR22: =INDEX(B:B,MATCH(AH22,B:B,0)) -> #N/A | BK22: =BL21*13 -> 0 | BL22: =BH22+BI22+BJ22+BK22 -> 0 | BM22: =290*12*2 -> 6960 | BN22: =BL22*12 -> 0 | BO22: =BM22+BN22 -> 6960
E23: =SUMIF(AH:AH,B23,AK:AK) -> 0 | L23: =SUM(C23:K23)-SUM(J23:K23) -> 0 | N23: =INDEX(AK:AK,MATCH(B23,AH:AH,0))-E23 -> #N/A | P23: 蔡利君 | Q23: 企划专员 | W23: =T23 -> 0 | X23: =V23*U23 -> 0 | Z23: =SUM(W23:Y23) -> 0 | AA23: =Z23+R23+S23 -> 0 | AB23: 慧民 | AC23: 1月29日入职 | AH23: 雷卓远 | AK23: =IF((AJ23-AI23)>=0,0,IF(AJ23=1,-200,-400)) -> 0 | AN23: =IF(AL23>=0.67,1.1,IF(AL23>=0.6,1,IF(AL23>=0.45,0.9,0.8))) -> 0.8 | AR23: =INDEX(B:B,MATCH(AH23,B:B,0)) -> #N/A | BG23: 4000/考核 | BH23: 场次目标量 | BI23: 内训效果 | BJ23: 内训总结 | BK23: 总经理自调项目 | BL23: 合计 | BM23: 绩效 | BN23: 销量绩效
E24: =SUMIF(AH:AH,B24,AK:AK) -> 0 | L24: =SUM(C24:K24)-SUM(J24:K24) -> 0 | N24: =INDEX(AK:AK,MATCH(B24,AH:AH,0))-E24 -> #N/A | AH24: 何剑 | AK24: =IF((AJ24-AI24)>=0,0,IF(AJ24=1,-200,-400)) -> 0 | AN24: =IF(AL24>=0.67,1.1,IF(AL24>=0.6,1,IF(AL24>=0.45,0.9,0.8))) -> 0.8 | AR24: =INDEX(B:B,MATCH(AH24,B:B,0)) -> #N/A | BG24: 考核权重
E25: =SUMIF(AH:AH,B25,AK:AK) -> 0 | L25: =SUM(C25:K25)-SUM(J25:K25) -> 0 | N25: =INDEX(AK:AK,MATCH(B25,AH:AH,0))-E25 -> #N/A | AR25: =INDEX(B:B,MATCH(AH25,B:B,0)) -> #N/A | AS25: 合计 | BG25: 考核标准 | BH25: 按达成率 | BI25: 按达成率 | BJ25: 按达成率 | BK25: 按达成率 | BL25: 按达成率 | BM25: 按达成率 | BN25: 台次
E26: =SUMIF(AH:AH,B26,AK:AK) -> 0 | L26: =SUM(C26:K26)-SUM(J26:K26) -> 0 | N26: =INDEX(AK:AK,MATCH(B26,AH:AH,0))-E26 -> #N/A | AR26: =INDEX(B:B,MATCH(AH26,B:B,0)) -> #N/A | BG26: 目标 （《月度经营设线目标》） | BL26: / | BM26: / | BN26: /
E27: =SUMIF(AH:AH,B27,AK:AK) -> 0 | L27: =SUM(C27:K27)-SUM(J27:K27) -> 0 | N27: =INDEX(AK:AK,MATCH(B27,AH:AH,0))-E27 -> #N/A | AH27: 小计 | AI27: =SUM(AI16:AI26) -> 0 | AJ27: =SUM(AJ16:AJ26) -> 0 | AK27: =SUM(AK16:AK23) -> 0 | AN27: - | AO27: =SUM(AO16:AO24)/11 -> 0 | AP27: - | AR27: =INDEX(B:B,MATCH(AH27,B:B,0)) -> #N/A | BG27: 实绩 （当月实际达成） | BL27: / | BM27: / | BN27: /
E28: =SUMIF(AH:AH,B28,AK:AK) -> 0 | L28: =SUM(C28:K28)-SUM(J28:K28) -> 0 | N28: =INDEX(AK:AK,MATCH(B28,AH:AH,0))-E28 -> #N/A | AG28: 武侯店合计 | AI28: =AI15+AI27 -> 0 | AJ28: =AJ15+AJ27 -> 0 | AK28: =AK15+AK27 -> 0 | AL28: - | AO28: =(SUM(AO3:AO14)+SUM(AO16:AO24))/24 -> 0 | AP28: - | AR28: =INDEX(B:B,MATCH(AH28,B:B,0)) -> #N/A | BG28: 达成率 （实绩/目标，参考考核标准） | BH28: =IF(BH27>0,BH27/BH26,0) -> 0 | BI28: =IF(BI27>0,BI27/BI26,0) -> 0 | BJ28: =IF(BJ27>0,BJ27/BJ26,0) -> 0 | BK28: =IF(BK27>0,BK27/BK26,0) -> 0 | BL28: / | BM28: /
E29: =SUMIF(AH:AH,B29,AK:AK) -> 0 | L29: =SUM(C29:K29)-SUM(J29:K29) -> 0 | N29: =INDEX(AK:AK,MATCH(B29,AH:AH,0))-E29 -> #N/A | AR29: =INDEX(B:B,MATCH(AH29,B:B,0)) -> #N/A | BG29: 考核得分 （考核分值*达成率） | BH29: =IF(BH28>=100%,BH24*100%,BH24*BH28) -> 0 | BI29: =IF(BI28>=100%,BI24*100%,BI24*BI28) -> 0 | BJ29: =IF(BJ28>=100%,BJ24*100%,BJ24*BJ28) -> 0 | BK29: =IF(BK28>=100%,BK24*100%,BK24*BK28) -> 0 | BL29: =SUM(BH29:BK29) -> 0 | BM29: =BM24*BL29 -> 0 | BN29: =BN28*BN24 -> 0
E30: =SUMIF(AH:AH,B30,AK:AK) -> 0 | L30: =SUM(C30:K30)-SUM(J30:K30) -> 0 | N30: =INDEX(AK:AK,MATCH(B30,AH:AH,0))-E30 -> #N/A | AG30: 机场店 | AH30: 销售顾问 | AI30: 盈利性产品 | AL30: 渗透率考核 | AO30: 培训考核 | AR30: =INDEX(B:B,MATCH(AH30,B:B,0)) -> #N/A
E31: =SUMIF(AH:AH,B31,AK:AK) -> 0 | L31: =SUM(C31:K31)-SUM(J31:K31) -> 0 | N31: =INDEX(AK:AK,MATCH(B31,AH:AH,0))-E31 -> #N/A | AI31: 任务目标 | AJ31: 完成情况 | AK31: 考核 | AL31: 渗透率 | AM31: 盈利性占比 | AN31: 盈利性产品考核 | AO31: 考试成绩 | AP31: 绩效标准 | AR31: =INDEX(B:B,MATCH(AH31,B:B,0)) -> #N/A
E32: =SUMIF(AH:AH,B32,AK:AK) -> 0 | L32: =SUM(C32:K32)-SUM(J32:K32) -> 0 | N32: =INDEX(AK:AK,MATCH(B32,AH:AH,0))-E32 -> #N/A | AG32: 展厅 | AH32: 邓戈 | AK32: =IF((AJ32-AI32)>=0,0,IF(AJ32=1,-200,-400)) -> 0 | AN32: =IF(AL32>=0.67,1.1,IF(AL32>=0.6,1,IF(AL32>=0.45,0.9,0.8))) -> 0.8 | AR32: =INDEX(B:B,MATCH(AH32,B:B,0)) -> #N/A
E33: =SUMIF(AH:AH,B33,AK:AK) -> 0 | L33: =SUM(C33:K33)-SUM(J33:K33) -> 0 | N33: =INDEX(AK:AK,MATCH(B33,AH:AH,0))-E33 -> #N/A | AH33: 刘发 | AK33: =IF((AJ33-AI33)>=0,0,IF(AJ33=1,-200,-400)) -> 0 | AN33: =IF(AL33>=0.67,1.1,IF(AL33>=0.6,1,IF(AL33>=0.45,0.9,0.8))) -> 0.8 | AR33: =INDEX(B:B,MATCH(AH33,B:B,0)) -> #N/A
E34: =SUMIF(AH:AH,B34,AK:AK) -> 0 | L34: =SUM(C34:K34)-SUM(J34:K34) -> 0 | N34: =INDEX(AK:AK,MATCH(B34,AH:AH,0))-E34 -> #N/A | AH34: 黄军 | AK34: =IF((AJ34-AI34)>=0,0,IF(AJ34=1,-200,-400)) -> 0 | AN34: =IF(AL34>=0.67,1.1,IF(AL34>=0.6,1,IF(AL34>=0.45,0.9,0.8))) -> 0.8 | AR34: =INDEX(B:B,MATCH(AH34,B:B,0)) -> #N/A
E35: =SUMIF(AH:AH,B35,AK:AK) -> 0 | L35: =SUM(C35:K35)-SUM(J35:K35) -> 0 | N35: =INDEX(AK:AK,MATCH(B35,AH:AH,0))-E35 -> #N/A | AH35: 姚元利 | AK35: =IF((AJ35-AI35)>=0,0,IF(AJ35=1,-200,-400)) -> 0 | AN35: =IF(AL35>=0.67,1.1,IF(AL35>=0.6,1,IF(AL35>=0.45,0.9,0.8))) -> 0.8 | AR35: =INDEX(B:B,MATCH(AH35,B:B,0)) -> #N/A
E36: =SUMIF(AH:AH,B36,AK:AK) -> 0 | L36: =SUM(C36:K36)-SUM(J36:K36) -> 0 | N36: =INDEX(AK:AK,MATCH(B36,AH:AH,0))-E36 -> #N/A | AH36: 陈林 | AK36: =IF((AJ36-AI36)>=0,0,IF(AJ36=1,-200,-400)) -> 0 | AN36: =IF(AL36>=0.67,1.1,IF(AL36>=0.6,1,IF(AL36>=0.45,0.9,0.8))) -> 0.8 | AR36: =INDEX(B:B,MATCH(AH36,B:B,0)) -> #N/A
E37: =SUMIF(AH:AH,B37,AK:AK) -> 0 | L37: =SUM(C37:K37)-SUM(J37:K37) -> 0 | N37: =INDEX(AK:AK,MATCH(B37,AH:AH,0))-E37 -> #N/A | AH37: 冯超 | AK37: =IF((AJ37-AI37)>=0,0,IF(AJ37=1,-200,-400)) -> 0 | AN37: =IF(AL37>=0.67,1.1,IF(AL37>=0.6,1,IF(AL37>=0.45,0.9,0.8))) -> 0.8 | AR37: =INDEX(B:B,MATCH(AH37,B:B,0)) -> #N/A
E38: =SUMIF(AH:AH,B38,AK:AK) -> 0 | L38: =SUM(C38:K38)-SUM(J38:K38) -> 0 | N38: =INDEX(AK:AK,MATCH(B38,AH:AH,0))-E38 -> #N/A | AR38: =INDEX(B:B,MATCH(AH38,B:B,0)) -> #N/A
E39: =SUMIF(AH:AH,B39,AK:AK) -> 0 | L39: =SUM(C39:K39)-SUM(J39:K39) -> 0 | N39: =INDEX(AK:AK,MATCH(B39,AH:AH,0))-E39 -> #N/A | AR39: =INDEX(B:B,MATCH(AH39,B:B,0)) -> #N/A
E40: =SUMIF(AH:AH,B40,AK:AK) -> 0 | L40: =SUM(C40:K40)-SUM(J40:K40) -> 0 | N40: =INDEX(AK:AK,MATCH(B40,AH:AH,0))-E40 -> #N/A | AR40: =INDEX(B:B,MATCH(AH40,B:B,0)) -> #N/A
...

Sheet 重功超期+活动
P1: 3月团购活动任务（活动周期3.7-3.15）
A2: 归属公司 | B2: 车种 | C2: 采购日期 | D2: 颜色 | E2: VIN号 | F2: 统一零售价 | G2: 库龄 | H2: 区域 | I2: 库别 | J2: 装饰情况 | K2: 物流补偿 | L2: 质损降价 | M2: 销售追加奖励 | N2: =M2 -> 销售追加奖励 | Z2: =COUNTIF(Q:Q,Q2) -> 0 | AA2: 500/台 | AB2: 200≥2 台 | AC2: 100≥2 台 | AF2: 500/台 | AG2: 200≥2 台 | AH2: 100≥2 台
A3: 西物明睿 | B3: 星瑞 | C3: 2026-01-05 | D3: 紫 | E3: L6T7954Z2TD009890 | H3: 自有店 | I3: 电子厂库房 | J3: 前保险杠下部装饰条更换，需告知客户，降价1000 | N3: =M3 -> 0 | O3: 眉山销售 | P3: 部门 | Q3: 人员 | R3: 24号 | S3: 25号 | T3: 26号 | U3: 奖励明细 | V3: 重攻考核 | W3: 合计实发 | X3: 合计实发 | Z3: =COUNTIF(Q:Q,Q3) -> 3 | AA3: 奖励明细 | AB3: 奖励明细 | AC3: 奖励明细 | AD3: 合计实发 | AF3: 奖励明细 | AG3: 奖励明细 | AH3: 奖励明细 | AI3: 合计实发
A4: 西物明睿 | B4: 博越REV | C4: 2026-03-19 | D4: 白 | E4: L6T78XCZ2TY781363 | H4: 自有店 | I4: 网销 | J4: 天窗损坏跟换 | N4: =M4 -> 0 | X4: =SUM(U4:W4) -> 0 | Z4: =COUNTIF(Q:Q,Q4) -> 0 | AD4: =SUM(AA4:AC4) -> 0 | AF4: =SUMIFS(O:O,I:I,'重功超期+活动'!Q4,B:B,"豪越L") -> 0 | AG4: =SUMIFS(O:O,I:I,'重功超期+活动'!Q4,B:B,"第4代帝豪") -> 0 | AH4: =SUMIFS(O:O,I:I,'重功超期+活动'!Q4,B:B,"第5代帝豪") -> 0 | AI4: =SUM(AF4:AH4) -> 0
A5: 成都西物 | B5: 博越L | C5: 2026-02-25 | D5: 黑 | E5: LB37822Z0TB034100 | H5: 自有店 | I5: 西部智谷A区 | J5: 发动机下护板被猫抓坏-保险承担降价金额请示总经理 | N5: =M5 -> 0 | X5: =SUM(U5:W5) -> 0 | Z5: =COUNTIF(Q:Q,Q5) -> 0 | AD5: =SUM(AA5:AC5) -> 0 | AF5: =SUMIFS(O:O,I:I,'重功超期+活动'!Q5,B:B,"豪越L") -> 0 | AG5: =SUMIFS(O:O,I:I,'重功超期+活动'!Q5,B:B,"第4代帝豪") -> 0 | AH5: =SUMIFS(O:O,I:I,'重功超期+活动'!Q5,B:B,"第5代帝豪") -> 0 | AI5: =SUM(AF5:AH5) -> 0
A6: 成都西物 | B6: 豪越L | C6: 2026-03-03 | D6: 白 | E6: L6T7922Z0TY871189 | H6: 自有店 | I6: 电子营销 | J6: 更换贯穿式背门灯-需告知客户-具体降价补偿销售时请示总经理 | N6: =M6 -> 0 | X6: =SUM(U6:W6) -> 0 | Z6: =COUNTIF(Q:Q,Q6) -> 0 | AD6: =SUM(AA6:AC6) -> 0 | AF6: =SUMIFS(O:O,I:I,'重功超期+活动'!Q6,B:B,"豪越L") -> 0 | AG6: =SUMIFS(O:O,I:I,'重功超期+活动'!Q6,B:B,"第4代帝豪") -> 0 | AH6: =SUMIFS(O:O,I:I,'重功超期+活动'!Q6,B:B,"第5代帝豪") -> 0 | AI6: =SUM(AF6:AH6) -> 0
A7: 成都西物 | B7: 博越L | C7: 2026-03-19 | D7: 银 | E7: LB37822Z6TB045859 | H7: 自有店 | I7: 西部智谷B区 | J7: 车底挡板被猫抓坏待处理 | N7: =M7 -> 0 | X7: =SUM(U7:W7) -> 0 | Z7: =COUNTIF(Q:Q,Q7) -> 0 | AD7: =SUM(AA7:AC7) -> 0 | AF7: =SUMIFS(O:O,I:I,'重功超期+活动'!Q7,B:B,"豪越L") -> 0 | AG7: =SUMIFS(O:O,I:I,'重功超期+活动'!Q7,B:B,"第4代帝豪") -> 0 | AH7: =SUMIFS(O:O,I:I,'重功超期+活动'!Q7,B:B,"第5代帝豪") -> 0 | AI7: =SUM(AF7:AH7) -> 0
A8: 成都西物 | B8: 缤越L | C8: 2026-04-09 | D8: 白 | E8: LB37622Z8TX621220 | H8: 自有店 | I8: 售后维修 | J8: 更换右前右后门等装饰条及右后视镜总成-售后三包-告知客户降价金额待定 | N8: =M8 -> 0 | X8: =SUM(U8:W8) -> 0 | Z8: =COUNTIF(Q:Q,Q8) -> 0 | AD8: =SUM(AA8:AC8) -> 0 | AF8: =SUMIFS(O:O,I:I,'重功超期+活动'!Q8,B:B,"豪越L") -> 0 | AG8: =SUMIFS(O:O,I:I,'重功超期+活动'!Q8,B:B,"第4代帝豪") -> 0 | AH8: =SUMIFS(O:O,I:I,'重功超期+活动'!Q8,B:B,"第5代帝豪") -> 0 | AI8: =SUM(AF8:AH8) -> 0
A9: 成都西物 | B9: 缤越L | C9: 2026-04-09 | D9: 白 | E9: LB37622Z2TX621214 | H9: 自有店 | I9: 售后维修 | J9: 更换右前右后门等装饰条-售后三包-告知客户降价金额待定 | N9: =M9 -> 0 | X9: =SUM(U9:W9) -> 0 | Z9: =COUNTIF(Q:Q,Q9) -> 0 | AD9: =SUM(AA9:AC9) -> 0 | AF9: =SUMIFS(O:O,I:I,'重功超期+活动'!Q9,B:B,"豪越L") -> 0 | AG9: =SUMIFS(O:O,I:I,'重功超期+活动'!Q9,B:B,"第4代帝豪") -> 0 | AH9: =SUMIFS(O:O,I:I,'重功超期+活动'!Q9,B:B,"第5代帝豪") -> 0 | AI9: =SUM(AF9:AH9) -> 0
A10: 成都西物 | B10: 博越L | C10: 2026-03-19 | D10: 黑 | E10: LB37822Z6TB048261 | H10: 自有店 | I10: 售后 | J10: 底盘护板被抓坏，更换油钱轮眉，右前杠做漆待处理 | N10: =M10 -> 0 | X10: =SUM(U10:W10) -> 0 | Z10: =COUNTIF(Q:Q,Q10) -> 0 | AD10: =SUM(AA10:AC10) -> 0 | AF10: =SUMIFS(O:O,I:I,'重功超期+活动'!Q10,B:B,"豪越L") -> 0 | AG10: =SUMIFS(O:O,I:I,'重功超期+活动'!Q10,B:B,"第4代帝豪") -> 0 | AH10: =SUMIFS(O:O,I:I,'重功超期+活动'!Q10,B:B,"第5代帝豪") -> 0 | AI10: =SUM(AF10:AH10) -> 0
A11: 成都西物 | B11: 博越L | C11: 2026-01-20 | D11: 青 | E11: LB37822Z8TB021028 | H11: 自有店 | I11: 西部智谷C区 | J11: 右前杠右前叶子板被抓坏待保险处理 | N11: =M11 -> 0 | X11: =SUM(U11:W11) -> 0 | Z11: =COUNTIF(Q:Q,Q11) -> 0 | AD11: =SUM(AA11:AC11) -> 0 | AF11: =SUMIFS(O:O,I:I,'重功超期+活动'!Q11,B:B,"豪越L") -> 0 | AG11: =SUMIFS(O:O,I:I,'重功超期+活动'!Q11,B:B,"第4代帝豪") -> 0 | AH11: =SUMIFS(O:O,I:I,'重功超期+活动'!Q11,B:B,"第5代帝豪") -> 0 | AI11: =SUM(AF11:AH11) -> 0
A12: 成都西物 | B12: 博越L | C12: 2026-03-19 | D12: 银 | E12: LB37822Z9TB045144 | H12: 自有店 | I12: 售后 | J12: 车底挡板被猫抓坏待处理 | N12: =M12 -> 0 | X12: =SUM(U12:W12) -> 0 | Z12: =COUNTIF(Q:Q,Q12) -> 0 | AD12: =SUM(AA12:AC12) -> 0 | AF12: =SUMIFS(O:O,I:I,'重功超期+活动'!Q12,B:B,"豪越L") -> 0 | AG12: =SUMIFS(O:O,I:I,'重功超期+活动'!Q12,B:B,"第4代帝豪") -> 0 | AH12: =SUMIFS(O:O,I:I,'重功超期+活动'!Q12,B:B,"第5代帝豪") -> 0 | AI12: =SUM(AF12:AH12) -> 0
A13: 吉利超市 | B13: 星越L | C13: 2025-11-20 | D13: 白 | E13: LB37852Z0SS260105 | H13: 自有店 | I13: 华阳直营店 | J13: 右前轮轮毂轻微擦伤-华阳承担需要告知客户降价金额500元 | N13: =M13 -> 0 | X13: =SUM(U13:W13) -> 0 | Z13: =COUNTIF(Q:Q,Q13) -> 0 | AD13: =SUM(AB13:AC13) -> 0 | AI13: =SUM(AG13:AH13) -> 0
A14: 吉利超市 | B14: 缤越超能版 | C14: 2026-04-09 | D14: 白 | E14: LB37622Z0TX812503 | H14: 自有店 | I14: 售后维修 | J14: 更换右前B柱右后C柱右后门等装饰条-售后三包-告知客户降价金额待定 | N14: =M14 -> 0 | X14: =SUM(U14:W14) -> 0 | Z14: =COUNTIF(Q:Q,Q14) -> 0 | AD14: =SUM(AA14:AC14) -> 0 | AF14: =SUMIFS(O:O,I:I,'重功超期+活动'!Q14,B:B,"豪越L") -> 0 | AG14: =SUMIFS(O:O,I:I,'重功超期+活动'!Q14,B:B,"第4代帝豪") -> 0 | AH14: =SUMIFS(O:O,I:I,'重功超期+活动'!Q14,B:B,"第5代帝豪") -> 0 | AI14: =SUM(AF14:AH14) -> 0
A15: 吉利超市 | B15: 第5代帝豪 | C15: 2025-12-05 | D15: 蓝 | E15: LB37824Z4SG148390 | H15: 自有店 | I15: 机场展厅 | J15: 车顶划痕掉漆-公司承担告知客户降价金额800元 | N15: =M15 -> 0 | X15: =SUM(U15:W15) -> 0 | Z15: =COUNTIF(Q:Q,Q15) -> 0 | AD15: =SUM(AA15:AC15) -> 0 | AF15: =SUMIFS(O:O,I:I,'重功超期+活动'!Q15,B:B,"豪越L") -> 0 | AG15: =SUMIFS(O:O,I:I,'重功超期+活动'!Q15,B:B,"第4代帝豪") -> 0 | AH15: =SUMIFS(O:O,I:I,'重功超期+活动'!Q15,B:B,"第5代帝豪") -> 0 | AI15: =SUM(AF15:AH15) -> 0
