Workbook
Name aa: INDEX(#REF!,MATCH(#REF!,#REF!,0))
Name jiaocheliang: [6]销售明细!#REF!+[6]销售明细!#REF!+[6]销售明细!#REF!+[6]销售明细!#REF!+[6]销售明细!#REF!+[6]销售明细!#REF!+[6]销售明细!#REF!
Name Product1: #REF!
Name Product2: #REF!
Name Product3: #REF!
Name Product4: #REF!
Name Product5: #REF!
Name Product6: #REF!
Name Product7: #REF!
Name Product7: #REF!
Name Product7: #REF!
Name Product7: #REF!
Name Product7: #REF!
Name Product7: #REF!
Name Product8: #REF!
Name 灿谷: [7]数据有效性!#REF!
Name 灿谷: #REF!
Name 灿谷: [7]数据有效性!#REF!
Name 灿谷: [7]数据有效性!#REF!
Name 灿谷: [7]数据有效性!#REF!
Name 灿谷: #REF!
Name 车型: #REF!
Name 车型: #REF!
Name 车型: #REF!
Name 车型: #REF!
Name 车型: #REF!
Name 车型: [1]数据有效性!$T$3:$T$41
Name 车型颜色: #REF!
Name 车型颜色: #REF!
Name 车型颜色: #REF!
Name 车型颜色: #REF!
Name 车型颜色: #REF!
Name 车型颜色: '[2]0'!$Q$2:$Q$17
Name 成都健行: [8]数据有效性!$AE$3:$AE$10
Name 成都健行: #REF!
Name 成都健行: [8]数据有效性!$AE$3:$AE$10
Name 成都健行: [8]数据有效性!$AE$3:$AE$10
Name 成都健行: [8]数据有效性!$AE$3:$AE$10
Name 成都健行: #REF!
Name 大车型: #REF!
Name 大车型: #REF!
Name 大车型: #REF!
Name 大车型: #REF!
Name 大车型: #REF!
Name 大车型: '[2]0'!$P$2:$P$28
Name 都江堰二网: [9]数据有效性!#REF!
Name 都江堰直营店: [9]数据有效性!#REF!
Name 豪明新都: [7]数据有效性!#REF!
Name 豪明新都: #REF!
Name 豪明新都: [7]数据有效性!#REF!
Name 豪明新都: [7]数据有效性!#REF!
Name 豪明新都: [7]数据有效性!#REF!
Name 豪明新都: #REF!
Name 豪明展厅: [7]数据有效性!#REF!
Name 豪明展厅: #REF!
Name 豪明展厅: [7]数据有效性!#REF!
Name 豪明展厅: [7]数据有效性!#REF!
Name 豪明展厅: [7]数据有效性!#REF!
Name 豪明展厅: #REF!
Name 集团健行: [9]数据有效性!#REF!

Sheet 销售提成标准
A1: 公司 | B1: 序号 | C1: 店别 | D1: 职务 | E1: 姓名 | F1: 考核绩效分析
A2: 西物汽车 | B2: 1 | C2: 武侯展厅 | D2: 销售主管 | E2: 熊杰文 | F2: 销售整车按照标准对应提成
A3: 西物汽车 | B3: 2 | D3: 销售顾问 | E3: 易花贞子 | F3: 销售整车按照标准对应提成
A4: 西物汽车 | B4: 3 | D4: 销售顾问 | E4: 马攀 | F4: 销售整车按照标准对应提成
A5: 西物汽车 | B5: 4 | D5: 销售顾问 | E5: 毛春秀 | F5: 销售整车按照标准对应提成
A6: 西物汽车 | B6: 5 | D6: 销售顾问 | E6: 黄利君 | F6: 销售整车按照标准对应提成
A7: 西物汽车 | B7: 6 | D7: 销售顾问 | E7: 康鳞波 | F7: 销售整车按照标准对应提成
A8: 西物汽车 | B8: 7 | D8: 销售顾问 | E8: 廖晓军 | F8: 销售整车按照标准对应提成
A9: 西物汽车 | B9: 8 | D9: 销售顾问 | E9: 徐荣尧 | F9: 销售整车按照标准对应提成
A10: 西物汽车 | B10: 9 | D10: 销售顾问 | E10: 代力 | F10: 销售整车按照标准对应提成
A11: 西物汽车 | B11: 10 | C11: 武侯DCC | D11: 销售经理 | E11: 袁顺序 | F11: 岗位绩效KPI分值*9466.67元/月
A12: 西物汽车 | B12: 11 | D12: 销售顾问 | E12: 蒲喜 | F12: 销售整车按照标准对应提成
A13: 西物汽车 | B13: 12 | D13: 销售顾问 | E13: 唐操 | F13: 销售整车按照标准对应提成
A14: 西物汽车 | B14: 13 | D14: 销售顾问 | E14: 何伟 | F14: 销售整车按照标准对应提成
A15: 西物汽车 | B15: 14 | D15: 销售顾问 | E15: 万柳 | F15: 销售整车按照标准对应提成
A16: 西物汽车 | B16: 15 | D16: 销售顾问 | E16: 母勇 | F16: 销售整车按照标准对应提成
A17: 西物汽车 | B17: 16 | D17: 销售顾问 | E17: 刘飞 | F17: 销售整车按照标准对应提成
A18: 西物汽车 | B18: 17 | D18: 销售顾问 | E18: 钟小丽 | F18: 过程考核项目一分值*2500元+过程考核项目二分值*1500+BOC专项-特殊考核-1000元+网销*标准55*完成率
A19: 西物汽车 | B19: 18 | D19: 销售顾问 | E19: 何宇 | F19: 销售整车按照标准对应提成
A20: 西物汽车 | B20: 19 | D20: 销售顾问 | E20: 刘强1 | F20: 销售整车按照标准对应提成
A21: 西物汽车 | B21: 20 | D21: 销售顾问 | E21: 舒健 | F21: 销售整车按照标准对应提成
A22: 西物汽车 | B22: 21 | D22: 销售顾问 | E22: 王泳文 | F22: 销售整车按照标准对应提成
A23: 西物汽车 | B23: 22 | C23: 新媒体销售部 | D23: 主管 | E23: 肖廷忠 | F23: 岗位绩效KPI分值*固定金额元/月+终端量提成*40/台
A24: 西物汽车 | B24: 23 | D24: 主播 | E24: 黄凤 | F24: 岗位绩效KPI分值*固定金额元/月+终端量提成*20/台+优质视频*50元/条（上限500元）+视频创作超额完成奖励超额部分*50元/条（上限500元）
A25: 西物汽车 | B25: 24 | D25: 主播 | E25: 曾子乂 | F25: 岗位绩效KPI分值*固定金额元/月+终端量提成*100/台+线索超额完成奖励*10元/条（上限1000元）+直播场次超额奖励*100元/条（上限500元）
A26: 西物汽车 | B26: 25 | D26: 销售总监 | E26: 陈文虎 | F26: 岗位绩效KPI分值*固定金额元/月
A27: 西物汽车 | B27: 26 | C27: 事业部+总经办 | D27: 事业部总经理 | E27: 刘伟生
A28: 西物汽车 | B28: 27 | D28: 燃油车车部总监 | E28: 代蓓
A29: 西物汽车 | B29: 28 | D29: 新能源车部总监 | E29: 彭义
A30: 西物汽车 | B30: 29 | D30: 集团财务总监 | E30: 张静
A31: 西物汽车 | B31: 30 | D31: 事业部财务总监 | E31: 陶兰
A32: 西物汽车 | B32: 31 | D32: 集团资金总监 | E32: 陈军
A33: 西物汽车 | B33: 32 | D33: 事业部综合部副总 | E33: 齐坤忠
A34: 西物汽车 | B34: 33 | D34: 集团综合部 | E34: 王斌
A35: 西物汽车 | B35: 34 | D35: 事业部水平业务总监 | E35: 汤小明
A36: 西物汽车 | B36: 35 | D36: 事业部内勤 | E36: 唐玲 | F36: 固定绩效
A37: 西物汽车 | B37: 36 | D37: 总经办 | E37: 陈俊霖 | F37: 岗位绩效KPI分值*固定金额元/月
A38: 西物汽车 | B38: 37 | C38: 财务部 | D38: 财务经理 | E38: 顾雪梅 | F38: 固定绩效+考核绩效*KPI考核
A39: 西物汽车 | B39: 38 | C39: 财务部 | D39: 财务审计 | E39: 丁红 | F39: 固定绩效+考核绩效*KPI考核
A40: 西物汽车 | B40: 39 | C40: 财务部 | D40: 会计 | E40: 邓琦琪 | F40: 固定绩效+台次提成*1.5
...

Sheet 售后工资提成标准
B1: 2025年成都吉利汽车超市工资明细表（售后）
B2: 编制：人事部
B3: 序号 | C3: 部门 | D3: 姓 名 | E3: 考核绩效分析 | F3: 减：综合考核/其他 | G3: 留存
A5: 曹磊 | B5: 1 | C5: 管理部 | D5: 曹磊 | E5: 考核绩效分值<95 考核
A6: 曾吉斌 | B6: 2 | D6: 曾吉斌 | E6: 考核绩效分值<95 考核
A7: 谢尧江 | B7: 2 | D7: 谢尧江 | E7: （总产值-配件外销）*0.27%*95% | F7: （总产值-配件外销）*0.27%*95%*月度得分 | G7: （总产值-配件外销）*0.27%*5%
A8: 张敏 | B8: 3 | C8: 财务部 | D8: 张敏 | E8: 固定+（总产值-配件外销）*0.018% | G8: 固定留存
A9: 邱小艳 | B9: 4 | D9: 邱小艳 | E9: 固定+（总产值-配件外销）*0.02%+新能源补贴600/月 | G9: 固定留存
A10: 潘倩 | B10: 5 | D10: 潘倩 | E10: 固定+总产值*0.025% | G10: 固定留存
A11: 唐玉屏 | B11: 7 | C11: 业务部 | D11: 唐玉屏 | E11: (（留修信息量+返修信息量+送修信息量)*8/台+大事故补贴1000-3000)*95% | G11: (（留修信息量+返修信息量+送修信息量)*8/台+大事故补贴1000-3000)*5%
A12: 陈川蓉 | B12: 9 | D12: 陈川蓉 | E12: （总产值-配件外销）*0.1%*95% | G12: （总产值-配件外销）*0.1%*5%
A13: #N/A | D13: 小计
A14: 白影 | B14: =B12+1 -> 10 | C14: 服务部 | D14: 白影 | E14: (吧台收入*10%+结算台次提成*4元)*30%
A15: 曹青 | B15: =B14+1 -> 11 | D15: 曹青 | E15: (吧台收入*10%+结算台次提成*4元)*10%
D16: 陶纯玲 | E16: (吧台收入*10%+结算台次提成*4元)*14%
A17: 朱开莲 | B17: =B15+1 -> 12 | D17: 朱开莲 | E17: (吧台收入*10%+结算台次提成*4元)*22%
A18: #N/A | D18: 小计
A19: 唐梅 | B19: =B17+1 -> 13 | C19: 回访部 | D19: 唐梅 | E19: N-3首保*13+N-4首保*10+N-5首保*8+N-6二保*18+N-9二保*15+N-12二保*26+N-6定保*15+N-9定保*10+N-12定保*25+外拓*20+N-6其他*25+N-9其他*30+N-12其他*30+无福袋*2+续保*25+新能源续保*8+3DC*1
A20: 陈琳琳 | B20: =B19+1 -> 14 | D20: 陈琳琳 | E20: N-3首保*13+N-4首保*10+N-5首保*8+N-6二保*18+N-9二保*15+N-12二保*26+N-6定保*15+N-9定保*10+N-12定保*25+外拓*20+N-6其他*25+N-9其他*30+N-12其他*30+无福袋*2+续保*25+新能源续保*8+3DC*1
A21: 邱昭丽 | B21: =B20+1 -> 15 | D21: 邱昭丽 | E21: N-3首保*13+N-4首保*10+N-5首保*8+N-6二保*18+N-9二保*15+N-12二保*26+N-6定保*15+N-9定保*10+N-12定保*25+外拓*20+N-6其他*25+N-9其他*30+N-12其他*30+无福袋*2+续保*25+新能源续保*8+3DC*1
A22: 黄雪梅 | B22: =B21+1 -> 16 | D22: 黄雪梅 | E22: N-3首保*13+N-4首保*10+N-5首保*8+N-6二保*18+N-9二保*15+N-12二保*26+N-6定保*15+N-9定保*10+N-12定保*25+外拓*20+N-6其他*25+N-9其他*30+N-12其他*30+无福袋*2+续保*25+新能源续保*8+3DC*1
A23: 李彩琼 | B23: =B22+1 -> 17 | D23: 李彩琼 | E23: N-3首保*13+N-4首保*10+N-5首保*8+N-6二保*18+N-9二保*15+N-12二保*26+N-6定保*15+N-9定保*10+N-12定保*25+外拓*20+N-6其他*25+N-9其他*30+N-12其他*30+无福袋*2+续保*25+新能源续保*8+3DC*1
A24: 向阳 | B24: =B23+1 -> 18 | D24: 向阳 | E24: N-3首保*13+N-4首保*10+N-5首保*8+N-6二保*18+N-9二保*15+N-12二保*26+N-6定保*15+N-9定保*10+N-12定保*25+外拓*20+N-6其他*25+N-9其他*30+N-12其他*30+无福袋*2+续保*25+新能源续保*8+3DC*1
A25: #N/A | D25: 小计
A26: 阳国华 | B26: =B24+1 -> 19 | D26: 阳国华 | E26: 武侯店事故产值*40%*95% | G26: 武侯店事故产值*40%*5%
A27: 舒童强 | B27: =B26+1 -> 20 | C27: 业务部 | D27: 舒童强
A28: 罗义瑕 | B28: =B27+1 -> 21 | D28: 罗义瑕 | E28: 正常台次*4元+保险台次*8元+索赔台次*4元+正常产值*2%+保险产值*1.6%+索赔产值*0.5%+养护收入*6%+精品*8%+美容*10%+首保福袋卡*35+保养福袋卡*25+DMS保养套餐（任务达成率）*台次*50+附加业务提成
A29: 段宝安 | B29: =B28+1 -> 22 | D29: 段宝安 | E29: 正常台次*4元+保险台次*8元+索赔台次*4元+正常产值*2%+保险产值*1.6%+索赔产值*0.5%+养护收入*6%+精品*8%+美容*10%+首保福袋卡*35+保养福袋卡*25+DMS保养套餐（任务达成率）*台次*50+附加业务提成
A30: #N/A | B30: 23 | D30: 张林1 | E30: 正常台次*4元+保险台次*8元+索赔台次*4元+正常产值*2%+保险产值*1.6%+索赔产值*0.5%+养护收入*6%+精品*8%+美容*10%+首保福袋卡*35+保养福袋卡*25+DMS保养套餐（任务达成率）*台次*50+附加业务提成
A31: 张建 | B31: 25 | D31: 张建 | E31: 正常台次*4元+保险台次*8元+索赔台次*4元+正常产值*2%+保险产值*1.6%+索赔产值*0.5%+养护收入*6%+精品*8%+美容*10%+首保福袋卡*35+保养福袋卡*25+DMS保养套餐（任务达成率）*台次*50+附加业务提成
A32: 贾文哲 | B32: 26 | D32: 贾文哲 | E32: 正常台次*4元+保险台次*8元+索赔台次*4元+正常产值*2%+保险产值*1.6%+索赔产值*0.5%+养护收入*6%+精品*8%+美容*10%+首保福袋卡*35+保养福袋卡*25+DMS保养套餐（任务达成率）*台次*50+附加业务提成
A33: 黄小炼 | B33: 25 | D33: 黄小炼 | E33: 正常台次*4元+保险台次*8元+索赔台次*4元+正常产值*2%+保险产值*1.6%+索赔产值*0.5%+养护收入*6%+精品*8%+美容*10%+首保福袋卡*35+保养福袋卡*25+DMS保养套餐（任务达成率）*台次*50+附加业务提成
A34: 陈昱良 | B34: =B33+1 -> 26 | D34: 陈昱良 | E34: 正常台次*4元+保险台次*8元+索赔台次*4元+正常产值*2%+保险产值*1.6%+索赔产值*0.5%+养护收入*6%+精品*8%+美容*10%+首保福袋卡*35+保养福袋卡*25+DMS保养套餐（任务达成率）*台次*50+附加业务提成
A35: 王毅 | B35: =B34+1 -> 27 | D35: 王毅 | E35: 正常台次*4元+保险台次*8元+索赔台次*4元+正常产值*2%+保险产值*1.6%+索赔产值*0.5%+养护收入*6%+精品*8%+美容*10%+首保福袋卡*35+保养福袋卡*25+DMS保养套餐（任务达成率）*台次*50+附加业务提成
A36: 金亮亮 | B36: =B35+1 -> 28 | D36: 金亮亮 | E36: 正常台次*4元+保险台次*8元+索赔台次*4元+正常产值*2%+保险产值*1.6%+索赔产值*0.5%+养护收入*6%+精品*8%+美容*10%+首保福袋卡*35+保养福袋卡*25+DMS保养套餐（任务达成率）*台次*50+附加业务提成
A37: 徐源 | B37: =B36+1 -> 29 | D37: 徐源 | E37: 正常台次*4元+保险台次*8元+索赔台次*4元+正常产值*2%+保险产值*1.6%+索赔产值*0.5%+养护收入*6%+精品*8%+美容*10%+首保福袋卡*35+保养福袋卡*25+DMS保养套餐（任务达成率）*台次*50+附加业务提成
A38: 费朝旭 | B38: =B37+1 -> 30 | D38: 费朝旭 | E38: 正常台次*4元+保险台次*8元+索赔台次*4元+正常产值*2%+保险产值*1.6%+索赔产值*0.5%+养护收入*6%+精品*8%+美容*10%+首保福袋卡*35+保养福袋卡*25+DMS保养套餐（任务达成率）*台次*50+附加业务提成
A39: 曾浩 | B39: =B38+1 -> 31 | D39: 曾浩 | E39: 正常台次*4元+保险台次*8元+索赔台次*4元+正常产值*2%+保险产值*1.6%+索赔产值*0.5%+养护收入*6%+精品*8%+美容*10%+首保福袋卡*35+保养福袋卡*25+DMS保养套餐（任务达成率）*台次*50+附加业务提成
A40: 刘强 | B40: =B39+1 -> 32 | D40: 刘强 | E40: 正常台次*4元+保险台次*8元+索赔台次*4元+正常产值*2%+保险产值*1.6%+索赔产值*0.5%+养护收入*6%+精品*8%+美容*10%+首保福袋卡*35+保养福袋卡*25+DMS保养套餐（任务达成率）*台次*50+附加业务提成
A41: #N/A | D41: 小计
...

Sheet 邀约专员提成
B1: 05月 | C1: 人员 | D1: 人员 | AE1: 总绩效 | AF1: 发放金额
E2: 标准 | F2: 是否达成 | G2: 考核 | H2: 标准 | I2: 实际得分 | J2: 绩效 | K2: 单台绩效 | L2: 到店量 | M2: 绩效 | N2: 单台绩效 | O2: 成交台次 | P2: 绩效 | Q2: 计划线索分配量 | R2: 线索分配量 | S2: 邀约率 | T2: 单组追加 | U2: 奖励提成 | V2: 成交率 | W2: 单台追加 | X2: 奖励提成 | Y2: 单组追加 | Z2: 重攻台次 | AA2: 奖励 | AB2: 邀约任务 | AC2: 完成率
B3: 西物 | C3: 金玉梅 | D3: 1 | E3: 1 | F3: 0 | G3: 六项标准均达成 | H3: 6 | I3: 600 | J3: 60 | K3: 51 | L3: =K3*J3 -> 3060 | M3: 40 | N3: 9 | O3: =M3*N3 -> 360 | P3: 500 | Q3: 455 | R3: =IFERROR(K3/Q3,"") -> 0.11208791 | T3: =S3*K3 -> 0 | U3: =IFERROR(N3/K3,"") -> 0.17647059 | V3: 0 | W3: =N3*V3 -> 0 | Z3: =X3*Y3 -> 0 | AA3: 70 | AB3: =IFERROR(K3/AA3,"") -> 0.72857143 | AC3: -200 | AD3: =I3+L3+O3+T3+W3+Z3+AC3+F3 -> 3820 | AE3: 金玉梅 | AF3: =AD3 -> 3820
B4: 西物 | C4: 周思雨 | E4: 1 | F4: 0 | H4: 6 | I4: 600 | J4: 60 | K4: 48 | L4: =K4*J4 -> 2880 | M4: 40 | N4: 13 | O4: =M4*N4 -> 520 | P4: 500 | Q4: 441 | R4: =IFERROR(K4/Q4,"") -> 0.10884354 | T4: =S4*K4 -> 0 | U4: =IFERROR(N4/K4,"") -> 0.27083333 | V4: 20 | W4: =N4*V4 -> 260 | X4: 1000 | Y4: 1 | Z4: =X4*Y4 -> 1000 | AA4: 55 | AB4: =IFERROR(K4/AA4,"") -> 0.87272727 | AC4: -100 | AD4: =I4+L4+O4+T4+W4+Z4+AC4+F4 -> 5160 | AE4: 周思雨 | AF4: =AD4 -> 5160
B5: 西物 | C5: 陈文霜 | E5: 1 | F5: 0 | H5: 6 | I5: 600 | J5: 60 | K5: 57 | L5: =K5*J5 -> 3420 | M5: 40 | N5: 16 | O5: =M5*N5 -> 640 | P5: 500 | Q5: 458 | R5: =IFERROR(K5/Q5,"") -> 0.12445415 | T5: =S5*K5 -> 0 | U5: =IFERROR(N5/K5,"") -> 0.28070175 | V5: 20 | W5: =N5*V5 -> 320 | Z5: =X5*Y5 -> 0 | AA5: 70 | AB5: =IFERROR(K5/AA5,"") -> 0.81428571 | AC5: -200 | AD5: =I5+L5+O5+T5+W5+Z5+AC5+F5 -> 4780 | AE5: 陈文霜 | AF5: =AD5 -> 4780
B6: 西物 | C6: 杜小红 | E6: 1 | F6: 0 | H6: 6 | I6: 600 | J6: 60 | K6: 64 | L6: =K6*J6 -> 3840 | M6: 40 | N6: 15 | O6: =M6*N6 -> 600 | P6: 500 | Q6: 457 | R6: =IFERROR(K6/Q6,"") -> 0.14004376 | T6: =S6*K6 -> 0 | U6: =IFERROR(N6/K6,"") -> 0.234375 | V6: 20 | W6: =N6*V6 -> 300 | Z6: =X6*Y6 -> 0 | AA6: 70 | AB6: =IFERROR(K6/AA6,"") -> 0.91428571 | AC6: -100 | AD6: =I6+L6+O6+T6+W6+Z6+AC6+F6 -> 5240 | AE6: 杜小红 | AF6: =AD6 -> 5240
B7: 西物 | C7: 周梅 | E7: 1 | F7: 0 | H7: 6 | I7: 600 | J7: 60 | K7: 71 | L7: =K7*J7 -> 4260 | M7: 40 | N7: 16 | O7: =M7*N7 -> 640 | P7: 500 | Q7: 422 | R7: =IFERROR(K7/Q7,"") -> 0.16824645 | S7: 10 | T7: =S7*K7 -> 710 | U7: =IFERROR(N7/K7,"") -> 0.22535211 | V7: 20 | W7: =N7*V7 -> 320 | Z7: =X7*Y7 -> 0 | AA7: 70 | AB7: =IFERROR(K7/AA7,"") -> 1.0142857 | AD7: =I7+L7+O7+T7+W7+Z7+AC7+F7 -> 6530 | AE7: 周梅 | AF7: =AD7 -> 6530
B9: 05月 | C9: 人员 | D9: 400接起率 | G9: DMS指标六维度 | J9: 邀约绩效60元/组 | M9: 成交绩效40元/台 | P9: 缤越COOL、博越COOL、缤瑞COOL | S9: 成交率奖励 | V9: 任务考核 | Y9: 总绩效
D10: 标准 | E10: 是否达成 | F10: 考核 | G10: 标准 | H10: 实际得分 | I10: 绩效 | J10: 单台绩效 | K10: 到店量 | L10: 绩效 | M10: 单台绩效 | O10: 绩效 | P10: 达成邀约量 | Q10: 单组到店追加 | R10: 奖励提成 | S10: 成交率 | T10: 单台追加 | U10: 奖励提成 | V10: 邀约任务 | W10: 完成率 | X10: 考核金额
B11: 超市 | C11: 李春梅 | D11: 1 | E11: 1 | F11: 0 | G11: 六项标准均达成 | H11: 6 | I11: 600 | J11: 60 | K11: 74 | L11: 4440 | M11: 40 | N11: 15 | O11: 600 | P11: 6 | Q11: 100 | R11: 600 | S11: 0.2027027 | T11: 20 | U11: 300 | V11: 60 | W11: 1.2333333 | Y11: 6540 | AE11: =C11 -> 李春梅 | AF11: =Y11 -> 6540
B12: 超市 | C12: 魏艳 | E12: 1 | F12: 0 | H12: 6 | I12: 600 | J12: 60 | K12: 57 | L12: 3420 | M12: 40 | N12: 9 | O12: 360 | P12: 5 | Q12: 100 | R12: 500 | S12: 0.15789474 | U12: 0 | V12: 60 | W12: 0.95 | X12: 171 | Y12: 4709 | AE12: =C12 -> 魏艳 | AF12: =Y12 -> 4709
B13: 超市 | C13: 谷雨 | E13: 1 | F13: 0 | H13: 6 | I13: 600 | J13: 60 | K13: 56 | L13: 3360 | M13: 40 | N13: 12 | O13: 480 | P13: 6 | Q13: 100 | R13: 600 | S13: 0.21428571 | T13: 20 | U13: 240 | V13: 60 | W13: 0.93333333 | X13: 225 | Y13: 5055 | AE13: =C13 -> 谷雨 | AF13: =Y13 -> 5055
B15: 05月 | C15: 人员 | D15: 400接起率 | G15: DMS指标六维度 | J15: 邀约绩效60元/组 | M15: 成交绩效40元/台 | P15: 过程KPI奖励 | X15: 重攻奖励： | AA15: 任务考核 | AD15: 总绩效 | AE15: 杨婷 | AF15: =AD17 -> 4130
D16: 标准 | E16: 是否达成 | F16: 考核 | G16: 标准 | H16: 实际得分 | I16: 绩效 | J16: 单台绩效 | K16: 到店量 | L16: 绩效 | M16: 单台绩效 | N16: 成交台次 | O16: 绩效 | P16: 计划线索分配量 | Q16: 线索分配量 | R16: 邀约率 | S16: 单组追加 | T16: 奖励提成 | U16: 成交率 | V16: 单台追加 | W16: 奖励提成 | X16: 单组追加 | Y16: 重攻台次 | Z16: 奖励 | AA16: 邀约任务 | AB16: 完成率 | AC16: 考核金额 | AE16: 陈子逸 | AF16: =W32 -> 3638
B17: 崇州 | C17: 杨婷 | D17: 1 | E17: 1 | F17: 0 | G17: 六项标准均达成 | H17: 6 | I17: 600 | J17: 60 | K17: 38 | L17: =K17*J17 -> 2280 | M17: 35 | N17: 14 | O17: =M17*N17 -> 490 | P17: 600 | R17: =IFERROR(K17/Q17,"") | S17: 20 | T17: =S17*K17 -> 760 | U17: =IFERROR(N17/K17,"") -> 0.36842105 | W17: =N17*V17 -> 0 | Z17: =X17*Y17 -> 0 | AB17: =IFERROR(K17/AA17,"") | AD17: =I17+L17+O17+T17+W17+Z17-AC17-F17 -> 4130
B18: 1.400接起率出现未接起考核500元
B19: 2.DMS六维度指标：1.线索有效率70% 2.响应及时率100% 3.及时跟进率100% 4.邀约到店率15% 5.到店成交率35% 6.线索成交率4% 7.战败率90%以下，每项达成按100元计提，7项指标均达成追加100元。
B20: 3.邀约基础绩效：基础绩效60元一组
B21: 4.邀约到店率≥15%追加10元一组，未达标不奖励
B22: 5.成交基础绩效：基础绩效40元/台
B23: 6.成交率30-＜35%，追加20元/台成交；成交率≥35%，追加30元/台成交
B24: 7.有重攻车型时可设立重攻车型，重攻车型客户到店额外追加10元/组
B25: 8.任务考核：设立当月邀约到店目标量，未达成按照比例进行计提邀约绩效，上限100%
B26: 9.薪资方案由网销经理填报，销售总监/副总审核，总经理签字确认，承报财务/行政纳入当月绩效。
B27: 备注：1.到店率及成交率随市场变化，合理设定及上浮邀约专员追加指标。 2.店内过程指标需真实有效，DMS指标可手段提升
L30: 任务达成
C31: 员工 | D31: 店面 | E31: 基本工资 | F31: 岗位工资 | G31: DMS指标绩效/70元/项 | H31: 自媒体绩效(含内部员工转发率） | I31: 线索提成标准 | J31: 终端提成标准（月计算完成率） | K31: 线索任务 | L31: 销售任务 | M31: 线索数 | N31: 线索达成率 | O31: 终端达成 | P31: 终端达成率 | Q31: 线索绩效 | R31: 终端绩效 | S31: 新车上市4月内线索激励减半量 | T31: 线索减半金额 | U31: 考核 | V31: 绩效提成 | W31: 实际发放 | X31: 薪酬总额
C32: 陈子逸 | D32: 机场网销 | E32: 1000 | F32: 200 | G32: 280 | H32: 1000 | J32: 600 | K32: 2500 | L32: 102 | M32: 2472 | N32: 0.9888 | O32: 54 | P32: 0.52941176 | Q32: 2040 | R32: 317.64706 | T32: 0 | V32: 3638 | W32: 3638 | X32: 4838

Sheet 客户部提成
A1: 05月客户关系部 | AO1: A | AP1: B | AQ1: C=B-A | AR1: D | AS1: E | AT1: F=D*E
A2: 值 | B2: 项 | C2: 达成率 | D2: 系数 | E2: 邓芳 | G2: 张保珍 | I2: 备注 | K2: 05月 | L2: 潜客回访 | M2: 5天新车回访 | N2: 30天新车回访 | O2: 潜客战败回访 | P2: 新车回访绩效 | Q2: 面访量 | R2: 面访（6元/个） | S2: 多对一群聊建立量 | T2: 多对一群聊建立及维护（5元） | U2: 生日关怀接通量 | V2: 生日关怀绩效提成（2元/个） | W2: 口碑/发帖量 | X2: 口碑发帖绩效（X/个） | Y2: 投诉处理 | Z2: 销售满意度得分 | AA2: 销售满意度绩效 | AB2: 保客营销 | AD2: 合计薪资 | AE2: 备注 | AH2: 保客营销挖掘与转化绩效 | AN2: 店面——中国星武侯 | AO2: 1-3月数据情况 | AP2: 5月达成情况 | AQ2: 达成提升目标(%) | AR2: 台次(交付数) | AS2: 享受单台 | AT2: 金额
E3: 数量 | F3: 小计 | G3: 数量 | H3: 小计 | K3: 周舟 | L3: 78 | M3: 78 | N3: 82 | P3: =SUM(L3:O3)*2 -> 476 | Q3: 91 | R3: =Q3*6 -> 546 | S3: 126 | T3: =S3*5 -> 630 | U3: 381 | V3: =U3*2 -> 762 | W3: 15 | X3: =W3*50 -> 750 | Y3: 200 | Z3: 97.83 | AA3: 400 | AB3: 440 | AD3: =SUM(P3,R3,T3,V3,X3,Y3,AA3,AB3) -> 4204 | AH3: 基盘客户 转介绍 | AI3: 绩效(元/台) | AJ3: 20 | AK3: 30 | AL3: 40 | AN3: 电话回访 | AO3: 0 | AP3: =727+847 -> 1574 | AQ3: 0 | AR3: 0 | AS3: 0 | AT3: 500
A4: 必做 | B4: 3DC一网 | D4: 1 | F4: =D4*E4 -> 0 | H4: =G4*D4 -> 0 | K4: 合计 | AI4: 提升目标（%） | AJ4: 提升＜1% | AK4: 1%≤提升＜3% | AL4: 提升≥3% | AN4: 基盘客户转介绍 | AO4: 0.0695 | AP4: 0.3043 | AQ4: =+AP4-AO4 -> 0.2348 | AR4: 14 | AS4: =+IF(AQ4<1%,20,IF(AQ4<3%,30,40)) -> 40 | AT4: =AR4*AS4 -> 560
A5: 必做 | B5: 3DC二网 | D5: 1 | F5: =D5*E5 -> 0 | H5: =G5*D5 -> 0 | K5: 1.潜客回访、3天新车回访、30天新车回访、战败客户回访、生日关怀、售后3DC标准提成按电话接通2元/组 2.新车面访6元/个 3.口碑/发帖：＜5篇，30元/帖；≥5帖＜10帖，40元/帖；≥10帖，50元/帖；最高1000元 4.生日关怀，接通1元/个; 5.投诉处理：2小时未响应考核200元/单 3天未闭环考核500元/单，投诉单申述未通过考核200元/单，无异常奖励200元， 6.销售满意度：400得分90分及以下，考核200元；≥93分，奖励300元；≥95分，奖励500元 | AH5: 保客挖掘 置换/增购 | AI5: 绩效(元/台) | AJ5: 30 | AK5: 40 | AL5: 50 | AN5: 保客挖掘置换/增购 | AP5: 0.0667 | AQ5: 0.07 | AR5: 1 | AS5: =+IF(AQ5>=3%,50,IF(AQ5>=1%,40,30)) -> 50 | AT5: =AR5*AS5 -> 50
A6: 必做 | B6: 新车5DC回访 | D6: 1 | F6: =D6*E6 -> 0 | G6: 163 | H6: =G6*D6 -> 163 | AI6: 提升目标（%） | AJ6: 提升＜1% | AK6: 1%≤提升＜3% | AL6: 提升≥3% | AN6: 全员营销 | AO6: 0.1069 | AP6: 0.071 | AQ6: =+AP6-AO6 -> -0.0359 | AR6: 6 | AS6: =+IF(AQ6<1%,10,IF(AQ6<3%,20,30)) -> 10 | AT6: =AR6*AS6 -> 60
A7: 必做 | B7: 新车30DC回访 | D7: 1 | F7: =D7*E7 -> 0 | H7: =G7*D7 -> 0 | AH7: 全员营销 | AI7: 绩效(元/台) | AJ7: 10 | AK7: 20 | AL7: 30 | AN7: 绩效合计 | AO7: 邓芳 | AT7: =SUM(AT3:AT6) -> 1170
A8: 必做 | B8: 战败回访 | D8: 1 | F8: =D8*E8 -> 0 | H8: =G8*D8 -> 0 | AI8: 提升目标（%） | AJ8: 提升＜1% | AK8: 1%≤提升＜3% | AL8: 提升≥3%
A9: 必做 | B9: 潜客回访 | D9: 1 | E9: 200 | F9: =D9*E9 -> 200 | H9: =G9*D9 -> 0 | AH9: 基本数据要求： | AN9: 店面——银河B武侯 | AO9: 1-3月数据情况 | AP9: 5月达成情况 | AQ9: 达成提升目标(%) | AR9: 台次(交付数) | AS9: 享受单台 | AT9: 金额
A10: 机动 | B10: 其他回访 | D10: 1 | E10: 100 | F10: =D10*E10 -> 100 | G10: 100 | H10: =G10*D10 -> 100 | I10: 其他回访，是指核实老带新，核实债权转让，活动参加等临时事项 | AH10: 1、增加500元固定绩效，要求每日对基盘客户有效回访数＞30批次，单人每月有效回访批次＞900批 2、以上三类别计算基数分母为：当月销量 3、此方案试运行时间为：4月-6月，后续另行调整 | AN10: 电话回访 | AO10: 0 | AP10: 839 | AQ10: 0 | AR10: 0 | AS10: 0 | AT10: 0
A11: 必做 | B11: 新车面访 | D11: 6 | E11: 66 | F11: =D11*E11 -> 396 | G11: 24 | H11: =G11*D11 -> 144 | AN11: 基盘客户转介绍 | AO11: 0.1511 | AP11: 0.5714 | AQ11: =+AP11-AO11 -> 0.4203 | AR11: 16 | AS11: =+IF(AQ11<1%,20,IF(AQ11<3%,30,40)) -> 40 | AT11: =AR11*AS11 -> 640
A12: 必做 | B12: 微信维系 | D12: 300 | E12: 1 | F12: =D12*E12 -> 300 | G12: 1 | H12: =G12*D12 -> 300 | AN12: 保客挖掘置换/增购 | AO12: 4月新增项目 | AP12: 0.1111 | AQ12: 0.11 | AR12: 1 | AS12: =+IF(AQ12>=3%,50,IF(AQ12>=1%,40,30)) -> 50 | AT12: =AR12*AS12 -> 50
A13: 必做 | B13: 投诉处理 | D13: 100 | E13: 1 | F13: =D13*E13 -> 100 | G13: 1 | H13: =G13*D13 -> 100 | AN13: 全员营销 | AO13: 0.0612 | AP13: 0.124 | AQ13: =+AP13-AO13 -> 0.0628 | AR13: 15 | AS13: =+IF(AQ13<1%,10,IF(AQ13<3%,20,30)) -> 30 | AT13: =AR13*AS13 -> 450
A14: 必做 | B14: 微信添加 | D14: 100 | E14: 1 | F14: =D14*E14 -> 100 | G14: 1 | H14: =G14*D14 -> 100 | AN14: 绩效合计 | AO14: 李璐秀 | AT14: =SUM(AT10:AT13) -> 1140
A15: 机动 | B15: 满意度 | D15: 400 | E15: 1 | F15: =D15*E15 -> 400 | G15: 1 | H15: =G15*D15 -> 400 | I15: 4月400销售满意度：西物95.65分
A16: 增值 | B16: 口碑 | D16: 50 | E16: 20 | F16: =D16*E16 -> 1000 | G16: 20 | H16: =G16*D16 -> 1000
A17: 增值 | B17: 发帖 | D17: 50 | E17: 20 | F17: =D17*E17 -> 1000 | G17: 20 | H17: =G17*D17 -> 1000 | AN17: 店面——银河A武侯 | AO17: 1-3月数据情况 | AP17: 5月达成情况 | AQ17: 达成提升目标(%) | AR17: 台次(交付数) | AS17: 享受单台 | AT17: 金额
A18: 增值 | B18: N-3首保 | C18: 0.81 | D18: 25 | E18: 12 | F18: =D18*E18 -> 300 | G18: 1 | H18: =G18*D18 -> 25 | AN18: 电话回访 | AO18: 0 | AP18: 910 | AQ18: 0 | AR18: 0 | AS18: 0 | AT18: 500
A19: 增值 | B19: N-4首保 | C19: 0.85 | D19: 17 | E19: 1 | F19: =D19*E19 -> 17 | G19: 0 | H19: =G19*D19 -> 0 | AN19: 基盘客户转介绍 | AO19: 0.1574 | AP19: 0.3333 | AQ19: =+AP19-AO19 -> 0.1759 | AR19: 9 | AS19: =+IF(AQ19<1%,20,IF(AQ19<3%,30,40)) -> 40 | AT19: =AR19*AS19 -> 360
A20: 增值 | B20: N-5首保 | C20: 0.85 | D20: 15 | E20: 0 | F20: =D20*E20 -> 0 | G20: 0 | H20: =G20*D20 -> 0 | AN20: 保客挖掘置换/增购 | AO20: 4月新增项目 | AP20: 0.4348 | AQ20: 0.4348 | AR20: 10 | AS20: =+IF(AQ20>=3%,50,IF(AQ20>=1%,40,30)) -> 50 | AT20: =AR20*AS20 -> 500
A21: 增值 | B21: N-6二保 | C21: 0.38 | D21: 30 | E21: 2 | F21: =D21*E21 -> 60 | G21: 0 | H21: =G21*D21 -> 0 | AN21: 全员营销 | AO21: 0.0456 | AP21: 0.058 | AQ21: =+AP21-AO21 -> 0.0124 | AR21: 9 | AS21: =+IF(AQ21<1%,10,IF(AQ21<3%,20,30)) -> 20 | AT21: =AR21*AS21 -> 180
A22: 增值 | B22: N-9二保 | C22: 0.51 | D22: 25 | E22: 2 | F22: =D22*E22 -> 50 | G22: 1 | H22: =G22*D22 -> 25 | AN22: 绩效合计 | AO22: 郭静 | AT22: =SUM(AT18:AT21) -> 1540
A23: 增值 | B23: N-12二保 | C23: 0.61 | D23: 30 | E23: 2 | F23: =D23*E23 -> 60 | G23: 1 | H23: =G23*D23 -> 30
A24: 增值 | B24: N-6定保 | C24: 0.36 | D24: 30 | E24: 0 | F24: =D24*E24 -> 0 | G24: 4 | H24: =G24*D24 -> 120
A25: 增值 | B25: N-9定保 | C25: 0.54 | D25: 20 | E25: 0 | F25: =D25*E25 -> 0 | G25: 1 | H25: =G25*D25 -> 20 | AN25: 店面——银河B机场 | AO25: 1-3月数据情况 | AP25: 5月达成情况 | AQ25: 达成提升目标(%) | AR25: 台次(交付数) | AS25: 享受单台 | AT25: 金额
A26: 增值 | B26: N-12定保 | C26: 0.7119 | D26: 30 | E26: 0 | F26: =D26*E26 -> 0 | G26: 2 | H26: =G26*D26 -> 60 | AN26: 电话回访 | AO26: 0 | AP26: 22 | AQ26: 0 | AR26: 0 | AS26: 0 | AT26: 0
A27: 增值 | B27: 外拓 | D27: 20 | E27: 15 | F27: =D27*E27 -> 300 | G27: 6 | H27: =G27*D27 -> 120 | AN27: 基盘客户转介绍 | AO27: 0 | AP27: 0.33 | AQ27: =+AP27-AO27 -> 0.33 | AR27: 4 | AS27: =+IF(AQ27<1%,20,IF(AQ27<3%,30,40)) -> 40 | AT27: =AR27*AS27 -> 160
A28: 增值 | B28: N-6其他 | C28: 0.3025 | D28: 25 | E28: 2 | F28: =D28*E28 -> 50 | G28: 4 | H28: =G28*D28 -> 100 | AN28: 保客挖掘置换/增购 | AO28: 4月新增项目 | AP28: 0 | AQ28: 0 | AR28: 0 | AS28: =+IF(AQ28>=3%,50,IF(AQ28>=1%,40,30)) -> 30 | AT28: =AR28*AS28 -> 0
A29: 增值 | B29: N-9其他 | C29: 0.3581 | D29: 30 | E29: 2 | F29: =D29*E29 -> 60 | G29: 2 | H29: =G29*D29 -> 60 | AN29: 全员营销 | AO29: 0.0652 | AP29: 0.167 | AQ29: =+AP29-AO29 -> 0.1018 | AR29: 7 | AS29: =+IF(AQ29<1%,10,IF(AQ29<3%,20,30)) -> 30 | AT29: =AR29*AS29 -> 210
A30: 增值 | B30: N-12其他 | C30: 0.3989 | D30: 30 | E30: 2 | F30: =D30*E30 -> 60 | G30: 3 | H30: =G30*D30 -> 90 | AN30: 绩效合计 | AO30: 古瑞婷 | AT30: =SUM(AT26:AT29) -> 370
A31: 增值 | B31: 无福袋 | D31: 2 | E31: 2 | F31: =D31*E31 -> 4 | G31: 7 | H31: =G31*D31 -> 14
A32: 增值 | B32: 纯电回站 | D32: 8 | E32: 0 | F32: =D32*E32 -> 0 | G32: 3 | H32: =G32*D32 -> 24 | I32: 2023年4月1号起，纯电车型预约回站，按8元/个计算
A33: 增值 | B33: 车机 | D33: 100 | F33: =D33*E33 -> 0 | H33: =G33*D33 -> 0 | AN33: 店面——中国星机场 | AO33: 1-3月数据情况 | AP33: 5月达成情况 | AQ33: 达成提升目标(%) | AR33: 台次(交付数) | AS33: 享受单台 | AT33: 金额
A34: 增值 | B34: 福袋 | D34: 25 | F34: =D34*E34 -> 0 | H34: =G34*D34 -> 0 | AN34: 电话回访 | AO34: 0 | AP34: 72 | AQ34: 0 | AR34: 0 | AS34: 0 | AT34: 0
A35: 增值 | B35: 质保 | D35: 15 | F35: =D35*E35 -> 0 | H35: =G35*D35 -> 0 | AN35: 基盘客户转介绍 | AO35: 0.1319 | AP35: 0.45 | AQ35: =+AP35-AO35 -> 0.3181 | AR35: 9 | AS35: =+IF(AQ35<1%,20,IF(AQ35<3%,30,40)) -> 40 | AT35: =AR35*AS35 -> 360
A36: 增值 | B36: 流失 | D36: 15 | F36: =D36*E36 -> 0 | H36: =G36*D36 -> 0 | AN36: 保客挖掘置换/增购 | AO36: 4月新增项目 | AP36: 0.1429 | AQ36: 0 | AR36: 1 | AS36: =+IF(AQ36>=3%,50,IF(AQ36>=1%,40,30)) -> 30 | AT36: =AR36*AS36 -> 30
A37: 增值 | B37: 续保 | D37: 25 | E37: 2 | F37: =D37*E37 -> 50 | G37: 2 | H37: =G37*D37 -> 50 | AN37: 全员营销 | AO37: 0.2857 | AP37: 0.2 | AQ37: =+AP37-AO37 -> -0.0857 | AR37: 5 | AS37: =+IF(AQ37<1%,10,IF(AQ37<3%,20,30)) -> 10 | AT37: =AR37*AS37 -> 50
A38: 增值 | B38: 轮胎 | D38: 10 | F38: =D38*E38 -> 0 | H38: =G38*D38 -> 0 | AN38: 绩效合计 | AO38: 周舟 | AT38: =SUM(AT34:AT37) -> 440
A39: 增值 | B39: LED | D39: 24.8 | F39: =D39*E39 -> 0 | H39: =G39*D39 -> 0
A40: 增值 | B40: 盲区 | D40: 200 | F40: =D40*E40 -> 0 | H40: =G40*D40 -> 0
...

Sheet 新媒体
B1: 2026年 5月新媒体薪资明细
B2: 岗位 | C2: 项目 | D2: 直播场次 | E2: 直播线索 （仅限 小风车线索、直播复盘数据做参考） | F2: 直播粉丝关注量 （仅限 对应账户） | G2: 视频创作发布量 | H2: 岗位绩效KPI | I2: 岗位绩效 | J2: 终端量提成（仅限 对应公司账户端量） | L2: 线索超额完成奖励 | N2: 直播场次超额奖励 | P2: 基本薪资 | Q2: 绩效薪资 | R2: 合计薪资
J3: 以月度目标制定 | K3: 终端完成 | L3: 超额部分10元/条 （上限1000元） | M3: 当月超额线索数 | N3: 超额部分100元/场 （上限500元） | O3: 直播超额 完成场次 | T3: 新媒体部门人力归属及分配（5月）
J4: 18 | T4: 序号 | U4: 网属 | V4: 公司归属 | W4: 执行岗位 | X4: 岗位要求 | Y4: 姓名 | Z4: 负责店面 | AA4: 人力数量 | AB4: 绩效薪资 | AC4: 备注
B5: 直播运维专员 | C5: 月度目标量 | D5: 90 | E5: 523 | F5: 400 | G5: 40 | H5: 7000 | I5: =H9*H5% -> 6423.8611 | J5: 未完成50元/台 完成100元/台 | T5: 1 | U5: G网 | V5: 吉星-西物 | W5: 新媒体经理/运营 | X5: 专职 | Y5: 肖廷忠 | Z5: 吉星 | AA5: 1 | AB5: =Q54 -> 9684.0523
C6: 实际达成量 | D6: 82 | E6: 580 | F6: 213 | G6: 40 | J6: 50 | K6: 8 | L6: 10 | M6: =E6-E5 -> 57 | N6: 100 | P6: 1500 | Q6: =SUM(I5,J8,L8,N8) -> 7393.8611 | R6: =SUM(I5,J8,L8,N8,P6) -> 8893.8611 | T6: 2 | U6: G网 | V6: 吉星-西物 | W6: 视频运营专员 | X6: 专职 | Y6: 黄凤 | Z6: 吉星 | AA6: 1 | AB6: =Q46 -> 7240
B7: 吉星G-西物 | C7: 实际达成率 | D7: =D6/D5 -> 0.91111111 | E7: =E6/E5 -> 1.1089866 | F7: =F6/F5 -> 0.5325 | G7: =G6/G5 -> 1 | T7: 3 | U7: G网 | V7: 吉星-西物 | W7: 新媒体主播 | X7: 专职 | Y7: 曾子乂 | Z7: 西物 | AA7: 1 | AB7: =Q6 -> 7393.8611
C8: 考核分值数 | D8: 40 | E8: 40 | F8: 10 | G8: 10 | H8: =SUM(D8:G8) -> 100 | J8: =J6*K6 -> 400 | L8: =_xlfn.IFS(M6>=100,1000,M6<=100,M6*L6) -> 570 | N8: =_xlfn.IFS(O6>=5,500,O6<=5,O6*N6) -> 0 | T8: 4 | U8: L网 | V8: 吉星-超市 | W8: 新媒体主播 | X8: 专职 | Y8: 王芝婕 | Z8: 超市 | AA8: 1 | AB8: =Q25 -> 8672.25
B9: 曾子乂 | C9: 考核得分数 | D9: =IF(D7>=100%,D8*1,D8*D7) -> 36.444444 | E9: =IF(E7>=100%,E8*1,E8*E7) -> 40 | F9: =IF(F7>=100%,F8*1,F8*F7) -> 5.325 | G9: =IF(G7>=100%,G8*1,G8*G7) -> 10 | H9: =SUM(D9:G9) -> 91.769444 | T9: 5 | U9: L网 | V9: 吉星-超市 | W9: 新媒体主播 | X9: 专职 | Y9: 蓝仁楷 | Z9: 超市 | AA9: 1 | AB9: =Q34 -> 7768.6515
T10: 6 | U10: G网 | V10: 吉星-西物 | W10: 新媒体主播 | X10: 专职 | Y10: 何玉 | Z10: 西物G | AA10: 1 | AB10: =Q15 -> 9506
B11: 岗位 | C11: 项目 | D11: 直播场次 | E11: 直播线索 （仅限 小风车线索、直播复盘数据做参考） | F11: 直播粉丝关注量 （仅限 对应账户） | G11: 视频创作发布量 视频：40 小红书：20 | H11: 岗位绩效KPI | I11: 岗位绩效 | J11: 终端量提成（仅限 对应公司账户端量） | L11: 线索超额完成奖励 | N11: 直播场次超额奖励 | P11: 基本薪资 | Q11: 绩效薪资 | R11: 合计薪资 | T11: 7 | U11: G网 | W11: 新媒体运营 | X11: 兼职 | Y11: 赵金秀 | Z11: 吉星 | AA11: 1 | AB11: 3000
J12: 以月度目标制定 | K12: 终端完成 | L12: 超额部分10元/条 （上限1000元） | M12: 当月超额线索数 | N12: 超额部分100元/场 （上限500元） | O12: 直播超额 完成场次 | T12: 8
J13: 18 | T13: 9
B14: 直播运维专员 | C14: 月度目标量 | D14: 90 | E14: 500 | F14: 400 | G14: 40 | H14: 7000 | I14: =H18*H14% -> 6706 | J14: 完成100元/台； 未完成50元/台 | T14: 10
C15: 实际达成量 | D15: 90 | E15: 680 | F15: 232 | G15: 40 | J15: 100 | K15: 18 | L15: 10 | M15: =E15-E14 -> 180 | N15: 100 | P15: 1500 | Q15: =SUM(I14,J17,L17,N17) -> 9506 | R15: =SUM(I14,J17,L17,N17,P15) -> 11006 | T15: 11
B16: 吉星G-西物 | C16: 实际达成率 | D16: =D15/D14 -> 1 | E16: =E15/E14 -> 1.36 | F16: =F15/F14 -> 0.58 | G16: =G15/G14 -> 1 | T16: 12
C17: 考核分值数 | D17: 40 | E17: 40 | F17: 10 | G17: 10 | H17: =SUM(D17:G17) -> 100 | J17: =J15*K15 -> 1800 | L17: =_xlfn.IFS(M15>=100,1000,M15<=100,M15*L15) -> 1000 | N17: =_xlfn.IFS(O15>=5,500,O15<=5,O15*N15) -> 0 | T17: 13
B18: 何玉 | C18: 考核得分数 | D18: =IF(D16>=100%,D17*1,D17*D16) -> 40 | E18: =IF(E16>=100%,E17*1,E17*E16) -> 40 | F18: =IF(F16>=100%,F17*1,F17*F16) -> 5.8 | G18: =IF(G16>=100%,G17*1,G17*G16) -> 10 | H18: =SUM(D18:G18) -> 95.8 | T18: 14
T19: 15
T20: 16
B21: 岗位 | C21: 项目 | D21: 直播场次 | E21: 直播线索 （仅限 小风车线索、直播复盘数据做参考） | F21: 直播粉丝关注量 （仅限 对应账户） | G21: 视频创作发布量 | H21: 岗位绩效KPI | I21: 岗位绩效 | J21: 终端量提成（仅限 对应公司账户端量） | L21: 线索超额完成奖励 | N21: 直播场次超额奖励 | P21: 基本薪资 | Q21: 绩效薪资 | R21: 合计薪资 | T21: 17
J22: 以月度目标制定 | K22: 终端完成 | L22: 超额部分10元/条 （上限1000元） | M22: 当月超额线索数 | N22: 超额部分100元/场 （上限500元） | O22: 直播超额 完成场次 | T22: 18
J23: 16 | T23: 19
B24: 直播运维专员 | C24: 月度目标量 | D24: 90 | E24: 500 | F24: 400 | G24: 40 | H24: 7000 | I24: =H28*H24% -> 6872.25 | J24: 未完成50元/台 完成100元/台
C25: 实际达成量 | D25: 92 | E25: 616 | F25: 327 | G25: 400 | J25: 50 | K25: 12 | L25: 10 | M25: =E25-E24 -> 116 | N25: 100 | O25: =D25-D24 -> 2 | P25: 1500 | Q25: =SUM(I24,J27,L27,N27) -> 8672.25 | R25: =SUM(I24,J27,L27,N27,P25) -> 10172.25
B26: 吉星L-超市 | C26: 实际达成率 | D26: =D25/D24 -> 1.0222222 | E26: =E25/E24 -> 1.232 | F26: =F25/F24 -> 0.8175 | G26: =G25/G24 -> 10
C27: 考核分值数 | D27: 40 | E27: 40 | F27: 10 | G27: 10 | H27: =SUM(D27:G27) -> 100 | J27: =J25*K25 -> 600 | L27: =_xlfn.IFS(M25>=100,1000,M25<=100,M25*L25) -> 1000 | N27: =_xlfn.IFS(O25>=5,500,O25<=5,O25*N25) -> 200
B28: 王芝婕 | C28: 考核得分数 | D28: =IF(D26>=100%,D27*1,D27*D26) -> 40 | E28: =IF(E26>=100%,E27*1,E27*E26) -> 40 | F28: =IF(F26>=100%,F27*1,F27*F26) -> 8.175 | G28: =IF(G26>=100%,G27*1,G27*G26) -> 10 | H28: =SUM(D28:G28) -> 98.175
B30: 岗位 | C30: 项目 | D30: 直播场次 | E30: 直播线索 （仅限 小风车线索、直播复盘数据做参考） | F30: 直播粉丝关注量 （仅限 对应账户） | G30: 视频创作发布量 | H30: 岗位绩效KPI | I30: 岗位绩效 | J30: 终端量提成（仅限 对应公司账户端量） | L30: 线索超额完成奖励 | N30: 直播场次超额奖励 | P30: 基本薪资 | Q30: 绩效薪资 | R30: 合计薪资
J31: 以月度目标制定 | K31: 终端完成 | L31: 超额部分10元/条 （上限1000元） | M31: 当月超额线索数 | N31: 超额部分100元/场 （上限500元） | O31: 直播超额 完成场次
J32: 16
B33: 直播运维专员 | C33: 月度目标量 | D33: 90 | E33: 523 | F33: 400 | G33: 50 | H33: 7000 | I33: =H37*H33% -> 6718.6515 | J33: 未完成50元/台 完成100元/台
C34: 实际达成量 | D34: 95 | E34: 510 | F34: 279 | G34: 50 | J34: 50 | K34: 11 | L34: 10 | M34: 0 | N34: 100 | O34: =D34-D33 -> 5 | P34: 1500 | Q34: =SUM(I33,J36,L36,N36) -> 7768.6515 | R34: =SUM(I33,J36,L36,N36,P34) -> 9268.6515
B35: 吉星L—超市 | C35: 实际达成率 | D35: =D34/D33 -> 1.0555556 | E35: =E34/E33 -> 0.9751434 | F35: =F34/F33 -> 0.6975 | G35: =G34/G33 -> 1
C36: 考核分值数 | D36: 40 | E36: 40 | F36: 10 | G36: 10 | H36: =SUM(D36:G36) -> 100 | J36: =J34*K34 -> 550 | L36: =_xlfn.IFS(M34>=100,1000,M34<=100,M34*L34) -> 0 | N36: =_xlfn.IFS(O34>=5,500,O34<=5,O34*N34) -> 500
B37: 蓝仁楷 | C37: 考核得分数 | D37: =IF(D35>=100%,D36*1,D36*D35) -> 40 | E37: =IF(E35>=100%,E36*1,E36*E35) -> 39.005736 | F37: =IF(F35>=100%,F36*1,F36*F35) -> 6.975 | G37: =IF(G35>=100%,G36*1,G36*G35) -> 10 | H37: =SUM(D37:G37) -> 95.980736
B42: 岗位 | C42: 项目 | D42: 视频创作发布数 | E42: 播放量 | F42: 短视频粉丝关注量 | G42: 小红书笔记发布 | H42: 岗位绩效KPI | I42: 岗位绩效 | J42: 终端量提成（双账户合计量） | L42: 优质视频视频奖励≥30000播放量 | N42: 视频创作超额完成奖励 | P42: 基本薪资 | Q42: 绩效薪资 | R42: 合计薪资
J43: 以月度目标制定 | K43: 终端完成 | L43: 优质视频50元/条 （上限500元） | M43: 优质视频数量 | N43: 超额部分50元/条 (上限500元) | O43: 视频超额完成数
E44: 播放量≥3000 | J44: 55
B45: 视频运维专员 超市+西物视频 | C45: 月度目标量 | D45: 61 | E45: 20 | F45: 60 | G45: 16 | H45: 6000 | I45: =H49*H45% -> 5780 | J45: 未完成20元/台； 完成30元/台
...

Sheet 直营店经理提成 (财务)
D1: 直营店店面 | J1: 直营店二网
B2: 店别 | C2: 展厅任务销售台次 | D2: 展厅实际销售台次 | E2: 新能源展厅实际销售台次 | F2: 完成率 | G2: 单台提成标准 | H2: 单台提成金额 | I2: 渠道任务销售台次 | J2: 渠道实际销售台次 | K2: 新能源渠道任务销售台次 | L2: 完成率 | M2: 单台提成标准 | N2: 单台提成金额 | O2: 台次提成合计 | P2: 附加收入提成合计 | Q2: 固定绩效 | R2: 提成合计 | S2: 指定车型考核 | T2: 考核金额 | AN2: 序号 | AO2: 出库日期 | AP2: 客户姓名 | AQ2: 电话 | AR2: 按揭信息 | BA2: 贴息信息 | BF2: 上户地 | BG2: 销售部门 | BH2: 直营店经理 | BI2: 车架号 | BJ2: 直营店经理 奖励金额
B3: 崇州直营店 | C3: 26 | D3: =SUMIFS([5]绩效整理表!K:K,[5]绩效整理表!A:A,'直营店经理提成 (财务)'!B3,[5]绩效整理表!D:D,$D$1) -> 20 | F3: =IF(C3<>0,IF(D3/C3>110%,110%,D3/C3),0) -> 0.76923077 | G3: 100 | H3: =D3*F3*G3+E3*G3 -> 1538.4615 | I3: 1 | J3: =SUMIFS([5]绩效整理表!K:K,[5]绩效整理表!A:A,'直营店经理提成 (财务)'!B3,[5]绩效整理表!D:D,$J$1) -> 1 | L3: =IF(I3<>0,IF(J3/I3>110%,110%,J3/I3),0) -> 1 | M3: 50 | N3: =L3*M3*J3+K3*M3 -> 50 | O3: =H3+N3 -> 1588.4615 | P3: =V13 -> 1803.0265 | Q3: =2500 -> 2500 | R3: =SUM(O3:Q3)+V3 -> 5891.488 | AR3: 总车价 | AS3: 期数 | AT3: 产品 | AU3: 贷款金额 | AV3: 附加贷 | AW3: 首付金额 | AX3: 首付比例 | AY3: 车型 | AZ3: 金融公司 | BA3: 贴息 | BB3: 工厂贴息 | BC3: 金融公司 贴息 | BD3: 客户补息 | BE3: 我司贴息
B4: 大邑直营店 | C4: 15 | D4: =SUMIFS([5]绩效整理表!K:K,[5]绩效整理表!A:A,'直营店经理提成 (财务)'!B4,[5]绩效整理表!D:D,$D$1) -> 12 | F4: =IF(C4<>0,IF(D4/C4>110%,110%,D4/C4),0) -> 0.8 | G4: 100 | H4: =D4*F4*G4+E4*G4 -> 960 | I4: 1 | J4: =SUMIFS([5]绩效整理表!K:K,[5]绩效整理表!A:A,'直营店经理提成 (财务)'!B4,[5]绩效整理表!D:D,$J$1) -> 3 | L4: =IF(I4<>0,IF(J4/I4>110%,110%,J4/I4),0) -> 1.1 | M4: 50 | N4: =L4*M4*J4+K4*M4 -> 165 | O4: =H4+N4 -> 1125 | P4: =V14 -> 32.525 | Q4: =2500 -> 2500 | R4: =SUM(O4:Q4)+V4 -> 3657.525 | AN4: 1 | AO4: 46147 | AP4: 隆波 | AQ4: 18280124667 | AR4: 109200 | AS4: 60 | AT4: 60建行三支行(普通) | AU4: 55000 | AV4: 0 | AW4: 54200 | AX4: 0.5 | AY4: 星越L | AZ4: 建行三支行 | BA4: 是 | BF4: A成都 | BG4: 彭州直营店 | BH4: 黎明朗 | BI4: LB37852Z0TS027357 | BJ4: 200
B5: 华阳直营店 | C5: 23 | D5: =SUMIFS([5]绩效整理表!K:K,[5]绩效整理表!A:A,'直营店经理提成 (财务)'!B5,[5]绩效整理表!D:D,$D$1) -> 18 | F5: =IF(C5<>0,IF(D5/C5>110%,110%,D5/C5),0) -> 0.7826087 | G5: 100 | H5: =D5*F5*G5+E5*G5 -> 1408.6957 | I5: 1 | J5: =SUMIFS([5]绩效整理表!K:K,[5]绩效整理表!A:A,'直营店经理提成 (财务)'!B5,[5]绩效整理表!D:D,$J$1) -> 1 | L5: =IF(I5<>0,IF(J5/I5>110%,110%,J5/I5),0) -> 1 | M5: 50 | N5: =L5*M5*J5+K5*M5 -> 50 | O5: =H5+N5 -> 1458.6957 | P5: =V15 -> 472.921 | Q5: =2500 -> 2500 | R5: =SUM(O5:Q5)+V5 -> 4431.6167 | AN5: 2 | AO5: 46149 | AP5: 刘倩言 | AQ5: 15928646092 | AR5: 66900 | AS5: 60 | AT5: 60吉致(9.58%标贷) | AU5: 50900 | AV5: 0 | AW5: 16000 | AX5: 0.4 | AY5: 新博越 | AZ5: 吉致 | BA5: 否 | BF5: A成都 | BG5: 邛崃直营店 | BH5: 吴思超 | BI5: LB37722Z6TX316067 | BJ5: 200
B6: 华阳领克 | D6: =SUMIFS([5]绩效整理表!K:K,[5]绩效整理表!A:A,'直营店经理提成 (财务)'!B6,[5]绩效整理表!D:D,$D$1) -> 0 | F6: =IF(C6<>0,IF(D6/C6>110%,110%,D6/C6),0) -> 0 | G6: 100 | H6: =D6*F6*G6+E6*G6 -> 0 | J6: =SUMIFS([5]绩效整理表!K:K,[5]绩效整理表!A:A,'直营店经理提成 (财务)'!B6,[5]绩效整理表!D:D,$J$1) -> 0 | L6: =IF(I6<>0,IF(J6/I6>110%,110%,J6/I6),0) -> 0 | M6: 50 | N6: =L6*M6*J6+K6*M6 -> 0 | O6: =H6+N6 -> 0 | P6: =V16 -> 0 | R6: =SUM(O6:Q6)+V6 -> 0 | AN6: 3 | AO6: 46153 | AP6: 肖杨 | AQ6: 18884150929 | AR6: 69900 | AS6: 60 | AT6: 60吉致(安心宝) | AU6: 62500 | AV6: 0 | AW6: 7400 | AX6: 0.05 | AY6: 第5代帝豪 | AZ6: 吉致 | BA6: 是 | BB6: 1498.68 | BF6: A成都 | BG6: 崇州直营店 | BH6: 朱剑波 | BI6: LB37824Z1TG026166 | BJ6: 200
B7: 彭州直营店 | C7: 20 | D7: =SUMIFS([5]绩效整理表!K:K,[5]绩效整理表!A:A,'直营店经理提成 (财务)'!B7,[5]绩效整理表!D:D,$D$1) -> 23 | F7: =IF(C7<>0,IF(D7/C7>110%,110%,D7/C7),0) -> 1.1 | G7: 100 | H7: =D7*F7*G7+E7*G7 -> 2530 | I7: 1 | J7: =SUMIFS([5]绩效整理表!K:K,[5]绩效整理表!A:A,'直营店经理提成 (财务)'!B7,[5]绩效整理表!D:D,$J$1) -> 0 | L7: =IF(I7<>0,IF(J7/I7>110%,110%,J7/I7),0) -> 0 | M7: 50 | N7: =L7*M7*J7+K7*M7 -> 0 | O7: =H7+N7 -> 2530 | P7: =V17 -> 591.6875 | Q7: =2500+750 -> 3250 | R7: =SUM(O7:Q7)+V7 -> 6371.6875 | AN7: 4 | AO7: 46156 | AP7: 罗利华 | AQ7: 15328896389 | AR7: 90000 | AS7: 60 | AT7: 60吉致(安心宝) | AU7: 90000 | AV7: 0 | AW7: 0 | AX7: 0 | AY7: 第四代博越L | AZ7: 吉致 | BA7: 是 | BB7: 3000 | BF7: A成都 | BG7: 华阳直营店 | BH7: 钟涛 | BI7: LB37822Z7TB041979 | BJ7: 400
B8: 邛崃直营店 | C8: 16 | D8: =SUMIFS([5]绩效整理表!K:K,[5]绩效整理表!A:A,'直营店经理提成 (财务)'!B8,[5]绩效整理表!D:D,$D$1) -> 13 | F8: =IF(C8<>0,IF(D8/C8>110%,110%,D8/C8),0) -> 0.8125 | G8: 100 | H8: =D8*F8*G8+E8*G8 -> 1056.25 | I8: 1 | J8: 3 | L8: =IF(I8<>0,IF(J8/I8>110%,110%,J8/I8),0) -> 1.1 | M8: 50 | N8: =L8*M8*J8+K8*M8 -> 165 | O8: =H8+N8 -> 1221.25 | P8: =V18 -> 1058.7985 | Q8: =2500 -> 2500 | R8: =SUM(O8:Q8)+V8 -> 4780.0485 | AN8: 5 | AO8: 46158 | AP8: 濮寿邦 | AQ8: 13150771917 | AR8: 119200 | AS8: 60 | AT8: 60吉致(安心宝) | AU8: 105800 | AV8: 0 | AW8: 13400 | AX8: 0.25 | AY8: 星越L | AZ8: 吉致 | BA8: 是 | BB8: 3497.25 | BF8: A成都 | BG8: 崇州直营店 | BH8: 朱剑波 | BI8: LB37852ZXTS027950 | BJ8: 400
B9: 合计 | C9: =SUM(C3:C8) -> 100 | D9: =SUM(D3:D8) -> 86 | E9: =SUM(E3:E8) -> 0 | I9: =SUM(I3:I8) -> 5 | J9: =SUM(J3:J8) -> 8 | O9: =SUM(O3:O8) -> 7923.4072 | P9: =SUM(P3:P8) -> 3958.9585 | Q9: =SUM(Q3:Q8) -> 13250 | R9: =SUM(R3:R8) -> 25132.366 | AN9: 6 | AO9: 46159 | AP9: 何冉 | AQ9: 17882239391 | AR9: 97400 | AS9: 60 | AT9: 60吉致(安心宝) | AU9: 70000 | AV9: 0 | AW9: 27400 | AX9: 0.05 | AY9: 豪越L | AZ9: 吉致 | BA9: 是 | BB9: 1799 | BF9: A成都 | BG9: 崇州直营店 | BH9: 朱剑波 | BI9: L6T7922Z0TY871239 | BJ9: 300
AN10: 7 | AO10: 46164 | AP10: 唐庆 | AQ10: 15228814042 | AR10: 116700 | AS10: 60 | AT10: 60吉致(安心宝) | AU10: 100000 | AV10: 0 | AW10: 16700 | AX10: 0.25 | AY10: 星越L | AZ10: 吉致 | BA10: 是 | BB10: 3497.9 | BF10: A成都 | BG10: 华阳直营店 | BH10: 钟涛 | BI10: LB37852Z4TS040239 | BJ10: 400
AN11: 8 | AO11: 46164 | AP11: 黎智全 | AQ11: 13547726888 | AR11: 97400 | AS11: 60 | AT11: 60吉致(9.58%标贷) | AU11: 97400 | AV11: 0 | AW11: 0 | AX11: 0 | AY11: 豪越L | AZ11: 吉致 | BA11: 否 | BF11: A成都 | BG11: 彭州直营店 | BH11: 黎明朗 | BI11: L6T7922Z3SY852750 | BJ11: 400
B12: 店别 | C12: 展厅按提台次 | D12: 展厅实际销售台次 | E12: 渠道按提台次 | F12: 渠道实际销售台次 | G12: 展厅手续费实际金额 | H12: 展厅手续费标准金额（考核标准） | I12: 渠道手续费实际金额 | J12: 渠道手续费标准金额（考核标准） | K12: 爱车保毛利 | L12: 爱车保毛利标准 | M12: 上户费合计（扣出库）实际 | N12: 上户费合计（扣出库）标准 | O12: 整车超权限 | P12: 实际附加收入 | Q12: 标准附加收入 | R12: 差异 | S12: 盈利性渗透率 | T12: 盈利性渗透率 | U12: 盈利性提成金额 | V12: 新工资标准 | AN12: 9 | AO12: 46165 | AP12: 罗新华 | AQ12: 13880927112 | AR12: 80300 | AS12: 60 | AT12: 60吉致(安心宝) | AU12: 60000 | AV12: 0 | AW12: 20300 | AX12: 0.25 | AY12: 第四代博越L | AZ12: 吉致 | BA12: 是 | BB12: 2998.94 | BF12: A成都 | BG12: 华阳直营店 | BH12: 钟涛 | BI12: LB37822Z4TB044774 | BJ12: 200
A13: 朱剑波 | B13: 崇州直营店 | C13: =SUMIFS([5]按揭明细!V:V,[5]按揭明细!C:C,B13,[5]按揭明细!BE:BE,$D$1) -> 12 | D13: =D3 -> 20 | E13: =SUMIFS([5]按揭明细!V:V,[5]按揭明细!C:C,B13,[5]按揭明细!BE:BE,$J$1) -> 0 | F13: =J3 -> 1 | G13: =SUMIFS([5]按揭明细!Y:Y,[5]按揭明细!C:C,B13,[5]按揭明细!BE:BE,$D$1) -> 3000 | H13: =D13*0.55*283 -> 3113 | I13: =SUMIFS([5]按揭明细!Y:Y,[5]按揭明细!C:C,B13,[5]按揭明细!BE:BE,$J$1) -> 0 | J13: =F13*0.3*170 -> 51 | K13: =SUMIFS([5]爱车保!N:N,[5]爱车保!BC:BC,B13) -> 9 | L13: =D13*0.3*1085 -> 6510 | M13: =SUMIFS([5]上户提成!G:G,[5]上户提成!A:A,B13) -> 22706.73 | N13: =D13*552*1.06 -> 11702.4 | P13: =G13+I13+K13+M13+O13 -> 25715.73 | Q13: =H13+J13+L13+N13 -> 21376.4 | R13: =P13-Q13 -> 4339.33 | S13: 0.435 | T13: 0.25 | U13: =IF(D13>0,ROUND((IF(T13/S13>110%,SUMIF(BH:BH,A13,BJ:BJ)*110%,SUMIF(BH:BH,A13,BJ:BJ)*(T13/S13))),2),0) -> 517.24 | V13: =IF(R13<=0,(P13+R13)*0.05,P13*0.05)+U13 -> 1803.0265 | W13: =P13-Q13 -> 4339.33 | X13: 3757.809 | AN13: 10 | AO13: 46169 | AP13: 张志友 | AQ13: 13508233497 | AR13: 70700 | AS13: 60 | AT13: 60吉致(安心宝) | AU13: 50000 | AV13: 0 | AW13: 20700 | AX13: 0.3 | AY13: 星瑞(1.5T) | AZ13: 吉致 | BA13: 是 | BB13: 2000 | BF13: A成都 | BG13: 彭州直营店 | BH13: 黎明朗 | BI13: L6T7924Z9TD052802 | BJ13: 200
A14: 孙伟 | B14: 大邑直营店 | C14: =SUMIFS([5]按揭明细!V:V,[5]按揭明细!C:C,B14,[5]按揭明细!BE:BE,$D$1) -> 4 | D14: =D4 -> 12 | E14: =SUMIFS([5]按揭明细!V:V,[5]按揭明细!C:C,B14,[5]按揭明细!BE:BE,$J$1) -> 2 | F14: =J4 -> 3 | G14: =SUMIFS([5]按揭明细!Y:Y,[5]按揭明细!C:C,B14,[5]按揭明细!BE:BE,$D$1) -> 0 | H14: =D14*0.55*283 -> 1867.8 | I14: =SUMIFS([5]按揭明细!Y:Y,[5]按揭明细!C:C,B14,[5]按揭明细!BE:BE,$J$1) -> 1000 | J14: =F14*0.3*170 -> 153 | K14: =SUMIFS([5]爱车保!N:N,[5]爱车保!BC:BC,B14) -> 3 | L14: =D14*0.3*1085 -> 3906 | M14: =SUMIFS([5]上户提成!G:G,[5]上户提成!A:A,B14) -> 5796.37 | N14: =D14*552*1.06 -> 7021.44 | P14: =G14+I14+K14+M14+O14 -> 6799.37 | Q14: =H14+J14+L14+N14 -> 12948.24 | R14: =P14-Q14 -> -6148.87 | S14: 0.435 | T14: 0 | U14: =IF(D14>0,ROUND((IF(T14/S14>110%,SUMIF(BH:BH,A14,BJ:BJ)*110%,SUMIF(BH:BH,A14,BJ:BJ)*(T14/S14))),2),0) -> 0 | V14: =IF(R14<=0,(P14+R14)*0.05,P14*0.05)+U14 -> 32.525 | W14: =P14-Q14 -> -6148.87 | X14: 2502.476 | AN14: 11 | AO14: 46169 | AP14: 陈静 | AQ14: 15390030053 | AR14: 91700 | AS14: 60 | AT14: 60吉致(安心宝) | AU14: 91700 | AV14: 0 | AW14: 0 | AX14: 0 | AY14: 星瑞(1.5T) | AZ14: 吉致 | BA14: 是 | BB14: 1999.24 | BF14: A成都 | BG14: 邛崃直营店 | BH14: 吴思超 | BI14: L6T7924Z3TD056019 | BJ14: 400
A15: 钟涛 | B15: 华阳直营店 | C15: =SUMIFS([5]按揭明细!V:V,[5]按揭明细!C:C,B15,[5]按揭明细!BE:BE,$D$1) -> 13 | D15: =D5 -> 18 | E15: =SUMIFS([5]按揭明细!V:V,[5]按揭明细!C:C,B15,[5]按揭明细!BE:BE,$J$1) -> 1 | F15: =J5 -> 1 | G15: =SUMIFS([5]按揭明细!Y:Y,[5]按揭明细!C:C,B15,[5]按揭明细!BE:BE,$D$1) -> 0 | H15: =D15*0.55*283 -> 2801.7 | I15: =SUMIFS([5]按揭明细!Y:Y,[5]按揭明细!C:C,B15,[5]按揭明细!BE:BE,$J$1) -> 200 | J15: =F15*0.3*170 -> 51 | K15: =SUMIFS([5]爱车保!N:N,[5]爱车保!BC:BC,B15) -> 1 | L15: =D15*0.3*1085 -> 5859 | M15: =SUMIFS([5]上户提成!G:G,[5]上户提成!A:A,B15) -> 8862.74 | N15: =D15*552*1.06 -> 10532.16 | P15: =G15+I15+K15+M15+O15 -> 9063.74 | Q15: =H15+J15+L15+N15 -> 19243.86 | R15: =P15-Q15 -> -10180.12 | S15: 0.435 | T15: 0.23 | U15: =IF(D15>0,ROUND((IF(T15/S15>110%,SUMIF(BH:BH,A15,BJ:BJ)*110%,SUMIF(BH:BH,A15,BJ:BJ)*(T15/S15))),2),0) -> 528.74 | V15: =IF(R15<=0,(P15+R15)*0.05,P15*0.05)+U15 -> 472.921 | W15: =P15-Q15 -> -10180.12 | X15: 957.385
B16: 华阳领克 | C16: =SUMIFS([5]按揭明细!V:V,[5]按揭明细!C:C,B16,[5]按揭明细!BE:BE,$D$1) -> 0 | D16: =D6 -> 0 | E16: =SUMIFS([5]按揭明细!V:V,[5]按揭明细!C:C,B16,[5]按揭明细!BE:BE,$J$1) -> 0 | F16: =J6 -> 0 | G16: =SUMIFS([5]按揭明细!Y:Y,[5]按揭明细!C:C,B16,[5]按揭明细!BE:BE,$D$1) -> 0 | H16: =D16*0.55*283 -> 0 | I16: =SUMIFS([5]按揭明细!Y:Y,[5]按揭明细!C:C,B16,[5]按揭明细!BE:BE,$J$1) -> 0 | J16: =F16*0.3*170 -> 0 | K16: =SUMIFS([5]爱车保!N:N,[5]爱车保!BC:BC,B16) -> 0 | L16: =D16*0.3*1085 -> 0 | M16: =SUMIFS([5]上户提成!G:G,[5]上户提成!A:A,B16) -> 0 | N16: =D16*552*1.06 -> 0 | O16: =SUMIFS([5]绩效整理表!Y:Y,[5]绩效整理表!A:A,'直营店经理提成 (财务)'!B16,[5]绩效整理表!D:D,$D$1) -> 0 | P16: =G16+I16+K16+M16+O16 -> 0 | Q16: =H16+J16+L16+N16 -> 0 | R16: 3 | U16: =IF(D16>0,ROUND((IF(T16/S16>110%,SUMIF(BH:BH,A16,BJ:BJ)*110%,SUMIF(BH:BH,A16,BJ:BJ)*(T16/S16))),2),0) -> 0 | V16: =IF(R16<=0,(P16+R16)*0.05,P16*0.05)+U16 -> 0 | W16: =P16-Q16 -> 0 | X16: 0
A17: 黎明朗 | B17: 彭州直营店 | C17: =SUMIFS([5]按揭明细!V:V,[5]按揭明细!C:C,B17,[5]按揭明细!BE:BE,$D$1) -> 9 | D17: =D7 -> 23 | E17: =SUMIFS([5]按揭明细!V:V,[5]按揭明细!C:C,B17,[5]按揭明细!BE:BE,$J$1) -> 0 | F17: =J7 -> 0 | G17: =SUMIFS([5]按揭明细!Y:Y,[5]按揭明细!C:C,B17,[5]按揭明细!BE:BE,$D$1) -> 0 | H17: =D17*0.55*283 -> 3579.95 | I17: =SUMIFS([5]按揭明细!Y:Y,[5]按揭明细!C:C,B17,[5]按揭明细!BE:BE,$J$1) -> 0 | J17: =F17*0.3*170 -> 0 | K17: =SUMIFS([5]爱车保!N:N,[5]爱车保!BC:BC,B17) -> 5 | L17: =D17*0.3*1085 -> 7486.5 | M17: =SUMIFS([5]上户提成!G:G,[5]上户提成!A:A,B17) -> 14127.98 | N17: =D17*552*1.06 -> 13457.76 | P17: =G17+I17+K17+M17+O17 -> 14132.98 | Q17: =H17+J17+L17+N17 -> 24524.21 | R17: =P17-Q17 -> -10391.23 | S17: 0.435 | T17: 0.22 | U17: =IF(D17>0,ROUND((IF(T17/S17>110%,SUMIF(BH:BH,A17,BJ:BJ)*110%,SUMIF(BH:BH,A17,BJ:BJ)*(T17/S17))),2),0) -> 404.6 | V17: =IF(R17<=0,(P17+R17)*0.05,P17*0.05)+U17 -> 591.6875 | W17: =P17-Q17 -> -10391.23 | X17: 4616.64
A18: 吴思超 | B18: 邛崃直营店 | C18: =SUMIFS([5]按揭明细!V:V,[5]按揭明细!C:C,B18,[5]按揭明细!BE:BE,$D$1) -> 3 | D18: =D8 -> 13 | E18: =SUMIFS([5]按揭明细!V:V,[5]按揭明细!C:C,B18,[5]按揭明细!BE:BE,$J$1) -> 0 | F18: =J8 -> 3 | G18: =SUMIFS([5]按揭明细!Y:Y,[5]按揭明细!C:C,B18,[5]按揭明细!BE:BE,$D$1) -> 500 | H18: =D18*0.55*283 -> 2023.45 | I18: =SUMIFS([5]按揭明细!Y:Y,[5]按揭明细!C:C,B18,[5]按揭明细!BE:BE,$J$1) -> 0 | J18: =F18*0.3*170 -> 153 | K18: =SUMIFS([5]爱车保!N:N,[5]爱车保!BC:BC,B18) -> 1 | L18: =D18*0.3*1085 -> 4231.5 | M18: =SUMIFS([5]上户提成!G:G,[5]上户提成!A:A,B18) -> 10494.24 | N18: =D18*552*1.06 -> 7606.56 | P18: =G18+I18+K18+M18+O18 -> 10995.24 | Q18: =H18+J18+L18+N18 -> 14014.51 | R18: =P18-Q18 -> -3019.27 | S18: 0.435 | T18: 0.67 | U18: =IF(D18>0,ROUND((IF(T18/S18>110%,SUMIF(BH:BH,A18,BJ:BJ)*110%,SUMIF(BH:BH,A18,BJ:BJ)*(T18/S18))),2),0) -> 660 | V18: =IF(R18<=0,(P18+R18)*0.05,P18*0.05)+U18 -> 1058.7985 | W18: =P18-Q18 -> -3019.27 | X18: 1457.015
B19: 合计 | C19: =SUM(C13:C18) -> 41 | D19: =SUM(D13:D18) -> 86 | E19: =SUM(E13:E18) -> 3 | F19: =SUM(F13:F18) -> 8 | G19: =SUM(G13:G18) -> 3500 | H19: =SUM(H13:H18) -> 13385.9 | I19: =SUM(I13:I18) -> 1200 | J19: =SUM(J13:J18) -> 408 | ... O19: =SUM(O13:O18) -> 0 | P19: =G19+I19+K19+M19+O19 -> 66707.06 | Q19: =H19+J19+L19+N19 -> 92107.22 | R19: =SUM(R13:R18) -> -25397.16 | U19: =SUM(U13:U18) -> 2110.58 | V19: =SUM(V13:V18) -> 3958.9585 | W19: =SUM(W13:W18) -> -25400.16 | X19: =SUM(X13:X18) -> 13291.325
X20: =IF(V20<=0,(R20+V20)*0.05,R20*0.05) -> 0
