Workbook
Name 备件类: #REF!
Name 服务质量: [1]基础参数勿删!$E$6:$E$14
Name 颜色: [2]菜单!$C$2:$C$15

Sheet 05月提成-武侯售后
A1: 2026年05月成都吉利汽车超市工资明细表（售后）
A2: 编制：人事部
A3: 序号 | B3: 部门 | C3: 姓 名 | D3: 其他补贴 | E3: 单位社保 | F3: 个人社保 | G3: 个人公积金 | H3: 其它 | I3: 基本工资 | J3: 其中： 加班工资 | K3: 当月应计提绩效 | L3: 综合考核/其他 | M3: 应付提 成工资 | N3: 代扣社保 | O3: 实付提成 | P3: 其它 | Q3: 已发并税 | R3: 计税工资 | S3: 代扣个税 | V3: 其他(代扣项) | W3: 实发提成 | X3: 备注 | Y3: 留存 合计 | Z3: 留存1 | AA3: 留存2 | AF3: 其他部门 | AG3: 车间 | AH3: 业务
S4: 应扣税 | T4: 已扣税 | U4: 实际扣税 | Y4: 留存 | Z4: 留存 | AA4: 留存 | AB4: 姓名 | AC4: 累计应补(退)税额 | AF4: =SUMIF('05月其他部门提成'!C:C,'05月提成-武侯售后'!C4,'05月其他部门提成'!Q:Q) -> 0 | AH4: =SUMIF('05月业务提成'!B:B,'05月提成-武侯售后'!C4,'05月业务提成'!BO:BO) -> 0
A5: 1 | B5: 管理部 | C5: 曹磊 | D5: =INDEX('05基本'!I:I,MATCH(C5,'05基本'!C:C,0))+INDEX('05基本'!J:J,MATCH(C5,'05基本'!C:C,0)) -> 0 | E5: =INDEX('05基本'!AA:AA,MATCH(C5,'05基本'!C:C,0)) -> 1497.5 | F5: =INDEX('05基本'!AB:AB,MATCH(C5,'05基本'!C:C,0)) -> 572 | G5: =INDEX('05基本'!AC:AC,MATCH(C5,'05基本'!C:C,0)) -> 117 | H5: =INDEX('05基本'!K:K,MATCH(C5,'05基本'!C:C,0))+INDEX('05基本'!L:L,MATCH(C5,'05基本'!C:C,0)) -> 1000 | I5: =INDEX('05基本'!P:P,MATCH(C5,'05基本'!C:C,0)) -> 8000 | J5: =INDEX('05基本'!M:M,MATCH(C5,'05基本'!C:C,0)) -> 1000 | K5: =INDEX('05月其他部门提成'!Q:Q,MATCH(C5,'05月其他部门提成'!C:C,0)) -> 8666.6667 | L5: =SUMIF(综合考核!A:A,'05月提成-武侯售后'!C5,综合考核!M:M) -> 0 | M5: =SUM(K5:L5) -> 8666.6667 | N5: =SUMIF(服装扣款!C:C,C5,服装扣款!N:N) -> 0 | O5: =M5-N5 -> 8666.6667 | P5: =SUMIF(超市公积金!C:C,'05月提成-武侯售后'!C5,超市公积金!I:I) -> 0 | Q5: =SUMIF(综合考核!A:A,'05月提成-武侯售后'!C5,综合考核!N:N) -> 0 | R5: =M5+I5+Q5 -> 16666.667 | S5: =INDEX(AC:AC,MATCH(C5,AB:AB,0)) -> 797.76 | U5: =S5-T5 -> 797.76 | V5: =INDEX('05基本'!AF:AF,MATCH(C5,'05基本'!C:C,0)) -> 0 | W5: =O5-P5-U5 -> 7868.9067 | Z5: 3566.67 | AB5: 曹磊 | AC5: 797.76 | AD5: =COUNTIF(C:C,C5) -> 1 | AE5: =INDEX('05基本'!P:P,MATCH(C5,'05基本'!C:C,0))-I5 -> 0 | AF5: =SUMIF('05月其他部门提成'!C:C,'05月提成-武侯售后'!C5,'05月其他部门提成'!Q:Q) -> 8666.6667 | AG5: =SUMIF('05月车间提成'!C:C,'05月提成-武侯售后'!C5,'05月车间提成'!W:W) -> 0 | AH5: =SUMIF('05月业务提成'!B:B,'05月提成-武侯售后'!C5,'05月业务提成'!BO:BO) -> 0 | AI5: =AF5+AG5+AH5 -> 8666.6667 | AJ5: =AI5-K5 -> 0
A6: 2 | C6: 曾吉斌 | D6: =INDEX('05基本'!I:I,MATCH(C6,'05基本'!C:C,0))+INDEX('05基本'!J:J,MATCH(C6,'05基本'!C:C,0)) -> 0 | E6: =INDEX('05基本'!AA:AA,MATCH(C6,'05基本'!C:C,0)) -> 1748.5 | F6: =INDEX('05基本'!AB:AB,MATCH(C6,'05基本'!C:C,0)) -> 676 | G6: =INDEX('05基本'!AC:AC,MATCH(C6,'05基本'!C:C,0)) -> 117 | H6: =INDEX('05基本'!K:K,MATCH(C6,'05基本'!C:C,0))+INDEX('05基本'!L:L,MATCH(C6,'05基本'!C:C,0)) -> 1000 | I6: =INDEX('05基本'!P:P,MATCH(C6,'05基本'!C:C,0)) -> 10000 | J6: =INDEX('05基本'!M:M,MATCH(C6,'05基本'!C:C,0)) -> 1000 | K6: =INDEX('05月其他部门提成'!Q:Q,MATCH(C6,'05月其他部门提成'!C:C,0)) -> 10833.33 | L6: =SUMIF(综合考核!A:A,'05月提成-武侯售后'!C6,综合考核!M:M) -> 0 | M6: =SUM(K6:L6) -> 10833.33 | N6: =SUMIF(服装扣款!C:C,C6,服装扣款!N:N) -> 0 | O6: =M6-N6 -> 10833.33 | P6: =SUMIF(超市公积金!C:C,'05月提成-武侯售后'!C6,超市公积金!I:I) -> 0 | Q6: =SUMIF(综合考核!A:A,'05月提成-武侯售后'!C6,综合考核!N:N) -> 0 | R6: =M6+I6+Q6 -> 20833.33 | S6: =INDEX(AC:AC,MATCH(C6,AB:AB,0)) -> 1504.03 | U6: =S6-T6 -> 1504.03 | V6: =INDEX('05基本'!AF:AF,MATCH(C6,'05基本'!C:C,0)) -> 0 | W6: =O6-P6-U6 -> 9329.3 | AB6: 曾吉斌 | AC6: 1504.03 | AD6: =COUNTIF(C:C,C6) -> 1 | AE6: =INDEX('05基本'!P:P,MATCH(C6,'05基本'!C:C,0))-I6 -> 0 | AF6: =SUMIF('05月其他部门提成'!C:C,'05月提成-武侯售后'!C6,'05月其他部门提成'!Q:Q) -> 10833.33 | AG6: =SUMIF('05月车间提成'!C:C,'05月提成-武侯售后'!C6,'05月车间提成'!W:W) -> 0 | AH6: =SUMIF('05月业务提成'!B:B,'05月提成-武侯售后'!C6,'05月业务提成'!BO:BO) -> 0 | AI6: =AF6+AG6+AH6 -> 10833.33 | AJ6: =AI6-K6 -> 0
A7: 3 | C7: 谢尧江 | D7: =INDEX('05基本'!I:I,MATCH(C7,'05基本'!C:C,0))+INDEX('05基本'!J:J,MATCH(C7,'05基本'!C:C,0)) -> 0 | E7: =INDEX('05基本'!AA:AA,MATCH(C7,'05基本'!C:C,0)) -> 1372 | F7: =INDEX('05基本'!AB:AB,MATCH(C7,'05基本'!C:C,0)) -> 520 | G7: =INDEX('05基本'!AC:AC,MATCH(C7,'05基本'!C:C,0)) -> 117 | H7: =INDEX('05基本'!K:K,MATCH(C7,'05基本'!C:C,0))+INDEX('05基本'!L:L,MATCH(C7,'05基本'!C:C,0)) -> 100 | I7: =INDEX('05基本'!P:P,MATCH(C7,'05基本'!C:C,0)) -> 1700 | J7: =INDEX('05基本'!M:M,MATCH(C7,'05基本'!C:C,0)) -> 0 | K7: =INDEX('05月其他部门提成'!Q:Q,MATCH(C7,'05月其他部门提成'!C:C,0)) -> 11763.001 | L7: =SUMIF(综合考核!A:A,'05月提成-武侯售后'!C7,综合考核!M:M) -> 0 | M7: =SUM(K7:L7) -> 11763.001 | N7: =SUMIF(服装扣款!C:C,C7,服装扣款!N:N) -> 0 | O7: =M7-N7 -> 11763.001 | P7: =SUMIF(超市公积金!C:C,'05月提成-武侯售后'!C7,超市公积金!I:I) -> 0 | Q7: =SUMIF(综合考核!A:A,'05月提成-武侯售后'!C7,综合考核!N:N) -> 0 | R7: =M7+I7+Q7 -> 13463.001 | S7: =INDEX(AC:AC,MATCH(C7,AB:AB,0)) -> 782.6 | U7: =S7-T7 -> 782.6 | V7: =INDEX('05基本'!AF:AF,MATCH(C7,'05基本'!C:C,0)) -> 0 | W7: =O7-P7-U7 -> 10980.401 | Z7: ='05月其他部门提成'!R9 -> 116.09792 | AB7: 谢尧江 | AC7: 782.6 | AD7: =COUNTIF(C:C,C7) -> 1 | AE7: =INDEX('05基本'!P:P,MATCH(C7,'05基本'!C:C,0))-I7 -> 0 | AF7: =SUMIF('05月其他部门提成'!C:C,'05月提成-武侯售后'!C7,'05月其他部门提成'!Q:Q) -> 11763.001 | AG7: =SUMIF('05月车间提成'!C:C,'05月提成-武侯售后'!C7,'05月车间提成'!W:W) -> 0 | AH7: =SUMIF('05月业务提成'!B:B,'05月提成-武侯售后'!C7,'05月业务提成'!BO:BO) -> 0 | AI7: =AF7+AG7+AH7 -> 11763.001 | AJ7: =AI7-K7 -> 0
C8: 小计 | D8: =SUM(D5:D7) -> 0 | E8: =SUM(E5:E7) -> 4618 | F8: =SUM(F5:F7) -> 1768 | G8: =SUM(G5:G7) -> 351 | H8: =SUM(H5:H7) -> 2100 | I8: =SUM(I5:I7) -> 19700 | J8: =SUM(J5:J7) -> 2000 | K8: =SUM(K5:K7) -> 31262.998 | ... AA8: =SUM(AA5:AA7) -> 0 | AB8: 张敏 | AC8: 0 | AD8: =COUNTIF(C:C,C8) -> 11 | AE8: =INDEX('05基本'!P:P,MATCH(C8,'05基本'!C:C,0))-I8 -> #N/A
A9: =A7+1 -> 4 | B9: 财务部 | C9: 张敏 | D9: =INDEX('05基本'!I:I,MATCH(C9,'05基本'!C:C,0))+INDEX('05基本'!J:J,MATCH(C9,'05基本'!C:C,0)) -> 200 | E9: =INDEX('05基本'!AA:AA,MATCH(C9,'05基本'!C:C,0)) -> 1268.59 | F9: =INDEX('05基本'!AB:AB,MATCH(C9,'05基本'!C:C,0)) -> 477.15 | G9: =INDEX('05基本'!AC:AC,MATCH(C9,'05基本'!C:C,0)) -> 117 | H9: =INDEX('05基本'!K:K,MATCH(C9,'05基本'!C:C,0))+INDEX('05基本'!L:L,MATCH(C9,'05基本'!C:C,0)) -> 0 | I9: =INDEX('05基本'!P:P,MATCH(C9,'05基本'!C:C,0)) -> 2200 | J9: =INDEX('05基本'!M:M,MATCH(C9,'05基本'!C:C,0)) -> 0 | K9: =INDEX('05月其他部门提成'!Q:Q,MATCH(C9,'05月其他部门提成'!C:C,0)) -> 6328.2846 | L9: =SUMIF(综合考核!A:A,'05月提成-武侯售后'!C9,综合考核!M:M) -> 0 | M9: =SUM(K9:L9) -> 6328.2846 | N9: =SUMIF(服装扣款!C:C,C9,服装扣款!N:N) -> 0 | O9: =M9-N9 -> 6328.2846 | P9: =SUMIF(超市公积金!C:C,'05月提成-武侯售后'!C9,超市公积金!I:I) -> 0 | Q9: =SUMIF(综合考核!A:A,'05月提成-武侯售后'!C9,综合考核!N:N) -> 0 | R9: =M9+I9+Q9 -> 8528.2846 | S9: =INDEX(AC:AC,MATCH(C9,AB:AB,0)) -> 0 | U9: =S9-T9 -> 0 | V9: =INDEX('05基本'!AF:AF,MATCH(C9,'05基本'!C:C,0)) -> 0 | W9: =O9-P9-U9 -> 6328.2846 | Y9: =SUM(Z9:AA9) -> 416.66667 | Z9: =INDEX('05月其他部门提成'!S:S,MATCH(C9,'05月其他部门提成'!C:C,0)) -> 416.66667 | AB9: 邱小艳 | AC9: 26.11 | AD9: =COUNTIF(C:C,C9) -> 1 | AE9: =INDEX('05基本'!P:P,MATCH(C9,'05基本'!C:C,0))-I9 -> 0 | AF9: =SUMIF('05月其他部门提成'!C:C,'05月提成-武侯售后'!C9,'05月其他部门提成'!Q:Q) -> 6328.2846 | AG9: =SUMIF('05月车间提成'!C:C,'05月提成-武侯售后'!C9,'05月车间提成'!W:W) -> 0 | AH9: =SUMIF('05月业务提成'!B:B,'05月提成-武侯售后'!C9,'05月业务提成'!BO:BO) -> 0 | AI9: =AF9+AG9+AH9 -> 6328.2846 | AJ9: =AI9-K9 -> 0
A10: =A9+1 -> 5 | C10: 邱小艳 | D10: =INDEX('05基本'!I:I,MATCH(C10,'05基本'!C:C,0))+INDEX('05基本'!J:J,MATCH(C10,'05基本'!C:C,0)) -> 0 | E10: =INDEX('05基本'!AA:AA,MATCH(C10,'05基本'!C:C,0)) -> 1268.59 | F10: =INDEX('05基本'!AB:AB,MATCH(C10,'05基本'!C:C,0)) -> 477.15 | G10: =INDEX('05基本'!AC:AC,MATCH(C10,'05基本'!C:C,0)) -> 117 | H10: =INDEX('05基本'!K:K,MATCH(C10,'05基本'!C:C,0))+INDEX('05基本'!L:L,MATCH(C10,'05基本'!C:C,0)) -> 0 | I10: =INDEX('05基本'!P:P,MATCH(C10,'05基本'!C:C,0)) -> 2000 | J10: =INDEX('05基本'!M:M,MATCH(C10,'05基本'!C:C,0)) -> 0 | K10: =INDEX('05月其他部门提成'!Q:Q,MATCH(C10,'05月其他部门提成'!C:C,0)) -> 4464.7607 | L10: =SUMIF(综合考核!A:A,'05月提成-武侯售后'!C10,综合考核!M:M) -> 0 | M10: =SUM(K10:L10) -> 4464.7607 | N10: =SUMIF(服装扣款!C:C,C10,服装扣款!N:N) -> 0 | O10: =M10-N10 -> 4464.7607 | P10: =SUMIF(超市公积金!C:C,'05月提成-武侯售后'!C10,超市公积金!I:I) -> 0 | Q10: =SUMIF(综合考核!A:A,'05月提成-武侯售后'!C10,综合考核!N:N) -> 0 | R10: =M10+I10+Q10 -> 6464.7607 | S10: =INDEX(AC:AC,MATCH(C10,AB:AB,0)) -> 26.11 | U10: =S10-T10 -> 26.11 | V10: =INDEX('05基本'!AF:AF,MATCH(C10,'05基本'!C:C,0)) -> 0 | W10: =O10-P10-U10 -> 4438.6507 | Y10: =SUM(Z10:AA10) -> 216.66667 | Z10: =INDEX('05月其他部门提成'!S:S,MATCH(C10,'05月其他部门提成'!C:C,0)) -> 216.66667 | AB10: 潘倩 | AC10: 18.71 | AD10: =COUNTIF(C:C,C10) -> 1 | AE10: =INDEX('05基本'!P:P,MATCH(C10,'05基本'!C:C,0))-I10 -> 0 | AF10: =SUMIF('05月其他部门提成'!C:C,'05月提成-武侯售后'!C10,'05月其他部门提成'!Q:Q) -> 4464.7607 | AG10: =SUMIF('05月车间提成'!C:C,'05月提成-武侯售后'!C10,'05月车间提成'!W:W) -> 0 | AH10: =SUMIF('05月业务提成'!B:B,'05月提成-武侯售后'!C10,'05月业务提成'!BO:BO) -> 0 | AI10: =AF10+AG10+AH10 -> 4464.7607 | AJ10: =AI10-K10 -> 0
A11: =A10+1 -> 6 | C11: 潘倩 | D11: =INDEX('05基本'!I:I,MATCH(C11,'05基本'!C:C,0))+INDEX('05基本'!J:J,MATCH(C11,'05基本'!C:C,0)) -> 0 | E11: =INDEX('05基本'!AA:AA,MATCH(C11,'05基本'!C:C,0)) -> 1268.59 | F11: =INDEX('05基本'!AB:AB,MATCH(C11,'05基本'!C:C,0)) -> 477.15 | G11: =INDEX('05基本'!AC:AC,MATCH(C11,'05基本'!C:C,0)) -> 117 | H11: =INDEX('05基本'!K:K,MATCH(C11,'05基本'!C:C,0))+INDEX('05基本'!L:L,MATCH(C11,'05基本'!C:C,0)) -> 0 | I11: =INDEX('05基本'!P:P,MATCH(C11,'05基本'!C:C,0)) -> 2000 | J11: =INDEX('05基本'!M:M,MATCH(C11,'05基本'!C:C,0)) -> 0 | K11: =INDEX('05月其他部门提成'!Q:Q,MATCH(C11,'05月其他部门提成'!C:C,0)) -> 4217.8873 | L11: =SUMIF(综合考核!A:A,'05月提成-武侯售后'!C11,综合考核!M:M) -> 0 | M11: =SUM(K11:L11) -> 4217.8873 | N11: =SUMIF(服装扣款!C:C,C11,服装扣款!N:N) -> 0 | O11: =M11-N11 -> 4217.8873 | P11: =SUMIF(超市公积金!C:C,'05月提成-武侯售后'!C11,超市公积金!I:I) -> 0 | Q11: =SUMIF(综合考核!A:A,'05月提成-武侯售后'!C11,综合考核!N:N) -> 0 | R11: =M11+I11+Q11 -> 6217.8873 | S11: =INDEX(AC:AC,MATCH(C11,AB:AB,0)) -> 18.71 | U11: =S11-T11 -> 18.71 | V11: =INDEX('05基本'!AF:AF,MATCH(C11,'05基本'!C:C,0)) -> 0 | W11: =O11-P11-U11 -> 4199.1773 | Y11: =SUM(Z11:AA11) -> 216.66667 | Z11: =INDEX('05月其他部门提成'!S:S,MATCH(C11,'05月其他部门提成'!C:C,0)) -> 216.66667 | AB11: 唐玉屏 | AC11: 28.46 | AD11: =COUNTIF(C:C,C11) -> 1 | AE11: =INDEX('05基本'!P:P,MATCH(C11,'05基本'!C:C,0))-I11 -> 0 | AF11: =SUMIF('05月其他部门提成'!C:C,'05月提成-武侯售后'!C11,'05月其他部门提成'!Q:Q) -> 4217.8873 | AG11: =SUMIF('05月车间提成'!C:C,'05月提成-武侯售后'!C11,'05月车间提成'!W:W) -> 0 | AH11: =SUMIF('05月业务提成'!B:B,'05月提成-武侯售后'!C11,'05月业务提成'!BO:BO) -> 0 | AI11: =AF11+AG11+AH11 -> 4217.8873 | AJ11: =AI11-K11 -> 0
A12: =A11+1 -> 7 | B12: 业务部 | C12: 唐玉屏 | D12: =INDEX('05基本'!I:I,MATCH(C12,'05基本'!C:C,0))+INDEX('05基本'!J:J,MATCH(C12,'05基本'!C:C,0)) -> 0 | E12: =INDEX('05基本'!AA:AA,MATCH(C12,'05基本'!C:C,0)) -> 1268.59 | F12: =INDEX('05基本'!AB:AB,MATCH(C12,'05基本'!C:C,0)) -> 477.15 | G12: =INDEX('05基本'!AC:AC,MATCH(C12,'05基本'!C:C,0)) -> 117 | H12: =INDEX('05基本'!K:K,MATCH(C12,'05基本'!C:C,0))+INDEX('05基本'!L:L,MATCH(C12,'05基本'!C:C,0)) -> 0 | I12: =INDEX('05基本'!P:P,MATCH(C12,'05基本'!C:C,0)) -> 1200 | J12: =INDEX('05基本'!M:M,MATCH(C12,'05基本'!C:C,0)) -> 0 | K12: =INDEX('05月其他部门提成'!Q:Q,MATCH(C12,'05月其他部门提成'!C:C,0)) -> 5342.8 | L12: =SUMIF(综合考核!A:A,'05月提成-武侯售后'!C12,综合考核!M:M) -> 0 | M12: =SUM(K12:L12) -> 5342.8 | N12: =SUMIF(服装扣款!C:C,C12,服装扣款!N:N) -> 0 | O12: =M12-N12 -> 5342.8 | P12: =SUMIF(超市公积金!C:C,'05月提成-武侯售后'!C12,超市公积金!I:I) -> 0 | Q12: =SUMIF(综合考核!A:A,'05月提成-武侯售后'!C12,综合考核!N:N) -> 0 | R12: =M12+I12+Q12 -> 6542.8 | S12: =INDEX(AC:AC,MATCH(C12,AB:AB,0)) -> 28.46 | U12: =S12-T12 -> 28.46 | V12: =INDEX('05基本'!AF:AF,MATCH(C12,'05基本'!C:C,0)) -> 0 | W12: =O12-P12-U12 -> 5314.34 | Y12: =SUM(Z12:AA12) -> 281.2 | Z12: =INDEX('05月其他部门提成'!S:S,MATCH(C12,'05月其他部门提成'!C:C,0)) -> 281.2 | AB12: 陈川蓉 | AC12: 62.65 | AD12: =COUNTIF(C:C,C12) -> 1 | AE12: =INDEX('05基本'!P:P,MATCH(C12,'05基本'!C:C,0))-I12 -> 0 | AF12: =SUMIF('05月其他部门提成'!C:C,'05月提成-武侯售后'!C12,'05月其他部门提成'!Q:Q) -> 5342.8 | AG12: =SUMIF('05月车间提成'!C:C,'05月提成-武侯售后'!C12,'05月车间提成'!W:W) -> 0 | AH12: =SUMIF('05月业务提成'!B:B,'05月提成-武侯售后'!C12,'05月业务提成'!BO:BO) -> 0 | AI12: =AF12+AG12+AH12 -> 5342.8 | AJ12: =AI12-K12 -> 0
A13: =A12+1 -> 8 | C13: 陈川蓉 | D13: =INDEX('05基本'!I:I,MATCH(C13,'05基本'!C:C,0))+INDEX('05基本'!J:J,MATCH(C13,'05基本'!C:C,0)) -> 0 | E13: =INDEX('05基本'!AA:AA,MATCH(C13,'05基本'!C:C,0)) -> 1268.59 | F13: =INDEX('05基本'!AB:AB,MATCH(C13,'05基本'!C:C,0)) -> 477.15 | G13: =INDEX('05基本'!AC:AC,MATCH(C13,'05基本'!C:C,0)) -> 117 | H13: =INDEX('05基本'!K:K,MATCH(C13,'05基本'!C:C,0))+INDEX('05基本'!L:L,MATCH(C13,'05基本'!C:C,0)) -> 0 | I13: =INDEX('05基本'!P:P,MATCH(C13,'05基本'!C:C,0)) -> 1200 | J13: =INDEX('05基本'!M:M,MATCH(C13,'05基本'!C:C,0)) -> 0 | K13: =INDEX('05月其他部门提成'!Q:Q,MATCH(C13,'05月其他部门提成'!C:C,0)) -> 6482.6133 | L13: =SUMIF(综合考核!A:A,'05月提成-武侯售后'!C13,综合考核!M:M) -> 0 | M13: =SUM(K13:L13) -> 6482.6133 | N13: =SUMIF(服装扣款!C:C,C13,服装扣款!N:N) -> 0 | O13: =M13-N13 -> 6482.6133 | P13: =SUMIF(超市公积金!C:C,'05月提成-武侯售后'!C13,超市公积金!I:I) -> 0 | Q13: =SUMIF(综合考核!A:A,'05月提成-武侯售后'!C13,综合考核!N:N) -> 0 | R13: =M13+I13+Q13 -> 7682.6133 | S13: =INDEX(AC:AC,MATCH(C13,AB:AB,0)) -> 62.65 | U13: =S13-T13 -> 62.65 | V13: =INDEX('05基本'!AF:AF,MATCH(C13,'05基本'!C:C,0)) -> 0 | W13: =O13-P13-U13 -> 6419.9633 | Y13: =SUM(Z13:AA13) -> 86.414327 | Z13: =INDEX('05月其他部门提成'!S:S,MATCH(C13,'05月其他部门提成'!C:C,0)) -> 86.414327 | AB13: 白影 | AC13: 0 | AD13: =COUNTIF(C:C,C13) -> 1 | AE13: =INDEX('05基本'!P:P,MATCH(C13,'05基本'!C:C,0))-I13 -> 0 | AF13: =SUMIF('05月其他部门提成'!C:C,'05月提成-武侯售后'!C13,'05月其他部门提成'!Q:Q) -> 6482.6133 | AG13: =SUMIF('05月车间提成'!C:C,'05月提成-武侯售后'!C13,'05月车间提成'!W:W) -> 0 | AH13: =SUMIF('05月业务提成'!B:B,'05月提成-武侯售后'!C13,'05月业务提成'!BO:BO) -> 0 | AI13: =AF13+AG13+AH13 -> 6482.6133 | AJ13: =AI13-K13 -> 0
C14: 小计 | D14: =SUM(D9:D13) -> 200 | E14: =SUM(E9:E13) -> 6342.95 | F14: =SUM(F9:F13) -> 2385.75 | G14: =SUM(G9:G13) -> 585 | H14: =SUM(H9:H13) -> 0 | I14: =SUM(I9:I13) -> 8600 | J14: =SUM(J9:J13) -> 0 | K14: =SUM(K9:K13) -> 26836.346 | ... AA14: =SUM(AA9:AA13) -> 0 | AB14: 曹青 | AC14: 0 | AD14: =COUNTIF(C:C,C14) -> 11 | AE14: =INDEX('05基本'!P:P,MATCH(C14,'05基本'!C:C,0))-I14 -> #N/A
A15: =A13+1 -> 9 | B15: 服务部 | C15: 白影 | D15: =INDEX('05基本'!I:I,MATCH(C15,'05基本'!C:C,0))+INDEX('05基本'!J:J,MATCH(C15,'05基本'!C:C,0)) -> 0 | E15: =INDEX('05基本'!AA:AA,MATCH(C15,'05基本'!C:C,0)) -> 1268.59 | F15: =INDEX('05基本'!AB:AB,MATCH(C15,'05基本'!C:C,0)) -> 477.15 | G15: =INDEX('05基本'!AC:AC,MATCH(C15,'05基本'!C:C,0)) -> 117 | H15: =INDEX('05基本'!K:K,MATCH(C15,'05基本'!C:C,0))+INDEX('05基本'!L:L,MATCH(C15,'05基本'!C:C,0)) -> 312 | I15: =INDEX('05基本'!P:P,MATCH(C15,'05基本'!C:C,0)) -> 1812 | J15: =INDEX('05基本'!M:M,MATCH(C15,'05基本'!C:C,0)) -> 0 | K15: =INDEX(吧台提成!M:M,MATCH(C15,吧台提成!B:B,0)) -> 3632.94 | L15: =SUMIF(综合考核!A:A,'05月提成-武侯售后'!C15,综合考核!M:M) -> 0 | M15: =SUM(K15:L15) -> 3632.94 | N15: =SUMIF(服装扣款!C:C,C15,服装扣款!N:N) -> 0 | O15: =M15-N15 -> 3632.94 | P15: =SUMIF(超市公积金!C:C,'05月提成-武侯售后'!C15,超市公积金!I:I) -> 0 | Q15: =SUMIF(综合考核!A:A,'05月提成-武侯售后'!C15,综合考核!N:N) -> 0 | R15: =M15+I15+Q15 -> 5444.94 | S15: =INDEX(AC:AC,MATCH(C15,AB:AB,0)) -> 0 | U15: =S15-T15 -> 0 | V15: =INDEX('05基本'!AF:AF,MATCH(C15,'05基本'!C:C,0)) -> 0 | W15: =O15-P15-U15 -> 3632.94 | Y15: =SUM(Z15:AA15) -> 83.33 | Z15: 83.33 | AB15: 陶纯玲 | AC15: 0 | AD15: =COUNTIF(C:C,C15) -> 1 | AE15: =INDEX('05基本'!P:P,MATCH(C15,'05基本'!C:C,0))-I15 -> 0 | AF15: =SUMIF('05月其他部门提成'!C:C,'05月提成-武侯售后'!C15,'05月其他部门提成'!Q:Q) -> 0 | AG15: =SUMIF('05月车间提成'!C:C,'05月提成-武侯售后'!C15,'05月车间提成'!W:W) -> 0 | AH15: =SUMIF('05月业务提成'!B:B,'05月提成-武侯售后'!C15,'05月业务提成'!BO:BO) -> 0 | AI15: =K15 -> 3632.94 | AJ15: =AI15-K15 -> 0
A16: =A15+1 -> 10 | C16: 曹青 | D16: =INDEX('05基本'!I:I,MATCH(C16,'05基本'!C:C,0))+INDEX('05基本'!J:J,MATCH(C16,'05基本'!C:C,0)) -> 0 | E16: =INDEX('05基本'!AA:AA,MATCH(C16,'05基本'!C:C,0)) -> 0 | F16: =INDEX('05基本'!AB:AB,MATCH(C16,'05基本'!C:C,0)) -> 0 | G16: =INDEX('05基本'!AC:AC,MATCH(C16,'05基本'!C:C,0)) -> 0 | H16: =INDEX('05基本'!K:K,MATCH(C16,'05基本'!C:C,0))+INDEX('05基本'!L:L,MATCH(C16,'05基本'!C:C,0)) -> 0 | I16: =INDEX('05基本'!P:P,MATCH(C16,'05基本'!C:C,0)) -> 500 | J16: =INDEX('05基本'!M:M,MATCH(C16,'05基本'!C:C,0)) -> 0 | K16: =INDEX(吧台提成!M:M,MATCH(C16,吧台提成!B:B,0)) -> 1210.98 | L16: =SUMIF(综合考核!A:A,'05月提成-武侯售后'!C16,综合考核!M:M) -> 0 | M16: =SUM(K16:L16) -> 1210.98 | N16: =SUMIF(服装扣款!C:C,C16,服装扣款!N:N) -> 0 | O16: =M16-N16 -> 1210.98 | P16: =SUMIF(超市公积金!C:C,'05月提成-武侯售后'!C16,超市公积金!I:I) -> 0 | Q16: =SUMIF(综合考核!A:A,'05月提成-武侯售后'!C16,综合考核!N:N) -> 0 | R16: =M16+I16+Q16 -> 1710.98 | S16: =INDEX(AC:AC,MATCH(C16,AB:AB,0)) -> 0 | U16: =S16-T16 -> 0 | V16: =INDEX('05基本'!AF:AF,MATCH(C16,'05基本'!C:C,0)) -> 0 | W16: =O16-P16-U16 -> 1210.98 | Y16: =SUM(Z16:AA16) -> 83.33 | Z16: 83.33 | AB16: 朱开莲 | AC16: 0 | AD16: =COUNTIF(C:C,C16) -> 1 | AE16: =INDEX('05基本'!P:P,MATCH(C16,'05基本'!C:C,0))-I16 -> 0 | AF16: =SUMIF('05月其他部门提成'!C:C,'05月提成-武侯售后'!C16,'05月其他部门提成'!Q:Q) -> 0 | AG16: =SUMIF('05月车间提成'!C:C,'05月提成-武侯售后'!C16,'05月车间提成'!W:W) -> 0 | AH16: =SUMIF('05月业务提成'!B:B,'05月提成-武侯售后'!C16,'05月业务提成'!BO:BO) -> 0 | AI16: =K16 -> 1210.98 | AJ16: =AI16-K16 -> 0
A17: =A16+1 -> 11 | C17: 陶纯玲 | D17: =INDEX('05基本'!I:I,MATCH(C17,'05基本'!C:C,0))+INDEX('05基本'!J:J,MATCH(C17,'05基本'!C:C,0)) -> 0 | E17: =INDEX('05基本'!AA:AA,MATCH(C17,'05基本'!C:C,0)) -> 1268.59 | F17: =INDEX('05基本'!AB:AB,MATCH(C17,'05基本'!C:C,0)) -> 477.15 | G17: =INDEX('05基本'!AC:AC,MATCH(C17,'05基本'!C:C,0)) -> 117 | H17: =INDEX('05基本'!K:K,MATCH(C17,'05基本'!C:C,0))+INDEX('05基本'!L:L,MATCH(C17,'05基本'!C:C,0)) -> 0 | I17: =INDEX('05基本'!P:P,MATCH(C17,'05基本'!C:C,0)) -> 1500 | J17: =INDEX('05基本'!M:M,MATCH(C17,'05基本'!C:C,0)) -> 0 | K17: =INDEX(吧台提成!M:M,MATCH(C17,吧台提成!B:B,0)) -> 1695.372 | L17: =SUMIF(综合考核!A:A,'05月提成-武侯售后'!C17,综合考核!M:M) -> 0 | M17: =SUM(K17:L17) -> 1695.372 | N17: =SUMIF(服装扣款!C:C,C17,服装扣款!N:N) -> 0 | O17: =M17-N17 -> 1695.372 | P17: =SUMIF(超市公积金!C:C,'05月提成-武侯售后'!C17,超市公积金!I:I) -> 0 | Q17: =SUMIF(综合考核!A:A,'05月提成-武侯售后'!C17,综合考核!N:N) -> 0 | R17: =M17+I17+Q17 -> 3195.372 | S17: =INDEX(AC:AC,MATCH(C17,AB:AB,0)) -> 0 | U17: =S17-T17 -> 0 | V17: =INDEX('05基本'!AF:AF,MATCH(C17,'05基本'!C:C,0)) -> 0 | W17: =O17-P17-U17 -> 1695.372 | Y17: =SUM(Z17:AA17) -> 83.33 | Z17: 83.33 | AB17: 唐梅 | AC17: 0 | AD17: =COUNTIF(C:C,C17) -> 1 | AE17: =INDEX('05基本'!P:P,MATCH(C17,'05基本'!C:C,0))-I17 -> 0 | AF17: =SUMIF('05月其他部门提成'!C:C,'05月提成-武侯售后'!C17,'05月其他部门提成'!Q:Q) -> 0 | AG17: =SUMIF('05月车间提成'!C:C,'05月提成-武侯售后'!C17,'05月车间提成'!W:W) -> 0 | AH17: =SUMIF('05月业务提成'!B:B,'05月提成-武侯售后'!C17,'05月业务提成'!BO:BO) -> 0 | AI17: =K17 -> 1695.372 | AJ17: =AI17-K17 -> 0
A18: =A17+1 -> 12 | C18: 朱开莲 | D18: =INDEX('05基本'!I:I,MATCH(C18,'05基本'!C:C,0))+INDEX('05基本'!J:J,MATCH(C18,'05基本'!C:C,0)) -> 0 | E18: =INDEX('05基本'!AA:AA,MATCH(C18,'05基本'!C:C,0)) -> 1268.59 | F18: =INDEX('05基本'!AB:AB,MATCH(C18,'05基本'!C:C,0)) -> 477.15 | G18: =INDEX('05基本'!AC:AC,MATCH(C18,'05基本'!C:C,0)) -> 117 | H18: =INDEX('05基本'!K:K,MATCH(C18,'05基本'!C:C,0))+INDEX('05基本'!L:L,MATCH(C18,'05基本'!C:C,0)) -> 312 | I18: =INDEX('05基本'!P:P,MATCH(C18,'05基本'!C:C,0)) -> 1812 | J18: =INDEX('05基本'!M:M,MATCH(C18,'05基本'!C:C,0)) -> 0 | K18: =INDEX(吧台提成!M:M,MATCH(C18,吧台提成!B:B,0)) -> 2664.156 | L18: =SUMIF(综合考核!A:A,'05月提成-武侯售后'!C18,综合考核!M:M) -> 0 | M18: =SUM(K18:L18) -> 2664.156 | N18: =SUMIF(服装扣款!C:C,C18,服装扣款!N:N) -> 0 | O18: =M18-N18 -> 2664.156 | P18: =SUMIF(超市公积金!C:C,'05月提成-武侯售后'!C18,超市公积金!I:I) -> 0 | Q18: =SUMIF(综合考核!A:A,'05月提成-武侯售后'!C18,综合考核!N:N) -> 0 | R18: =M18+I18+Q18 -> 4476.156 | S18: =INDEX(AC:AC,MATCH(C18,AB:AB,0)) -> 0 | U18: =S18-T18 -> 0 | V18: =INDEX('05基本'!AF:AF,MATCH(C18,'05基本'!C:C,0)) -> 0 | W18: =O18-P18-U18 -> 2664.156 | Y18: =SUM(Z18:AA18) -> 83.33 | Z18: 83.33 | AB18: 陈琳琳 | AC18: 0 | AD18: =COUNTIF(C:C,C18) -> 1 | AE18: =INDEX('05基本'!P:P,MATCH(C18,'05基本'!C:C,0))-I18 -> 0 | AF18: =SUMIF('05月其他部门提成'!C:C,'05月提成-武侯售后'!C18,'05月其他部门提成'!Q:Q) -> 0 | AG18: =SUMIF('05月车间提成'!C:C,'05月提成-武侯售后'!C18,'05月车间提成'!W:W) -> 0 | AH18: =SUMIF('05月业务提成'!B:B,'05月提成-武侯售后'!C18,'05月业务提成'!BO:BO) -> 0 | AI18: =K18 -> 2664.156 | AJ18: =AI18-K18 -> 0
C19: 小计 | D19: =SUM(D15:D18) -> 0 | E19: =SUM(E15:E18) -> 3805.77 | F19: =SUM(F15:F18) -> 1431.45 | G19: =SUM(G15:G18) -> 351 | H19: =SUM(H15:H18) -> 624 | I19: =SUM(I15:I18) -> 5624 | J19: =SUM(J15:J18) -> 0 | K19: =SUM(K15:K18) -> 9203.448 | ... AA19: =SUM(AA15:AA18) -> 0 | AB19: 邱昭丽 | AC19: 25.49 | AD19: =COUNTIF(C:C,C19) -> 11 | AE19: =INDEX('05基本'!P:P,MATCH(C19,'05基本'!C:C,0))-I19 -> #N/A
A20: =A18+1 -> 13 | B20: 回访部 | C20: 唐梅 | D20: =INDEX('05基本'!I:I,MATCH(C20,'05基本'!C:C,0))+INDEX('05基本'!J:J,MATCH(C20,'05基本'!C:C,0)) -> 0 | E20: =INDEX('05基本'!AA:AA,MATCH(C20,'05基本'!C:C,0)) -> 1268.59 | F20: =INDEX('05基本'!AB:AB,MATCH(C20,'05基本'!C:C,0)) -> 477.15 | G20: =INDEX('05基本'!AC:AC,MATCH(C20,'05基本'!C:C,0)) -> 117 | H20: =INDEX('05基本'!K:K,MATCH(C20,'05基本'!C:C,0))+INDEX('05基本'!L:L,MATCH(C20,'05基本'!C:C,0)) -> 0 | I20: =INDEX('05基本'!P:P,MATCH(C20,'05基本'!C:C,0)) -> 1200 | J20: =INDEX('05基本'!M:M,MATCH(C20,'05基本'!C:C,0)) -> 0 | K20: =INDEX('05月其他部门提成'!Q:Q,MATCH(C20,'05月其他部门提成'!C:C,0)) -> 4387 | L20: =SUMIF(综合考核!A:A,'05月提成-武侯售后'!C20,综合考核!M:M) -> 0 | M20: =SUM(K20:L20) -> 4387 | N20: =SUMIF(服装扣款!C:C,C20,服装扣款!N:N) -> 0 | O20: =M20-N20 -> 4387 | P20: =SUMIF(超市公积金!C:C,'05月提成-武侯售后'!C20,超市公积金!I:I) -> 0 | Q20: =SUMIF(综合考核!A:A,'05月提成-武侯售后'!C20,综合考核!N:N) -> 0 | R20: =M20+I20+Q20 -> 5587 | S20: =INDEX(AC:AC,MATCH(C20,AB:AB,0)) -> 0 | U20: =S20-T20 -> 0 | V20: =INDEX('05基本'!AF:AF,MATCH(C20,'05基本'!C:C,0)) -> 0 | W20: =O20-P20-U20 -> 4387 | Y20: =SUM(Z20:AA20) -> 83.333333 | Z20: =1000/12 -> 83.333333 | AB20: 黄雪梅 | AC20: 19.91 | AD20: =COUNTIF(C:C,C20) -> 1 | AE20: =INDEX('05基本'!P:P,MATCH(C20,'05基本'!C:C,0))-I20 -> 0 | AF20: =SUMIF('05月其他部门提成'!C:C,'05月提成-武侯售后'!C20,'05月其他部门提成'!Q:Q) -> 4387 | AG20: =SUMIF('05月车间提成'!C:C,'05月提成-武侯售后'!C20,'05月车间提成'!W:W) -> 0 | AH20: =SUMIF('05月业务提成'!B:B,'05月提成-武侯售后'!C20,'05月业务提成'!BO:BO) -> 0 | AI20: =AF20+AG20+AH20 -> 4387 | AJ20: =AI20-K20 -> 0
A21: =A20+1 -> 14 | C21: 陈琳琳 | D21: =INDEX('05基本'!I:I,MATCH(C21,'05基本'!C:C,0))+INDEX('05基本'!J:J,MATCH(C21,'05基本'!C:C,0)) -> 0 | E21: =INDEX('05基本'!AA:AA,MATCH(C21,'05基本'!C:C,0)) -> 1268.59 | F21: =INDEX('05基本'!AB:AB,MATCH(C21,'05基本'!C:C,0)) -> 477.15 | G21: =INDEX('05基本'!AC:AC,MATCH(C21,'05基本'!C:C,0)) -> 117 | H21: =INDEX('05基本'!K:K,MATCH(C21,'05基本'!C:C,0))+INDEX('05基本'!L:L,MATCH(C21,'05基本'!C:C,0)) -> 0 | I21: =INDEX('05基本'!P:P,MATCH(C21,'05基本'!C:C,0)) -> 1200 | J21: =INDEX('05基本'!M:M,MATCH(C21,'05基本'!C:C,0)) -> 0 | K21: =INDEX('05月其他部门提成'!Q:Q,MATCH(C21,'05月其他部门提成'!C:C,0)) -> 3868 | L21: =SUMIF(综合考核!A:A,'05月提成-武侯售后'!C21,综合考核!M:M) -> 0 | M21: =SUM(K21:L21) -> 3868 | N21: =SUMIF(服装扣款!C:C,C21,服装扣款!N:N) -> 0 | O21: =M21-N21 -> 3868 | P21: =SUMIF(超市公积金!C:C,'05月提成-武侯售后'!C21,超市公积金!I:I) -> 0 | Q21: =SUMIF(综合考核!A:A,'05月提成-武侯售后'!C21,综合考核!N:N) -> 0 | R21: =M21+I21+Q21 -> 5068 | S21: =INDEX(AC:AC,MATCH(C21,AB:AB,0)) -> 0 | U21: =S21-T21 -> 0 | V21: =INDEX('05基本'!AF:AF,MATCH(C21,'05基本'!C:C,0)) -> 0 | W21: =O21-P21-U21 -> 3868 | Y21: =SUM(Z21:AA21) -> 83.333333 | Z21: =1000/12 -> 83.333333 | AB21: 李彩琼 | AC21: 11.36 | AD21: =COUNTIF(C:C,C21) -> 1 | AE21: =INDEX('05基本'!P:P,MATCH(C21,'05基本'!C:C,0))-I21 -> 0 | AF21: =SUMIF('05月其他部门提成'!C:C,'05月提成-武侯售后'!C21,'05月其他部门提成'!Q:Q) -> 3868 | AG21: =SUMIF('05月车间提成'!C:C,'05月提成-武侯售后'!C21,'05月车间提成'!W:W) -> 0 | AH21: =SUMIF('05月业务提成'!B:B,'05月提成-武侯售后'!C21,'05月业务提成'!BO:BO) -> 0 | AI21: =AF21+AG21+AH21 -> 3868 | AJ21: =AI21-K21 -> 0
A22: =A21+1 -> 15 | C22: 邱昭丽 | D22: =INDEX('05基本'!I:I,MATCH(C22,'05基本'!C:C,0))+INDEX('05基本'!J:J,MATCH(C22,'05基本'!C:C,0)) -> 0 | E22: =INDEX('05基本'!AA:AA,MATCH(C22,'05基本'!C:C,0)) -> 1268.59 | F22: =INDEX('05基本'!AB:AB,MATCH(C22,'05基本'!C:C,0)) -> 477.15 | G22: =INDEX('05基本'!AC:AC,MATCH(C22,'05基本'!C:C,0)) -> 117 | H22: =INDEX('05基本'!K:K,MATCH(C22,'05基本'!C:C,0))+INDEX('05基本'!L:L,MATCH(C22,'05基本'!C:C,0)) -> 0 | I22: =INDEX('05基本'!P:P,MATCH(C22,'05基本'!C:C,0)) -> 1200 | J22: =INDEX('05基本'!M:M,MATCH(C22,'05基本'!C:C,0)) -> 0 | K22: =INDEX('05月其他部门提成'!Q:Q,MATCH(C22,'05月其他部门提成'!C:C,0)) -> 5244 | L22: =SUMIF(综合考核!A:A,'05月提成-武侯售后'!C22,综合考核!M:M) -> 0 | M22: =SUM(K22:L22) -> 5244 | N22: =SUMIF(服装扣款!C:C,C22,服装扣款!N:N) -> 0 | O22: =M22-N22 -> 5244 | P22: =SUMIF(超市公积金!C:C,'05月提成-武侯售后'!C22,超市公积金!I:I) -> 0 | Q22: =SUMIF(综合考核!A:A,'05月提成-武侯售后'!C22,综合考核!N:N) -> 0 | R22: =M22+I22+Q22 -> 6444 | S22: =INDEX(AC:AC,MATCH(C22,AB:AB,0)) -> 25.49 | U22: =S22-T22 -> 25.49 | V22: =INDEX('05基本'!AF:AF,MATCH(C22,'05基本'!C:C,0)) -> 0 | W22: =O22-P22-U22 -> 5218.51 | Y22: =SUM(Z22:AA22) -> 83.333333 | Z22: =1000/12 -> 83.333333 | AB22: 向阳 | AC22: 0 | AD22: =COUNTIF(C:C,C22) -> 1 | AE22: =INDEX('05基本'!P:P,MATCH(C22,'05基本'!C:C,0))-I22 -> 0 | AF22: =SUMIF('05月其他部门提成'!C:C,'05月提成-武侯售后'!C22,'05月其他部门提成'!Q:Q) -> 5244 | AG22: =SUMIF('05月车间提成'!C:C,'05月提成-武侯售后'!C22,'05月车间提成'!W:W) -> 0 | AH22: =SUMIF('05月业务提成'!B:B,'05月提成-武侯售后'!C22,'05月业务提成'!BO:BO) -> 0 | AI22: =AF22+AG22+AH22 -> 5244 | AJ22: =AI22-K22 -> 0
A23: =A22+1 -> 16 | C23: 黄雪梅 | D23: =INDEX('05基本'!I:I,MATCH(C23,'05基本'!C:C,0))+INDEX('05基本'!J:J,MATCH(C23,'05基本'!C:C,0)) -> 0 | E23: =INDEX('05基本'!AA:AA,MATCH(C23,'05基本'!C:C,0)) -> 1268.59 | F23: =INDEX('05基本'!AB:AB,MATCH(C23,'05基本'!C:C,0)) -> 477.15 | G23: =INDEX('05基本'!AC:AC,MATCH(C23,'05基本'!C:C,0)) -> 117 | H23: =INDEX('05基本'!K:K,MATCH(C23,'05基本'!C:C,0))+INDEX('05基本'!L:L,MATCH(C23,'05基本'!C:C,0)) -> 0 | I23: =INDEX('05基本'!P:P,MATCH(C23,'05基本'!C:C,0)) -> 1200 | J23: =INDEX('05基本'!M:M,MATCH(C23,'05基本'!C:C,0)) -> 0 | K23: =INDEX('05月其他部门提成'!Q:Q,MATCH(C23,'05月其他部门提成'!C:C,0)) -> 5058 | L23: =SUMIF(综合考核!A:A,'05月提成-武侯售后'!C23,综合考核!M:M) -> 0 | M23: =SUM(K23:L23) -> 5058 | N23: =SUMIF(服装扣款!C:C,C23,服装扣款!N:N) -> 0 | O23: =M23-N23 -> 5058 | P23: =SUMIF(超市公积金!C:C,'05月提成-武侯售后'!C23,超市公积金!I:I) -> 0 | Q23: =SUMIF(综合考核!A:A,'05月提成-武侯售后'!C23,综合考核!N:N) -> 0 | R23: =M23+I23+Q23 -> 6258 | S23: =INDEX(AC:AC,MATCH(C23,AB:AB,0)) -> 19.91 | U23: =S23-T23 -> 19.91 | V23: =INDEX('05基本'!AF:AF,MATCH(C23,'05基本'!C:C,0)) -> 0 | W23: =O23-P23-U23 -> 5038.09 | Y23: =SUM(Z23:AA23) -> 83.333333 | Z23: =1000/12 -> 83.333333 | AB23: 阳国华 | AC23: 709.53 | AD23: =COUNTIF(C:C,C23) -> 1 | AE23: =INDEX('05基本'!P:P,MATCH(C23,'05基本'!C:C,0))-I23 -> 0 | AF23: =SUMIF('05月其他部门提成'!C:C,'05月提成-武侯售后'!C23,'05月其他部门提成'!Q:Q) -> 5058 | AG23: =SUMIF('05月车间提成'!C:C,'05月提成-武侯售后'!C23,'05月车间提成'!W:W) -> 0 | AH23: =SUMIF('05月业务提成'!B:B,'05月提成-武侯售后'!C23,'05月业务提成'!BO:BO) -> 0 | AI23: =AF23+AG23+AH23 -> 5058 | AJ23: =AI23-K23 -> 0
A24: =A23+1 -> 17 | C24: 李彩琼 | D24: =INDEX('05基本'!I:I,MATCH(C24,'05基本'!C:C,0))+INDEX('05基本'!J:J,MATCH(C24,'05基本'!C:C,0)) -> 0 | E24: =INDEX('05基本'!AA:AA,MATCH(C24,'05基本'!C:C,0)) -> 1268.59 | F24: =INDEX('05基本'!AB:AB,MATCH(C24,'05基本'!C:C,0)) -> 477.15 | G24: =INDEX('05基本'!AC:AC,MATCH(C24,'05基本'!C:C,0)) -> 117 | H24: =INDEX('05基本'!K:K,MATCH(C24,'05基本'!C:C,0))+INDEX('05基本'!L:L,MATCH(C24,'05基本'!C:C,0)) -> 0 | I24: =INDEX('05基本'!P:P,MATCH(C24,'05基本'!C:C,0)) -> 1200 | J24: =INDEX('05基本'!M:M,MATCH(C24,'05基本'!C:C,0)) -> 0 | K24: =INDEX('05月其他部门提成'!Q:Q,MATCH(C24,'05月其他部门提成'!C:C,0)) -> 4773 | L24: =SUMIF(综合考核!A:A,'05月提成-武侯售后'!C24,综合考核!M:M) -> 0 | M24: =SUM(K24:L24) -> 4773 | N24: =SUMIF(服装扣款!C:C,C24,服装扣款!N:N) -> 0 | O24: =M24-N24 -> 4773 | P24: =SUMIF(超市公积金!C:C,'05月提成-武侯售后'!C24,超市公积金!I:I) -> 0 | Q24: =SUMIF(综合考核!A:A,'05月提成-武侯售后'!C24,综合考核!N:N) -> 0 | R24: =M24+I24+Q24 -> 5973 | S24: =INDEX(AC:AC,MATCH(C24,AB:AB,0)) -> 11.36 | U24: =S24-T24 -> 11.36 | V24: =INDEX('05基本'!AF:AF,MATCH(C24,'05基本'!C:C,0)) -> 0 | W24: =O24-P24-U24 -> 4761.64 | Y24: =SUM(Z24:AA24) -> 83.333333 | Z24: =1000/12 -> 83.333333 | AB24: 舒童强 | AC24: 56.79 | AD24: =COUNTIF(C:C,C24) -> 1 | AE24: =INDEX('05基本'!P:P,MATCH(C24,'05基本'!C:C,0))-I24 -> 0 | AF24: =SUMIF('05月其他部门提成'!C:C,'05月提成-武侯售后'!C24,'05月其他部门提成'!Q:Q) -> 4773 | AG24: =SUMIF('05月车间提成'!C:C,'05月提成-武侯售后'!C24,'05月车间提成'!W:W) -> 0 | AH24: =SUMIF('05月业务提成'!B:B,'05月提成-武侯售后'!C24,'05月业务提成'!BO:BO) -> 0 | AI24: =AF24+AG24+AH24 -> 4773 | AJ24: =AI24-K24 -> 0
A25: =A24+1 -> 18 | C25: 向阳 | D25: =INDEX('05基本'!I:I,MATCH(C25,'05基本'!C:C,0))+INDEX('05基本'!J:J,MATCH(C25,'05基本'!C:C,0)) -> 0 | E25: =INDEX('05基本'!AA:AA,MATCH(C25,'05基本'!C:C,0)) -> 1268.59 | F25: =INDEX('05基本'!AB:AB,MATCH(C25,'05基本'!C:C,0)) -> 477.15 | G25: =INDEX('05基本'!AC:AC,MATCH(C25,'05基本'!C:C,0)) -> 117 | H25: =INDEX('05基本'!K:K,MATCH(C25,'05基本'!C:C,0))+INDEX('05基本'!L:L,MATCH(C25,'05基本'!C:C,0)) -> 0 | I25: =INDEX('05基本'!P:P,MATCH(C25,'05基本'!C:C,0)) -> 1200 | K25: =INDEX('05月其他部门提成'!Q:Q,MATCH(C25,'05月其他部门提成'!C:C,0)) -> 4010 | L25: =SUMIF(综合考核!A:A,'05月提成-武侯售后'!C25,综合考核!M:M) -> 0 | M25: =SUM(K25:L25) -> 4010 | N25: =SUMIF(服装扣款!C:C,C25,服装扣款!N:N) -> 0 | O25: =M25-N25 -> 4010 | P25: =SUMIF(超市公积金!C:C,'05月提成-武侯售后'!C25,超市公积金!I:I) -> 0 | Q25: =SUMIF(综合考核!A:A,'05月提成-武侯售后'!C25,综合考核!N:N) -> 0 | R25: =M25+I25+Q25 -> 5210 | S25: =INDEX(AC:AC,MATCH(C25,AB:AB,0)) -> 0 | U25: =S25-T25 -> 0 | V25: =INDEX('05基本'!AF:AF,MATCH(C25,'05基本'!C:C,0)) -> 0 | W25: =O25-P25-U25 -> 4010 | Y25: =SUM(Z25:AA25) -> 83.333333 | Z25: =1000/12 -> 83.333333 | AB25: 罗义瑕 | AC25: 0 | AE25: =INDEX('05基本'!P:P,MATCH(C25,'05基本'!C:C,0))-I25 -> 0
C26: 小计 | D26: =SUM(D20:D25) -> 0 | E26: =SUM(E20:E25) -> 7611.54 | F26: =SUM(F20:F25) -> 2862.9 | G26: =SUM(G20:G25) -> 702 | H26: =SUM(H20:H25) -> 0 | I26: =SUM(I20:I25) -> 7200 | J26: =SUM(J20:J25) -> 0 | K26: =SUM(K20:K25) -> 27340 | ... AA26: =SUM(AA20:AA25) -> 0 | AB26: 段宝安 | AC26: 81.26 | AD26: =COUNTIF(C:C,C26) -> 11 | AE26: =INDEX('05基本'!P:P,MATCH(C26,'05基本'!C:C,0))-I26 -> #N/A
A27: =A25+1 -> 19 | C27: 阳国华 | D27: =INDEX('05基本'!I:I,MATCH(C27,'05基本'!C:C,0))+INDEX('05基本'!J:J,MATCH(C27,'05基本'!C:C,0)) -> 0 | E27: =INDEX('05基本'!AA:AA,MATCH(C27,'05基本'!C:C,0)) -> 1268.59 | F27: =INDEX('05基本'!AB:AB,MATCH(C27,'05基本'!C:C,0)) -> 477.15 | G27: =INDEX('05基本'!AC:AC,MATCH(C27,'05基本'!C:C,0)) -> 117 | H27: =INDEX('05基本'!K:K,MATCH(C27,'05基本'!C:C,0))+INDEX('05基本'!L:L,MATCH(C27,'05基本'!C:C,0)) -> 100 | I27: =INDEX('05基本'!P:P,MATCH(C27,'05基本'!C:C,0)) -> 1700 | J27: =INDEX('05基本'!M:M,MATCH(C27,'05基本'!C:C,0)) -> 0 | K27: =INDEX('05月其他部门提成'!Q:Q,MATCH(C27,'05月其他部门提成'!C:C,0)) -> 10989.415 | L27: =SUMIF(综合考核!A:A,'05月提成-武侯售后'!C27,综合考核!M:M) -> 0 | M27: =SUM(K27:L27) -> 10989.415 | N27: =SUMIF(服装扣款!C:C,C27,服装扣款!N:N) -> 0 | O27: =M27-N27 -> 10989.415 | P27: =SUMIF(超市公积金!C:C,'05月提成-武侯售后'!C27,超市公积金!I:I) -> 0 | Q27: =SUMIF(综合考核!A:A,'05月提成-武侯售后'!C27,综合考核!N:N) -> 0 | R27: =M27+I27+Q27 -> 12689.415 | S27: =INDEX(AC:AC,MATCH(C27,AB:AB,0)) -> 709.53 | U27: =S27-T27 -> 709.53 | V27: =INDEX('05基本'!AF:AF,MATCH(C27,'05基本'!C:C,0)) -> 0 | W27: =O27-P27-U27 -> 10279.885 | Y27: =SUM(Z27:AA27) -> 830.08647 | Z27: ='05月其他部门提成'!R8 -> 830.08647 | AB27: 张建 | AC27: 68.18 | AD27: =COUNTIF(C:C,C27) -> 1 | AE27: =INDEX('05基本'!P:P,MATCH(C27,'05基本'!C:C,0))-I27 -> 0 | AF27: =SUMIF('05月其他部门提成'!C:C,'05月提成-武侯售后'!C27,'05月其他部门提成'!Q:Q) -> 10989.415 | AG27: =SUMIF('05月车间提成'!C:C,'05月提成-武侯售后'!C27,'05月车间提成'!W:W) -> 0 | AH27: =SUMIF('05月业务提成'!B:B,'05月提成-武侯售后'!C27,'05月业务提成'!BO:BO) -> 0 | AI27: =AF27+AG27+AH27 -> 10989.415 | AJ27: =AI27-K27 -> 0
A28: =A27+1 -> 20 | B28: 业务部 | C28: 舒童强 | D28: =INDEX('05基本'!I:I,MATCH(C28,'05基本'!C:C,0))+INDEX('05基本'!J:J,MATCH(C28,'05基本'!C:C,0)) -> 32 | E28: =INDEX('05基本'!AA:AA,MATCH(C28,'05基本'!C:C,0)) -> 1268.59 | F28: =INDEX('05基本'!AB:AB,MATCH(C28,'05基本'!C:C,0)) -> 477.15 | G28: =INDEX('05基本'!AC:AC,MATCH(C28,'05基本'!C:C,0)) -> 117 | H28: =INDEX('05基本'!K:K,MATCH(C28,'05基本'!C:C,0))+INDEX('05基本'!L:L,MATCH(C28,'05基本'!C:C,0)) -> 0 | I28: =INDEX('05基本'!P:P,MATCH(C28,'05基本'!C:C,0)) -> 932 | J28: =INDEX('05基本'!M:M,MATCH(C28,'05基本'!C:C,0)) -> 0 | K28: =INDEX('05月业务提成'!BO:BO,MATCH(C28,'05月业务提成'!B:B,0)) -> 6555.1645 | L28: =SUMIF(综合考核!A:A,'05月提成-武侯售后'!C28,综合考核!M:M) -> 0 | M28: =SUM(K28:L28) -> 6555.1645 | N28: =SUMIF(服装扣款!C:C,C28,服装扣款!N:N) -> 0 | O28: =M28-N28 -> 6555.1645 | P28: =SUMIF(超市公积金!C:C,'05月提成-武侯售后'!C28,超市公积金!I:I) -> 0 | Q28: =SUMIF(综合考核!A:A,'05月提成-武侯售后'!C28,综合考核!N:N) -> 0 | R28: =M28+I28+Q28 -> 7487.1645 | S28: =INDEX(AC:AC,MATCH(C28,AB:AB,0)) -> 56.79 | U28: =S28-T28 -> 56.79 | V28: =INDEX('05基本'!AF:AF,MATCH(C28,'05基本'!C:C,0)) -> 0 | W28: =O28-P28-U28 -> 6498.3745 | Y28: =SUM(Z28:AA28) -> 479.10813 | Z28: =INDEX('05月业务提成'!C:C,MATCH(C28,'05月业务提成'!B:B,0))*1 -> 288 | AA28: =INDEX('05月业务提成'!F:F,MATCH(C28,'05月业务提成'!B:B,0))*0.05*2%+INDEX('05月业务提成'!J:J,MATCH(C28,'05月业务提成'!B:B,0))*0.05*1.6%+(INDEX('05月业务提成'!P:P,MATCH(C28,'05月业务提成'!B:B,0))/0.95)*0.05++(INDEX('05月业务提成'!V:V,MATCH(C28,'05月业务提成'!B:B,0))/0.95)*0.05+(INDEX('05月业务提成'!Z:Z,MATCH(C28,'05月业务提成'!B:B,0))/0.95)*0.05 -> 191.10813 | AB28: 贾文哲 | AC28: 33.7 | AD28: =COUNTIF(C:C,C28) -> 1 | AE28: =INDEX('05基本'!P:P,MATCH(C28,'05基本'!C:C,0))-I28 -> 0 | AF28: =SUMIF('05月其他部门提成'!C:C,'05月提成-武侯售后'!C28,'05月其他部门提成'!Q:Q) -> 0 | AG28: =SUMIF('05月车间提成'!C:C,'05月提成-武侯售后'!C28,'05月车间提成'!W:W) -> 0 | AH28: =SUMIF('05月业务提成'!B:B,'05月提成-武侯售后'!C28,'05月业务提成'!BO:BO) -> 6555.1645 | AI28: =AF28+AG28+AH28 -> 6555.1645 | AJ28: =AI28-K28 -> 0
A29: =A28+1 -> 21 | C29: 罗义瑕 | D29: =INDEX('05基本'!I:I,MATCH(C29,'05基本'!C:C,0))+INDEX('05基本'!J:J,MATCH(C29,'05基本'!C:C,0)) -> 32 | E29: =INDEX('05基本'!AA:AA,MATCH(C29,'05基本'!C:C,0)) -> 1268.59 | F29: =INDEX('05基本'!AB:AB,MATCH(C29,'05基本'!C:C,0)) -> 477.15 | G29: =INDEX('05基本'!AC:AC,MATCH(C29,'05基本'!C:C,0)) -> 117 | H29: =INDEX('05基本'!K:K,MATCH(C29,'05基本'!C:C,0))+INDEX('05基本'!L:L,MATCH(C29,'05基本'!C:C,0)) -> 0 | I29: =INDEX('05基本'!P:P,MATCH(C29,'05基本'!C:C,0)) -> 932 | J29: =INDEX('05基本'!M:M,MATCH(C29,'05基本'!C:C,0)) -> 0 | K29: =INDEX('05月业务提成'!BO:BO,MATCH(C29,'05月业务提成'!B:B,0)) -> 4175.6566 | L29: =SUMIF(综合考核!A:A,'05月提成-武侯售后'!C29,综合考核!M:M) -> 0 | M29: =SUM(K29:L29) -> 4175.6566 | N29: =SUMIF(服装扣款!C:C,C29,服装扣款!N:N) -> 0 | O29: =M29-N29 -> 4175.6566 | P29: =SUMIF(超市公积金!C:C,'05月提成-武侯售后'!C29,超市公积金!I:I) -> 0 | Q29: =SUMIF(综合考核!A:A,'05月提成-武侯售后'!C29,综合考核!N:N) -> 0 | R29: =M29+I29+Q29 -> 5107.6566 | S29: =INDEX(AC:AC,MATCH(C29,AB:AB,0)) -> 0 | U29: =S29-T29 -> 0 | V29: =INDEX('05基本'!AF:AF,MATCH(C29,'05基本'!C:C,0)) -> 0 | W29: =O29-P29-U29 -> 4175.6566 | Y29: =SUM(Z29:AA29) -> 294.04403 | Z29: =INDEX('05月业务提成'!C:C,MATCH(C29,'05月业务提成'!B:B,0))*1 -> 159 | AA29: =INDEX('05月业务提成'!F:F,MATCH(C29,'05月业务提成'!B:B,0))*0.05*2%+INDEX('05月业务提成'!J:J,MATCH(C29,'05月业务提成'!B:B,0))*0.05*1.6%+(INDEX('05月业务提成'!P:P,MATCH(C29,'05月业务提成'!B:B,0))/0.95)*0.05++(INDEX('05月业务提成'!V:V,MATCH(C29,'05月业务提成'!B:B,0))/0.95)*0.05+(INDEX('05月业务提成'!Z:Z,MATCH(C29,'05月业务提成'!B:B,0))/0.95)*0.05 -> 135.04403 | AB29: 黄小炼 | AC29: 22.15 | AD29: =COUNTIF(C:C,C29) -> 1 | AE29: =INDEX('05基本'!P:P,MATCH(C29,'05基本'!C:C,0))-I29 -> 0 | AF29: =SUMIF('05月其他部门提成'!C:C,'05月提成-武侯售后'!C29,'05月其他部门提成'!Q:Q) -> 0 | AG29: =SUMIF('05月车间提成'!C:C,'05月提成-武侯售后'!C29,'05月车间提成'!W:W) -> 0 | AH29: =SUMIF('05月业务提成'!B:B,'05月提成-武侯售后'!C29,'05月业务提成'!BO:BO) -> 4175.6566 | AI29: =AF29+AG29+AH29 -> 4175.6566 | AJ29: =AI29-K29 -> 0
A30: =A29+1 -> 22 | C30: 段宝安 | D30: =INDEX('05基本'!I:I,MATCH(C30,'05基本'!C:C,0))+INDEX('05基本'!J:J,MATCH(C30,'05基本'!C:C,0)) -> 0 | E30: =INDEX('05基本'!AA:AA,MATCH(C30,'05基本'!C:C,0)) -> 1268.59 | F30: =INDEX('05基本'!AB:AB,MATCH(C30,'05基本'!C:C,0)) -> 477.15 | G30: =INDEX('05基本'!AC:AC,MATCH(C30,'05基本'!C:C,0)) -> 117 | H30: =INDEX('05基本'!K:K,MATCH(C30,'05基本'!C:C,0))+INDEX('05基本'!L:L,MATCH(C30,'05基本'!C:C,0)) -> 0 | I30: =INDEX('05基本'!P:P,MATCH(C30,'05基本'!C:C,0)) -> 900 | J30: =INDEX('05基本'!M:M,MATCH(C30,'05基本'!C:C,0)) -> 0 | K30: =INDEX('05月业务提成'!BO:BO,MATCH(C30,'05月业务提成'!B:B,0)) -> 7182.7026 | L30: =SUMIF(综合考核!A:A,'05月提成-武侯售后'!C30,综合考核!M:M) -> 220 | M30: =SUM(K30:L30) -> 7402.7026 | N30: =SUMIF(服装扣款!C:C,C30,服装扣款!N:N) -> 0 | O30: =M30-N30 -> 7402.7026 | P30: =SUMIF(超市公积金!C:C,'05月提成-武侯售后'!C30,超市公积金!I:I) -> 0 | Q30: =SUMIF(综合考核!A:A,'05月提成-武侯售后'!C30,综合考核!N:N) -> 0 | R30: =M30+I30+Q30 -> 8302.7026 | S30: =INDEX(AC:AC,MATCH(C30,AB:AB,0)) -> 81.26 | U30: =S30-T30 -> 81.26 | V30: =INDEX('05基本'!AF:AF,MATCH(C30,'05基本'!C:C,0)) -> 0 | W30: =O30-P30-U30 -> 7321.4426 | Y30: =SUM(Z30:AA30) -> 461.30014 | Z30: =INDEX('05月业务提成'!C:C,MATCH(C30,'05月业务提成'!B:B,0))*1 -> 62 | AA30: =INDEX('05月业务提成'!F:F,MATCH(C30,'05月业务提成'!B:B,0))*0.05*2%+INDEX('05月业务提成'!J:J,MATCH(C30,'05月业务提成'!B:B,0))*0.05*1.6%+(INDEX('05月业务提成'!P:P,MATCH(C30,'05月业务提成'!B:B,0))/0.95)*0.05++(INDEX('05月业务提成'!V:V,MATCH(C30,'05月业务提成'!B:B,0))/0.95)*0.05+(INDEX('05月业务提成'!Z:Z,MATCH(C30,'05月业务提成'!B:B,0))/0.95)*0.05 -> 399.30014 | AB30: 陈昱良 | AC30: 50.13 | AD30: =COUNTIF(C:C,C30) -> 1 | AE30: =INDEX('05基本'!P:P,MATCH(C30,'05基本'!C:C,0))-I30 -> 0 | AF30: =SUMIF('05月其他部门提成'!C:C,'05月提成-武侯售后'!C30,'05月其他部门提成'!Q:Q) -> 0 | AG30: =SUMIF('05月车间提成'!C:C,'05月提成-武侯售后'!C30,'05月车间提成'!W:W) -> 0 | AH30: =SUMIF('05月业务提成'!B:B,'05月提成-武侯售后'!C30,'05月业务提成'!BO:BO) -> 7182.7026 | AI30: =AF30+AG30+AH30 -> 7182.7026 | AJ30: =AI30-K30 -> 0
A31: =A30+1 -> 23 | C31: 张建 | D31: =INDEX('05基本'!I:I,MATCH(C31,'05基本'!C:C,0))+INDEX('05基本'!J:J,MATCH(C31,'05基本'!C:C,0)) -> 32 | E31: =INDEX('05基本'!AA:AA,MATCH(C31,'05基本'!C:C,0)) -> 1268.59 | F31: =INDEX('05基本'!AB:AB,MATCH(C31,'05基本'!C:C,0)) -> 477.15 | G31: =INDEX('05基本'!AC:AC,MATCH(C31,'05基本'!C:C,0)) -> 117 | H31: =INDEX('05基本'!K:K,MATCH(C31,'05基本'!C:C,0))+INDEX('05基本'!L:L,MATCH(C31,'05基本'!C:C,0)) -> 0 | I31: =INDEX('05基本'!P:P,MATCH(C31,'05基本'!C:C,0)) -> 932 | J31: =INDEX('05基本'!M:M,MATCH(C31,'05基本'!C:C,0)) -> 0 | K31: =INDEX('05月业务提成'!BO:BO,MATCH(C31,'05月业务提成'!B:B,0)) -> 6934.8284 | L31: =SUMIF(综合考核!A:A,'05月提成-武侯售后'!C31,综合考核!M:M) -> 0 | M31: =SUM(K31:L31) -> 6934.8284 | N31: =SUMIF(服装扣款!C:C,C31,服装扣款!N:N) -> 0 | O31: =M31-N31 -> 6934.8284 | P31: =SUMIF(超市公积金!C:C,'05月提成-武侯售后'!C31,超市公积金!I:I) -> 0 | Q31: =SUMIF(综合考核!A:A,'05月提成-武侯售后'!C31,综合考核!N:N) -> 0 | R31: =M31+I31+Q31 -> 7866.8284 | S31: =INDEX(AC:AC,MATCH(C31,AB:AB,0)) -> 68.18 | U31: =S31-T31 -> 68.18 | V31: =INDEX('05基本'!AF:AF,MATCH(C31,'05基本'!C:C,0)) -> 0 | W31: =O31-P31-U31 -> 6866.6484 | Y31: =SUM(Z31:AA31) -> 441.89571 | Z31: =INDEX('05月业务提成'!C:C,MATCH(C31,'05月业务提成'!B:B,0))*1 -> 235 | AA31: =INDEX('05月业务提成'!F:F,MATCH(C31,'05月业务提成'!B:B,0))*0.05*2%+INDEX('05月业务提成'!J:J,MATCH(C31,'05月业务提成'!B:B,0))*0.05*1.6%+(INDEX('05月业务提成'!P:P,MATCH(C31,'05月业务提成'!B:B,0))/0.95)*0.05++(INDEX('05月业务提成'!V:V,MATCH(C31,'05月业务提成'!B:B,0))/0.95)*0.05+(INDEX('05月业务提成'!Z:Z,MATCH(C31,'05月业务提成'!B:B,0))/0.95)*0.05 -> 206.8957 | AB31: 张林 | AC31: 66.88 | AD31: =COUNTIF(C:C,C31) -> 1 | AE31: =INDEX('05基本'!P:P,MATCH(C31,'05基本'!C:C,0))-I31 -> 0 | AF31: =SUMIF('05月其他部门提成'!C:C,'05月提成-武侯售后'!C31,'05月其他部门提成'!Q:Q) -> 0 | AG31: =SUMIF('05月车间提成'!C:C,'05月提成-武侯售后'!C31,'05月车间提成'!W:W) -> 0 | AH31: =SUMIF('05月业务提成'!B:B,'05月提成-武侯售后'!C31,'05月业务提成'!BO:BO) -> 6934.8284 | AI31: =AF31+AG31+AH31 -> 6934.8284 | AJ31: =AI31-K31 -> 0
A32: =A31+1 -> 24 | C32: 贾文哲 | D32: =INDEX('05基本'!I:I,MATCH(C32,'05基本'!C:C,0))+INDEX('05基本'!J:J,MATCH(C32,'05基本'!C:C,0)) -> 32 | E32: =INDEX('05基本'!AA:AA,MATCH(C32,'05基本'!C:C,0)) -> 1268.59 | F32: =INDEX('05基本'!AB:AB,MATCH(C32,'05基本'!C:C,0)) -> 477.15 | G32: =INDEX('05基本'!AC:AC,MATCH(C32,'05基本'!C:C,0)) -> 117 | H32: =INDEX('05基本'!K:K,MATCH(C32,'05基本'!C:C,0))+INDEX('05基本'!L:L,MATCH(C32,'05基本'!C:C,0)) -> 0 | I32: =INDEX('05基本'!P:P,MATCH(C32,'05基本'!C:C,0)) -> 932 | J32: =INDEX('05基本'!M:M,MATCH(C32,'05基本'!C:C,0)) -> 0 | K32: =INDEX('05月业务提成'!BO:BO,MATCH(C32,'05月业务提成'!B:B,0)) -> 5785.5861 | L32: =SUMIF(综合考核!A:A,'05月提成-武侯售后'!C32,综合考核!M:M) -> 0 | M32: =SUM(K32:L32) -> 5785.5861 | N32: =SUMIF(服装扣款!C:C,C32,服装扣款!N:N) -> 0 | O32: =M32-N32 -> 5785.5861 | P32: =SUMIF(超市公积金!C:C,'05月提成-武侯售后'!C32,超市公积金!I:I) -> 0 | Q32: =SUMIF(综合考核!A:A,'05月提成-武侯售后'!C32,综合考核!N:N) -> 0 | R32: =M32+I32+Q32 -> 6717.5861 | S32: =INDEX(AC:AC,MATCH(C32,AB:AB,0)) -> 33.7 | U32: =S32-T32 -> 33.7 | V32: =INDEX('05基本'!AF:AF,MATCH(C32,'05基本'!C:C,0)) -> 0 | W32: =O32-P32-U32 -> 5751.8861 | Y32: =SUM(Z32:AA32) -> 385.18137 | Z32: =INDEX('05月业务提成'!C:C,MATCH(C32,'05月业务提成'!B:B,0))*1 -> 219 | AA32: =INDEX('05月业务提成'!F:F,MATCH(C32,'05月业务提成'!B:B,0))*0.05*2%+INDEX('05月业务提成'!J:J,MATCH(C32,'05月业务提成'!B:B,0))*0.05*1.6%+(INDEX('05月业务提成'!P:P,MATCH(C32,'05月业务提成'!B:B,0))/0.95)*0.05++(INDEX('05月业务提成'!V:V,MATCH(C32,'05月业务提成'!B:B,0))/0.95)*0.05+(INDEX('05月业务提成'!Z:Z,MATCH(C32,'05月业务提成'!B:B,0))/0.95)*0.05 -> 166.18137 | AB32: 王毅 | AC32: 125.15 | AD32: =COUNTIF(C:C,C32) -> 1 | AE32: =INDEX('05基本'!P:P,MATCH(C32,'05基本'!C:C,0))-I32 -> 0 | AF32: =SUMIF('05月其他部门提成'!C:C,'05月提成-武侯售后'!C32,'05月其他部门提成'!Q:Q) -> 0 | AG32: =SUMIF('05月车间提成'!C:C,'05月提成-武侯售后'!C32,'05月车间提成'!W:W) -> 0 | AH32: =SUMIF('05月业务提成'!B:B,'05月提成-武侯售后'!C32,'05月业务提成'!BO:BO) -> 5785.5861 | AI32: =AF32+AG32+AH32 -> 5785.5861 | AJ32: =AI32-K32 -> 0
A33: =A32+1 -> 25 | C33: 黄小炼 | D33: =INDEX('05基本'!I:I,MATCH(C33,'05基本'!C:C,0))+INDEX('05基本'!J:J,MATCH(C33,'05基本'!C:C,0)) -> 32 | E33: =INDEX('05基本'!AA:AA,MATCH(C33,'05基本'!C:C,0)) -> 1268.59 | F33: =INDEX('05基本'!AB:AB,MATCH(C33,'05基本'!C:C,0)) -> 477.15 | G33: =INDEX('05基本'!AC:AC,MATCH(C33,'05基本'!C:C,0)) -> 117 | H33: =INDEX('05基本'!K:K,MATCH(C33,'05基本'!C:C,0))+INDEX('05基本'!L:L,MATCH(C33,'05基本'!C:C,0)) -> 0 | I33: =INDEX('05基本'!P:P,MATCH(C33,'05基本'!C:C,0)) -> 932 | J33: =INDEX('05基本'!M:M,MATCH(C33,'05基本'!C:C,0)) -> 0 | K33: =INDEX('05月业务提成'!BO:BO,MATCH(C33,'05月业务提成'!B:B,0)) -> 8400.5975 | L33: =SUMIF(综合考核!A:A,'05月提成-武侯售后'!C33,综合考核!M:M) -> 0 | M33: =SUM(K33:L33) -> 8400.5975 | N33: =SUMIF(服装扣款!C:C,C33,服装扣款!N:N) -> 0 | O33: =M33-N33 -> 8400.5975 | P33: =SUMIF(超市公积金!C:C,'05月提成-武侯售后'!C33,超市公积金!I:I) -> 0 | Q33: =SUMIF(综合考核!A:A,'05月提成-武侯售后'!C33,综合考核!N:N) -> 0 | R33: =M33+I33+Q33 -> 9332.5975 | S33: =INDEX(AC:AC,MATCH(C33,AB:AB,0)) -> 22.15 | U33: =S33-T33 -> 22.15 | V33: =INDEX('05基本'!AF:AF,MATCH(C33,'05基本'!C:C,0)) -> 0 | W33: =O33-P33-U33 -> 8378.4475 | Y33: =SUM(Z33:AA33) -> 509.28303 | Z33: =INDEX('05月业务提成'!C:C,MATCH(C33,'05月业务提成'!B:B,0))*1 -> 292 | AA33: =INDEX('05月业务提成'!F:F,MATCH(C33,'05月业务提成'!B:B,0))*0.05*2%+INDEX('05月业务提成'!J:J,MATCH(C33,'05月业务提成'!B:B,0))*0.05*1.6%+(INDEX('05月业务提成'!P:P,MATCH(C33,'05月业务提成'!B:B,0))/0.95)*0.05++(INDEX('05月业务提成'!V:V,MATCH(C33,'05月业务提成'!B:B,0))/0.95)*0.05+(INDEX('05月业务提成'!Z:Z,MATCH(C33,'05月业务提成'!B:B,0))/0.95)*0.05 -> 217.28303 | AB33: 李国民 | AC33: 0 | AD33: =COUNTIF(C:C,C33) -> 1 | AE33: =INDEX('05基本'!P:P,MATCH(C33,'05基本'!C:C,0))-I33 -> 0 | AF33: =SUMIF('05月其他部门提成'!C:C,'05月提成-武侯售后'!C33,'05月其他部门提成'!Q:Q) -> 0 | AG33: =SUMIF('05月车间提成'!C:C,'05月提成-武侯售后'!C33,'05月车间提成'!W:W) -> 0 | AH33: =SUMIF('05月业务提成'!B:B,'05月提成-武侯售后'!C33,'05月业务提成'!BO:BO) -> 8400.5975 | AI33: =AF33+AG33+AH33 -> 8400.5975 | AJ33: =AI33-K33 -> 0
A34: =A33+1 -> 26 | C34: 陈昱良 | D34: =INDEX('05基本'!I:I,MATCH(C34,'05基本'!C:C,0))+INDEX('05基本'!J:J,MATCH(C34,'05基本'!C:C,0)) -> 0 | E34: =INDEX('05基本'!AA:AA,MATCH(C34,'05基本'!C:C,0)) -> 1268.59 | F34: =INDEX('05基本'!AB:AB,MATCH(C34,'05基本'!C:C,0)) -> 477.15 | G34: =INDEX('05基本'!AC:AC,MATCH(C34,'05基本'!C:C,0)) -> 117 | H34: =INDEX('05基本'!K:K,MATCH(C34,'05基本'!C:C,0))+INDEX('05基本'!L:L,MATCH(C34,'05基本'!C:C,0)) -> 0 | I34: =INDEX('05基本'!P:P,MATCH(C34,'05基本'!C:C,0)) -> 900 | J34: =INDEX('05基本'!M:M,MATCH(C34,'05基本'!C:C,0)) -> 0 | K34: =INDEX('05月业务提成'!BO:BO,MATCH(C34,'05月业务提成'!B:B,0)) -> 6015.3249 | L34: =SUMIF(综合考核!A:A,'05月提成-武侯售后'!C34,综合考核!M:M) -> 350 | M34: =SUM(K34:L34) -> 6365.3249 | N34: =SUMIF(服装扣款!C:C,C34,服装扣款!N:N) -> 0 | O34: =M34-N34 -> 6365.3249 | P34: =SUMIF(超市公积金!C:C,'05月提成-武侯售后'!C34,超市公积金!I:I) -> 0 | Q34: =SUMIF(综合考核!A:A,'05月提成-武侯售后'!C34,综合考核!N:N) -> 0 | R34: =M34+I34+Q34 -> 7265.3249 | S34: =INDEX(AC:AC,MATCH(C34,AB:AB,0)) -> 50.13 | U34: =S34-T34 -> 50.13 | V34: =INDEX('05基本'!AF:AF,MATCH(C34,'05基本'!C:C,0)) -> 0 | W34: =O34-P34-U34 -> 6315.1949 | Y34: =SUM(Z34:AA34) -> 409.12236 | Z34: =INDEX('05月业务提成'!C:C,MATCH(C34,'05月业务提成'!B:B,0))*1 -> 78 | AA34: =INDEX('05月业务提成'!F:F,MATCH(C34,'05月业务提成'!B:B,0))*0.05*2%+INDEX('05月业务提成'!J:J,MATCH(C34,'05月业务提成'!B:B,0))*0.05*1.6%+(INDEX('05月业务提成'!P:P,MATCH(C34,'05月业务提成'!B:B,0))/0.95)*0.05++(INDEX('05月业务提成'!V:V,MATCH(C34,'05月业务提成'!B:B,0))/0.95)*0.05+(INDEX('05月业务提成'!Z:Z,MATCH(C34,'05月业务提成'!B:B,0))/0.95)*0.05 -> 331.12236 | AB34: 金亮亮 | AC34: 1024.74 | AD34: =COUNTIF(C:C,C34) -> 1 | AE34: =INDEX('05基本'!P:P,MATCH(C34,'05基本'!C:C,0))-I34 -> 0 | AF34: =SUMIF('05月其他部门提成'!C:C,'05月提成-武侯售后'!C34,'05月其他部门提成'!Q:Q) -> 0 | AG34: =SUMIF('05月车间提成'!C:C,'05月提成-武侯售后'!C34,'05月车间提成'!W:W) -> 0 | AH34: =SUMIF('05月业务提成'!B:B,'05月提成-武侯售后'!C34,'05月业务提成'!BO:BO) -> 6015.3249 | AI34: =AF34+AG34+AH34 -> 6015.3249 | AJ34: =AI34-K34 -> 0
A35: =A34+1 -> 27 | C35: 张林 | D35: =INDEX('05基本'!I:I,MATCH(C35,'05基本'!C:C,0))+INDEX('05基本'!J:J,MATCH(C35,'05基本'!C:C,0)) -> 32 | E35: =INDEX('05基本'!AA:AA,MATCH(C35,'05基本'!C:C,0)) -> 1268.59 | F35: =INDEX('05基本'!AB:AB,MATCH(C35,'05基本'!C:C,0)) -> 477.15 | G35: =INDEX('05基本'!AC:AC,MATCH(C35,'05基本'!C:C,0)) -> 117 | H35: =INDEX('05基本'!K:K,MATCH(C35,'05基本'!C:C,0))+INDEX('05基本'!L:L,MATCH(C35,'05基本'!C:C,0)) -> 0 | I35: =INDEX('05基本'!P:P,MATCH(C35,'05基本'!C:C,0)) -> 932 | J35: =INDEX('05基本'!M:M,MATCH(C35,'05基本'!C:C,0)) -> 0 | K35: =INDEX('05月业务提成'!BO:BO,MATCH(C35,'05月业务提成'!B:B,0)) -> 6591.5185 | L35: =SUMIF(综合考核!A:A,'05月提成-武侯售后'!C35,综合考核!M:M) -> 0 | M35: =SUM(K35:L35) -> 6591.5185 | N35: =SUMIF(服装扣款!C:C,C35,服装扣款!N:N) -> 0 | O35: =M35-N35 -> 6591.5185 | P35: =SUMIF(超市公积金!C:C,'05月提成-武侯售后'!C35,超市公积金!I:I) -> 0 | Q35: =SUMIF(综合考核!A:A,'05月提成-武侯售后'!C35,综合考核!N:N) -> 300 | R35: =M35+I35+Q35 -> 7823.5185 | S35: =INDEX(AC:AC,MATCH(C35,AB:AB,0)) -> 66.88 | U35: =S35-T35 -> 66.88 | V35: =INDEX('05基本'!AF:AF,MATCH(C35,'05基本'!C:C,0)) -> 0 | W35: =O35-P35-U35 -> 6524.6385 | Y35: =SUM(Z35:AA35) -> 439.35519 | Z35: =INDEX('05月业务提成'!C:C,MATCH(C35,'05月业务提成'!B:B,0))*1 -> 250 | AA35: =INDEX('05月业务提成'!F:F,MATCH(C35,'05月业务提成'!B:B,0))*0.05*2%+INDEX('05月业务提成'!J:J,MATCH(C35,'05月业务提成'!B:B,0))*0.05*1.6%+(INDEX('05月业务提成'!P:P,MATCH(C35,'05月业务提成'!B:B,0))/0.95)*0.05++(INDEX('05月业务提成'!V:V,MATCH(C35,'05月业务提成'!B:B,0))/0.95)*0.05+(INDEX('05月业务提成'!Z:Z,MATCH(C35,'05月业务提成'!B:B,0))/0.95)*0.05 -> 189.35519 | AB35: 应文龙 | AC35: 55.55 | AD35: =COUNTIF(C:C,C35) -> 1 | AE35: =INDEX('05基本'!P:P,MATCH(C35,'05基本'!C:C,0))-I35 -> 0 | AF35: =SUMIF('05月其他部门提成'!C:C,'05月提成-武侯售后'!C35,'05月其他部门提成'!Q:Q) -> 0 | AG35: =SUMIF('05月车间提成'!C:C,'05月提成-武侯售后'!C35,'05月车间提成'!W:W) -> 0 | AH35: =SUMIF('05月业务提成'!B:B,'05月提成-武侯售后'!C35,'05月业务提成'!BO:BO) -> 6591.5185 | AI35: =AF35+AG35+AH35 -> 6591.5185 | AJ35: =AI35-K35 -> 0
A36: =A35+1 -> 28 | C36: 王毅 | D36: =INDEX('05基本'!I:I,MATCH(C36,'05基本'!C:C,0))+INDEX('05基本'!J:J,MATCH(C36,'05基本'!C:C,0)) -> 24 | E36: =INDEX('05基本'!AA:AA,MATCH(C36,'05基本'!C:C,0)) -> 1268.59 | F36: =INDEX('05基本'!AB:AB,MATCH(C36,'05基本'!C:C,0)) -> 477.15 | G36: =INDEX('05基本'!AC:AC,MATCH(C36,'05基本'!C:C,0)) -> 117 | H36: =INDEX('05基本'!K:K,MATCH(C36,'05基本'!C:C,0))+INDEX('05基本'!L:L,MATCH(C36,'05基本'!C:C,0)) -> 0 | I36: =INDEX('05基本'!P:P,MATCH(C36,'05基本'!C:C,0)) -> 924 | J36: =INDEX('05基本'!M:M,MATCH(C36,'05基本'!C:C,0)) -> 0 | K36: =INDEX('05月业务提成'!BO:BO,MATCH(C36,'05月业务提成'!B:B,0)) -> 8841.9309 | L36: =SUMIF(综合考核!A:A,'05月提成-武侯售后'!C36,综合考核!M:M) -> 0 | M36: =SUM(K36:L36) -> 8841.9309 | N36: =SUMIF(服装扣款!C:C,C36,服装扣款!N:N) -> 0 | O36: =M36-N36 -> 8841.9309 | P36: =SUMIF(超市公积金!C:C,'05月提成-武侯售后'!C36,超市公积金!I:I) -> 0 | Q36: =SUMIF(综合考核!A:A,'05月提成-武侯售后'!C36,综合考核!N:N) -> 0 | R36: =M36+I36+Q36 -> 9765.9309 | S36: =INDEX(AC:AC,MATCH(C36,AB:AB,0)) -> 125.15 | U36: =S36-T36 -> 125.15 | V36: =INDEX('05基本'!AF:AF,MATCH(C36,'05基本'!C:C,0)) -> 0 | W36: =O36-P36-U36 -> 8716.7809 | Y36: =SUM(Z36:AA36) -> 577.93163 | Z36: =INDEX('05月业务提成'!C:C,MATCH(C36,'05月业务提成'!B:B,0))*1 -> 319 | AA36: =INDEX('05月业务提成'!F:F,MATCH(C36,'05月业务提成'!B:B,0))*0.05*2%+INDEX('05月业务提成'!J:J,MATCH(C36,'05月业务提成'!B:B,0))*0.05*1.6%+(INDEX('05月业务提成'!P:P,MATCH(C36,'05月业务提成'!B:B,0))/0.95)*0.05++(INDEX('05月业务提成'!V:V,MATCH(C36,'05月业务提成'!B:B,0))/0.95)*0.05+(INDEX('05月业务提成'!Z:Z,MATCH(C36,'05月业务提成'!B:B,0))/0.95)*0.05 -> 258.93163 | AB36: 曾浩 | AC36: 145.59 | AD36: =COUNTIF(C:C,C36) -> 1 | AE36: =INDEX('05基本'!P:P,MATCH(C36,'05基本'!C:C,0))-I36 -> 0 | AF36: =SUMIF('05月其他部门提成'!C:C,'05月提成-武侯售后'!C36,'05月其他部门提成'!Q:Q) -> 0 | AG36: =SUMIF('05月车间提成'!C:C,'05月提成-武侯售后'!C36,'05月车间提成'!W:W) -> 0 | AH36: =SUMIF('05月业务提成'!B:B,'05月提成-武侯售后'!C36,'05月业务提成'!BO:BO) -> 8841.9309 | AI36: =AF36+AG36+AH36 -> 8841.9309 | AJ36: =AI36-K36 -> 0
A37: =A36+1 -> 29 | C37: 李国民 | D37: =INDEX('05基本'!I:I,MATCH(C37,'05基本'!C:C,0))+INDEX('05基本'!J:J,MATCH(C37,'05基本'!C:C,0)) -> 0 | E37: =INDEX('05基本'!AA:AA,MATCH(C37,'05基本'!C:C,0)) -> 1268.59 | F37: =INDEX('05基本'!AB:AB,MATCH(C37,'05基本'!C:C,0)) -> 477.15 | G37: =INDEX('05基本'!AC:AC,MATCH(C37,'05基本'!C:C,0)) -> 117 | H37: =INDEX('05基本'!K:K,MATCH(C37,'05基本'!C:C,0))+INDEX('05基本'!L:L,MATCH(C37,'05基本'!C:C,0)) -> 0 | I37: =INDEX('05基本'!P:P,MATCH(C37,'05基本'!C:C,0)) -> 900 | J37: =INDEX('05基本'!M:M,MATCH(C37,'05基本'!C:C,0)) -> 0 | K37: =INDEX('05月业务提成'!BO:BO,MATCH(C37,'05月业务提成'!B:B,0)) -> 3393.3366 | L37: =SUMIF(综合考核!A:A,'05月提成-武侯售后'!C37,综合考核!M:M) -> 190 | M37: =SUM(K37:L37) -> 3583.3366 | N37: =SUMIF(服装扣款!C:C,C37,服装扣款!N:N) -> 0 | O37: =M37-N37 -> 3583.3366 | P37: =SUMIF(超市公积金!C:C,'05月提成-武侯售后'!C37,超市公积金!I:I) -> 0 | Q37: =SUMIF(综合考核!A:A,'05月提成-武侯售后'!C37,综合考核!N:N) -> 0 | R37: =M37+I37+Q37 -> 4483.3366 | S37: =INDEX(AC:AC,MATCH(C37,AB:AB,0)) -> 0 | U37: =S37-T37 -> 0 | V37: =INDEX('05基本'!AF:AF,MATCH(C37,'05基本'!C:C,0)) -> 0 | W37: =O37-P37-U37 -> 3583.3366 | Y37: =SUM(Z37:AA37) -> 252.59667 | Z37: =INDEX('05月业务提成'!C:C,MATCH(C37,'05月业务提成'!B:B,0))*1 -> 46 | AA37: =INDEX('05月业务提成'!F:F,MATCH(C37,'05月业务提成'!B:B,0))*0.05*2%+INDEX('05月业务提成'!J:J,MATCH(C37,'05月业务提成'!B:B,0))*0.05*1.6%+(INDEX('05月业务提成'!P:P,MATCH(C37,'05月业务提成'!B:B,0))/0.95)*0.05++(INDEX('05月业务提成'!V:V,MATCH(C37,'05月业务提成'!B:B,0))/0.95)*0.05+(INDEX('05月业务提成'!Z:Z,MATCH(C37,'05月业务提成'!B:B,0))/0.95)*0.05 -> 206.59667 | AB37: 刘强 | AC37: 64.78 | AD37: =COUNTIF(C:C,C37) -> 1 | AE37: =INDEX('05基本'!P:P,MATCH(C37,'05基本'!C:C,0))-I37 -> 0 | AF37: =SUMIF('05月其他部门提成'!C:C,'05月提成-武侯售后'!C37,'05月其他部门提成'!Q:Q) -> 0 | AG37: =SUMIF('05月车间提成'!C:C,'05月提成-武侯售后'!C37,'05月车间提成'!W:W) -> 0 | AH37: =SUMIF('05月业务提成'!B:B,'05月提成-武侯售后'!C37,'05月业务提成'!BO:BO) -> 3393.3366 | AI37: =AF37+AG37+AH37 -> 3393.3366 | AJ37: =AI37-K37 -> 0
A38: =A37+1 -> 30 | C38: 金亮亮 | D38: =INDEX('05基本'!I:I,MATCH(C38,'05基本'!C:C,0))+INDEX('05基本'!J:J,MATCH(C38,'05基本'!C:C,0)) -> 0 | E38: =INDEX('05基本'!AA:AA,MATCH(C38,'05基本'!C:C,0)) -> 1268.59 | F38: =INDEX('05基本'!AB:AB,MATCH(C38,'05基本'!C:C,0)) -> 477.15 | G38: =INDEX('05基本'!AC:AC,MATCH(C38,'05基本'!C:C,0)) -> 117 | H38: =INDEX('05基本'!K:K,MATCH(C38,'05基本'!C:C,0))+INDEX('05基本'!L:L,MATCH(C38,'05基本'!C:C,0)) -> 0 | I38: =INDEX('05基本'!P:P,MATCH(C38,'05基本'!C:C,0)) -> 900 | J38: =INDEX('05基本'!M:M,MATCH(C38,'05基本'!C:C,0)) -> 0 | K38: =INDEX('05月业务提成'!BO:BO,MATCH(C38,'05月业务提成'!B:B,0)) -> 14651.612 | L38: =SUMIF(综合考核!A:A,'05月提成-武侯售后'!C38,综合考核!M:M) -> 290 | M38: =SUM(K38:L38) -> 14941.612 | N38: =SUMIF(服装扣款!C:C,C38,服装扣款!N:N) -> 0 | O38: =M38-N38 -> 14941.612 | P38: =SUMIF(超市公积金!C:C,'05月提成-武侯售后'!C38,超市公积金!I:I) -> 0 | Q38: =SUMIF(综合考核!A:A,'05月提成-武侯售后'!C38,综合考核!N:N) -> 0 | R38: =M38+I38+Q38 -> 15841.612 | S38: =INDEX(AC:AC,MATCH(C38,AB:AB,0)) -> 1024.74 | U38: =S38-T38 -> 1024.74 | V38: =INDEX('05基本'!AF:AF,MATCH(C38,'05基本'!C:C,0)) -> 0 | W38: =O38-P38-U38 -> 13916.872 | Y38: =SUM(Z38:AA38) -> 864.15855 | Z38: =INDEX('05月业务提成'!C:C,MATCH(C38,'05月业务提成'!B:B,0))*1 -> 83 | AA38: =INDEX('05月业务提成'!F:F,MATCH(C38,'05月业务提成'!B:B,0))*0.05*2%+INDEX('05月业务提成'!J:J,MATCH(C38,'05月业务提成'!B:B,0))*0.05*1.6%+(INDEX('05月业务提成'!P:P,MATCH(C38,'05月业务提成'!B:B,0))/0.95)*0.05++(INDEX('05月业务提成'!V:V,MATCH(C38,'05月业务提成'!B:B,0))/0.95)*0.05+(INDEX('05月业务提成'!Z:Z,MATCH(C38,'05月业务提成'!B:B,0))/0.95)*0.05 -> 781.15855 | AB38: 辜晓菲 | AC38: 214.65 | AD38: =COUNTIF(C:C,C38) -> 1 | AE38: =INDEX('05基本'!P:P,MATCH(C38,'05基本'!C:C,0))-I38 -> 0 | AF38: =SUMIF('05月其他部门提成'!C:C,'05月提成-武侯售后'!C38,'05月其他部门提成'!Q:Q) -> 0 | AG38: =SUMIF('05月车间提成'!C:C,'05月提成-武侯售后'!C38,'05月车间提成'!W:W) -> 0 | AH38: =SUMIF('05月业务提成'!B:B,'05月提成-武侯售后'!C38,'05月业务提成'!BO:BO) -> 14651.612 | AI38: =AF38+AG38+AH38 -> 14651.612 | AJ38: =AI38-K38 -> 0
A39: =A38+1 -> 31 | C39: 应文龙 | D39: =INDEX('05基本'!I:I,MATCH(C39,'05基本'!C:C,0))+INDEX('05基本'!J:J,MATCH(C39,'05基本'!C:C,0)) -> 0 | E39: =INDEX('05基本'!AA:AA,MATCH(C39,'05基本'!C:C,0)) -> 1268.59 | F39: =INDEX('05基本'!AB:AB,MATCH(C39,'05基本'!C:C,0)) -> 477.15 | G39: =INDEX('05基本'!AC:AC,MATCH(C39,'05基本'!C:C,0)) -> 117 | H39: =INDEX('05基本'!K:K,MATCH(C39,'05基本'!C:C,0))+INDEX('05基本'!L:L,MATCH(C39,'05基本'!C:C,0)) -> 0 | I39: =INDEX('05基本'!P:P,MATCH(C39,'05基本'!C:C,0)) -> 900 | J39: =INDEX('05基本'!M:M,MATCH(C39,'05基本'!C:C,0)) -> 0 | K39: =INDEX('05月业务提成'!BO:BO,MATCH(C39,'05月业务提成'!B:B,0)) -> 6275.8371 | L39: =SUMIF(综合考核!A:A,'05月提成-武侯售后'!C39,综合考核!M:M) -> 270 | M39: =SUM(K39:L39) -> 6545.8371 | N39: =SUMIF(服装扣款!C:C,C39,服装扣款!N:N) -> 0 | O39: =M39-N39 -> 6545.8371 | P39: =SUMIF(超市公积金!C:C,'05月提成-武侯售后'!C39,超市公积金!I:I) -> 0 | Q39: =SUMIF(综合考核!A:A,'05月提成-武侯售后'!C39,综合考核!N:N) -> 0 | R39: =M39+I39+Q39 -> 7445.8371 | S39: =INDEX(AC:AC,MATCH(C39,AB:AB,0)) -> 55.55 | U39: =S39-T39 -> 55.55 | V39: =INDEX('05基本'!AF:AF,MATCH(C39,'05基本'!C:C,0)) -> 0 | W39: =O39-P39-U39 -> 6490.287 | Y39: =SUM(Z39:AA39) -> 366.20195 | Z39: =INDEX('05月业务提成'!C:C,MATCH(C39,'05月业务提成'!B:B,0))*1 -> 62 | AA39: =INDEX('05月业务提成'!F:F,MATCH(C39,'05月业务提成'!B:B,0))*0.05*2%+INDEX('05月业务提成'!J:J,MATCH(C39,'05月业务提成'!B:B,0))*0.05*1.6%+(INDEX('05月业务提成'!P:P,MATCH(C39,'05月业务提成'!B:B,0))/0.95)*0.05++(INDEX('05月业务提成'!V:V,MATCH(C39,'05月业务提成'!B:B,0))/0.95)*0.05+(INDEX('05月业务提成'!Z:Z,MATCH(C39,'05月业务提成'!B:B,0))/0.95)*0.05 -> 304.20195 | AB39: 李超 | AC39: 1566.17 | AD39: =COUNTIF(C:C,C39) -> 1 | AE39: =INDEX('05基本'!P:P,MATCH(C39,'05基本'!C:C,0))-I39 -> 0 | AF39: =SUMIF('05月其他部门提成'!C:C,'05月提成-武侯售后'!C39,'05月其他部门提成'!Q:Q) -> 0 | AG39: =SUMIF('05月车间提成'!C:C,'05月提成-武侯售后'!C39,'05月车间提成'!W:W) -> 0 | AH39: =SUMIF('05月业务提成'!B:B,'05月提成-武侯售后'!C39,'05月业务提成'!BO:BO) -> 6275.8371 | AI39: =AF39+AG39+AH39 -> 6275.8371 | AJ39: =AI39-K39 -> 0
A40: =A39+1 -> 32 | C40: 曾浩 | D40: =INDEX('05基本'!I:I,MATCH(C40,'05基本'!C:C,0))+INDEX('05基本'!J:J,MATCH(C40,'05基本'!C:C,0)) -> 0 | E40: =INDEX('05基本'!AA:AA,MATCH(C40,'05基本'!C:C,0)) -> 1268.59 | F40: =INDEX('05基本'!AB:AB,MATCH(C40,'05基本'!C:C,0)) -> 477.15 | G40: =INDEX('05基本'!AC:AC,MATCH(C40,'05基本'!C:C,0)) -> 117 | H40: =INDEX('05基本'!K:K,MATCH(C40,'05基本'!C:C,0))+INDEX('05基本'!L:L,MATCH(C40,'05基本'!C:C,0)) -> 0 | I40: =INDEX('05基本'!P:P,MATCH(C40,'05基本'!C:C,0)) -> 900 | J40: =INDEX('05基本'!M:M,MATCH(C40,'05基本'!C:C,0)) -> 0 | K40: =INDEX('05月业务提成'!BO:BO,MATCH(C40,'05月业务提成'!B:B,0)) -> 9277.3472 | L40: =SUMIF(综合考核!A:A,'05月提成-武侯售后'!C40,综合考核!M:M) -> 270 | M40: =SUM(K40:L40) -> 9547.3472 | N40: =SUMIF(服装扣款!C:C,C40,服装扣款!N:N) -> 0 | O40: =M40-N40 -> 9547.3472 | P40: =SUMIF(超市公积金!C:C,'05月提成-武侯售后'!C40,超市公积金!I:I) -> 0 | Q40: =SUMIF(综合考核!A:A,'05月提成-武侯售后'!C40,综合考核!N:N) -> 0 | R40: =M40+I40+Q40 -> 10447.347 | S40: =INDEX(AC:AC,MATCH(C40,AB:AB,0)) -> 145.59 | U40: =S40-T40 -> 145.59 | V40: =INDEX('05基本'!AF:AF,MATCH(C40,'05基本'!C:C,0)) -> 0 | W40: =O40-P40-U40 -> 9401.7572 | Y40: =SUM(Z40:AA40) -> 591.2288 | Z40: =INDEX('05月业务提成'!C:C,MATCH(C40,'05月业务提成'!B:B,0))*1 -> 96 | AA40: =INDEX('05月业务提成'!F:F,MATCH(C40,'05月业务提成'!B:B,0))*0.05*2%+INDEX('05月业务提成'!J:J,MATCH(C40,'05月业务提成'!B:B,0))*0.05*1.6%+(INDEX('05月业务提成'!P:P,MATCH(C40,'05月业务提成'!B:B,0))/0.95)*0.05++(INDEX('05月业务提成'!V:V,MATCH(C40,'05月业务提成'!B:B,0))/0.95)*0.05+(INDEX('05月业务提成'!Z:Z,MATCH(C40,'05月业务提成'!B:B,0))/0.95)*0.05 -> 495.2288 | AB40: 黄意轩 | AC40: 188.28 | AD40: =COUNTIF(C:C,C40) -> 1 | AE40: =INDEX('05基本'!P:P,MATCH(C40,'05基本'!C:C,0))-I40 -> 0 | AF40: =SUMIF('05月其他部门提成'!C:C,'05月提成-武侯售后'!C40,'05月其他部门提成'!Q:Q) -> 0 | AG40: =SUMIF('05月车间提成'!C:C,'05月提成-武侯售后'!C40,'05月车间提成'!W:W) -> 0 | AH40: =SUMIF('05月业务提成'!B:B,'05月提成-武侯售后'!C40,'05月业务提成'!BO:BO) -> 9277.3472 | AI40: =AF40+AG40+AH40 -> 9277.3472 | AJ40: =AI40-K40 -> 0
...

Sheet 05月提成-机场售后
A1: 2026年05月成都西物汽车工资明细表-（机场售后）
A2: 编制：人事部
A3: 序号 | B3: 部门 | C3: 姓 名 | D3: 其他补贴 | E3: 单位社保 | F3: 个人社保 | G3: 个人公积金 | H3: 其它 | I3: 基本工资 | J3: 其中： 加班工资 | K3: 当月应计提绩效 | L3: 综合考核/其他 | M3: 应付提 成工资 | N3: 代扣社保 | O3: 实付提成 | P3: 其它 | Q3: 已发并税 | R3: 计税工资 | S3: 代扣个税 | V3: 其他(代扣项) | W3: 实发提成 | X3: 备注 | Y3: 留存 合计 | Z3: 留存1 | AA3: 留存2 | AF3: 其他部门 | AG3: 车间 | AH3: 业务
S4: 应扣税 | T4: 已扣税 | U4: 实际扣税 | Y4: 留存 | Z4: 留存 | AA4: 留存 | AB4: 姓名 | AC4: 累计应补(退)税额 | AF4: =SUMIF('05月其他部门提成'!C:C,'05月提成-机场售后'!C4,'05月其他部门提成'!Q:Q) -> 0 | AH4: =SUMIF('05月业务提成'!B:B,'05月提成-机场售后'!C4,'05月业务提成'!BO:BO) -> 0
A5: 1 | B5: 机场管理岗 | C5: 罗筱凡 | D5: =INDEX('05基本'!I:I,MATCH(C5,'05基本'!C:C,0))+INDEX('05基本'!J:J,MATCH(C5,'05基本'!C:C,0)) -> 0 | E5: =INDEX('05基本'!AA:AA,MATCH(C5,'05基本'!C:C,0)) -> 1497.5 | F5: =INDEX('05基本'!AB:AB,MATCH(C5,'05基本'!C:C,0)) -> 572 | G5: =INDEX('05基本'!AC:AC,MATCH(C5,'05基本'!C:C,0)) -> 117 | H5: =INDEX('05基本'!K:K,MATCH(C5,'05基本'!C:C,0))+INDEX('05基本'!L:L,MATCH(C5,'05基本'!C:C,0)) -> 0 | I5: =INDEX('05基本'!P:P,MATCH(C5,'05基本'!C:C,0)) -> 4000 | J5: =INDEX('05基本'!M:M,MATCH(C5,'05基本'!C:C,0)) -> 0 | K5: =INDEX('05月其他部门提成'!Q:Q,MATCH(C5,'05月其他部门提成'!C:C,0)) -> 6800 | L5: =SUMIF(综合考核!A:A,'05月提成-机场售后'!C5,综合考核!M:M) -> 0 | M5: =SUM(K5:L5) -> 6800 | N5: =SUMIF(服装扣款!C:C,C5,服装扣款!N:N) -> 0 | O5: =M5-N5 -> 6800 | P5: =SUMIF(西物公积金!C:C,C5,西物公积金!I:I) -> 0 | Q5: =SUMIF(综合考核!A:A,'05月提成-机场售后'!C5,综合考核!N:N) -> 0 | R5: =M5+I5+Q5 -> 10800 | S5: =INDEX(AC:AC,MATCH(C5,AB:AB,0)) -> 411.1 | U5: =S5-T5 -> 411.1 | V5: =INDEX('05基本'!AF:AF,MATCH(C5,'05基本'!C:C,0)) -> 0 | W5: =O5-P5-U5 -> 6388.9 | Y5: =SUM(Z5:AA5) -> 0 | Z5: =INDEX('05月其他部门提成'!S:S,MATCH(C5,'05月其他部门提成'!C:C,0)) -> 0 | AB5: 罗筱凡 | AC5: 411.1 | AD5: =COUNTIF(C:C,C5) -> 1 | AF5: =SUMIF('05月其他部门提成'!C:C,'05月提成-机场售后'!C5,'05月其他部门提成'!Q:Q) -> 6800 | AG5: =SUMIF('05月车间提成'!C:C,'05月提成-机场售后'!C5,'05月车间提成'!W:W) -> 0 | AH5: =SUMIF('05月业务提成'!B:B,'05月提成-机场售后'!C5,'05月业务提成'!BO:BO) -> 0 | AI5: =AF5+AG5+AH5 -> 6800 | AJ5: =AI5-K5 -> 0
A6: 2 | B6: 机场财务 | C6: 李佳语 | D6: =INDEX('05基本'!I:I,MATCH(C6,'05基本'!C:C,0))+INDEX('05基本'!J:J,MATCH(C6,'05基本'!C:C,0)) -> 0 | E6: =INDEX('05基本'!AA:AA,MATCH(C6,'05基本'!C:C,0)) -> 0 | F6: =INDEX('05基本'!AB:AB,MATCH(C6,'05基本'!C:C,0)) -> 0 | G6: =INDEX('05基本'!AC:AC,MATCH(C6,'05基本'!C:C,0)) -> 0 | H6: =INDEX('05基本'!K:K,MATCH(C6,'05基本'!C:C,0))+INDEX('05基本'!L:L,MATCH(C6,'05基本'!C:C,0)) -> 0 | I6: =INDEX('05基本'!P:P,MATCH(C6,'05基本'!C:C,0)) -> 1600 | J6: =INDEX('05基本'!M:M,MATCH(C6,'05基本'!C:C,0)) -> 0 | K6: =INDEX('05月其他部门提成'!Q:Q,MATCH(C6,'05月其他部门提成'!C:C,0)) -> 3855.4579 | L6: =SUMIF(综合考核!A:A,'05月提成-机场售后'!C6,综合考核!M:M) -> 0 | M6: =SUM(K6:L6) -> 3855.4579 | N6: =SUMIF(服装扣款!C:C,C6,服装扣款!N:N) -> 0 | O6: =M6-N6 -> 3855.4579 | P6: =SUMIF(西物公积金!C:C,C6,西物公积金!I:I) -> 0 | Q6: =SUMIF(综合考核!A:A,'05月提成-机场售后'!C6,综合考核!N:N) -> 0 | R6: =M6+I6+Q6 -> 5455.4579 | S6: =INDEX(AC:AC,MATCH(C6,AB:AB,0)) -> 13.66 | T6: 0 | U6: =S6-T6 -> 13.66 | V6: =INDEX('05基本'!AF:AF,MATCH(C6,'05基本'!C:C,0)) -> 0 | W6: =O6-P6-U6 -> 3841.7979 | Y6: =SUM(Z6:AA6) -> 216.66667 | Z6: =INDEX('05月其他部门提成'!S:S,MATCH(C6,'05月其他部门提成'!C:C,0)) -> 216.66667 | AB6: 李佳语 | AC6: 13.66 | AF6: =SUMIF('05月其他部门提成'!C:C,'05月提成-机场售后'!C6,'05月其他部门提成'!Q:Q) -> 3855.4579 | AG6: =SUMIF('05月车间提成'!C:C,'05月提成-机场售后'!C6,'05月车间提成'!W:W) -> 0 | AH6: =SUMIF('05月业务提成'!B:B,'05月提成-机场售后'!C6,'05月业务提成'!BO:BO) -> 0 | AI6: =AF6+AG6+AH6 -> 3855.4579 | AJ6: =AI6-K6 -> 0
A7: 3 | B7: 配件部 | C7: 古镇吉 | D7: =INDEX('05基本'!I:I,MATCH(C7,'05基本'!C:C,0))+INDEX('05基本'!J:J,MATCH(C7,'05基本'!C:C,0)) -> 0 | E7: =INDEX('05基本'!AA:AA,MATCH(C7,'05基本'!C:C,0)) -> 1268.59 | F7: =INDEX('05基本'!AB:AB,MATCH(C7,'05基本'!C:C,0)) -> 477.15 | G7: =INDEX('05基本'!AC:AC,MATCH(C7,'05基本'!C:C,0)) -> 117 | H7: =INDEX('05基本'!K:K,MATCH(C7,'05基本'!C:C,0))+INDEX('05基本'!L:L,MATCH(C7,'05基本'!C:C,0)) -> 100 | I7: =INDEX('05基本'!P:P,MATCH(C7,'05基本'!C:C,0)) -> 1700 | J7: =INDEX('05基本'!M:M,MATCH(C7,'05基本'!C:C,0)) -> 0 | K7: =INDEX('05月其他部门提成'!Q:Q,MATCH(C7,'05月其他部门提成'!C:C,0)) -> 9851.2332 | L7: =SUMIF(综合考核!A:A,'05月提成-机场售后'!C7,综合考核!M:M) -> 0 | M7: =SUM(K7:L7) -> 9851.2332 | N7: =SUMIF(服装扣款!C:C,C7,服装扣款!N:N) -> 0 | O7: =M7-N7 -> 9851.2332 | P7: =SUMIF(西物公积金!C:C,C7,西物公积金!I:I) -> 0 | Q7: =SUMIF(综合考核!A:A,'05月提成-机场售后'!C7,综合考核!N:N) -> 0 | R7: =M7+I7+Q7 -> 11551.233 | S7: =INDEX(AC:AC,MATCH(C7,AB:AB,0)) -> 118.72 | T7: 0 | U7: =S7-T7 -> 118.72 | V7: =INDEX('05基本'!AF:AF,MATCH(C7,'05基本'!C:C,0)) -> 0 | W7: =O7-P7-U7 -> 9732.5132 | Y7: =SUM(Z7:AA7) -> 518.48896 | Z7: =INDEX('05月其他部门提成'!S:S,MATCH(C7,'05月其他部门提成'!C:C,0)) -> 518.48896 | AB7: 古镇吉 | AC7: 118.72 | AF7: =SUMIF('05月其他部门提成'!C:C,'05月提成-机场售后'!C7,'05月其他部门提成'!Q:Q) -> 9851.2332 | AG7: =SUMIF('05月车间提成'!C:C,'05月提成-机场售后'!C7,'05月车间提成'!W:W) -> 0 | AH7: =SUMIF('05月业务提成'!B:B,'05月提成-机场售后'!C7,'05月业务提成'!BO:BO) -> 0 | AI7: =AF7+AG7+AH7 -> 9851.2332 | AJ7: =AI7-K7 -> 0
